Workbook

Sheet Math
B3: 1st Half | C3: 2nd Half | E3: Y2025
A5: Known/Forecasted | B5: =SUM('1 Collections'!E15:J15) -> 1425932.9 | C5: =SUM('1 Collections'!K15:P15) -> 2066373 | E5: =SUM(B5:C5) -> 3492305.9
A6: Unkown | B6: =SUM('1 Collections'!E27:J27) -> 0 | C6: =SUM('1 Collections'!K27:P27) -> 100000 | E6: =SUM(B6:C6) -> 100000
A7: Collections | B7: =SUM(B5:B6) -> 1425932.9 | C7: =SUM(C5:C6) -> 2166373 | E7: =SUM(E5:E6) -> 3592305.9
A9: W2 | B9: =SUM('2 Employees'!C286:H288)+SUM('3 Benefits'!C116:H116) -> 1928165.3 | C9: =SUM('2 Employees'!I289:N289)+SUM('3 Benefits'!I116:N116) -> 1694975.7 | E9: =SUM(B9:C9) -> 3623141
A10: Contractors | B10: =SUM('4 Contractors'!C131:H131) -> 1304965.2 | C10: =SUM('4 Contractors'!I131:N131) -> 1088280.9 | E10: =SUM(B10:C10) -> 2393246
A11: Other | B11: =SUM('6 Other'!C34:H34) -> 3545.63 | C11: =SUM('6 Other'!I34:N34) -> 0 | E11: =SUM(B11:C11) -> 3545.63
A12: Spend | B12: =SUM(B9:B11) -> 3236676.1 | C12: =SUM(C9:C11) -> 2783256.6 | E12: =SUM(E9:E11) -> 6019932.7
A14: Beginning Cash | B14: =+'2025 CF Basic'!E50 -> 3334341 | C14: =+B19 -> 2248597.3 | E14: =+B14 -> 3334341
A16: Net Burn | B16: =+B7-B12 -> -1810743.1 | C16: =+C7-C12 -> -616883.6 | E16: =+E7-E12 -> -2427626.7
A17: Investment | B17: =SUM('6 Other'!D29:H29) -> 724999.44 | C17: =SUM('6 Other'!I29:N29) -> -25000 | E17: =SUM(B17:C17) -> 699999.44
A19: Ending Cash | B19: =+B14+B16+B17 -> 2248597.3 | C19: =+C14+C16+C17 -> 1606713.7 | E19: =+E14+E16+E17 -> 1606713.7
A21: Check | B21: =+B19-'2025 Detail'!H61 -> 225314.04 | C21: =+C19-'2025 Detail'!N61 -> 642602.99 | E21: =+E19-'2025 Detail'!N61 -> 642602.99
B24: =SUM('2025 CF Basic'!E21:J21) -> 1928165.3
B25: =SUM('2025 CF Basic'!E26:J26) -> 1299922.1
B26: =+B10 -> 1304965.2
B28: =+B26-B25 -> 5043.12

Sheet 2026 Summary - BK No Bonus
B2: SYNAPTIC CASH FLOW FORECAST | C2: 46023 | D2: =EDATE(C2,1) -> 46054 | E2: =EDATE(D2,1) -> 46082 | F2: =EDATE(E2,1) -> 46113 | G2: =EDATE(F2,1) -> 46143 | H2: =EDATE(G2,1) -> 46174 | I2: =EDATE(H2,1) -> 46204 | J2: =EDATE(I2,1) -> 46235 | K2: =EDATE(J2,1) -> 46266 | ... N2: =EDATE(M2,1) -> 46357 | P2: Q1 | Q2: Q2 | R2: Q3 | S2: Q4 | U2: 2026 | W2: Check
B3: =+Version!$C$3 -> Y2025 12 v001
B5: Consulting - Classic | C5: =+'2026 Detail'!C8 -> 126737 | D5: =+'2026 Detail'!D8 -> 270160 | E5: =+'2026 Detail'!E8 -> 223350 | F5: =+'2026 Detail'!F8 -> 197930 | G5: =+'2026 Detail'!G8 -> 151930 | H5: =+'2026 Detail'!H8 -> 151930 | I5: =+'2026 Detail'!I8 -> 146930 | J5: =+'2026 Detail'!J8 -> 145000 | ... N5: =+'2026 Detail'!N8 -> 130000 | P5: =SUM(C5:E5) -> 620247 | Q5: =SUM(F5:H5) -> 501790 | R5: =SUM(I5:K5) -> 436930 | S5: =SUM(L5:N5) -> 410000 | U5: =SUM(C5:N5) -> 1968967 | W5: =ROUND(SUM(P5:S5)-U5,2) -> 0
B6: Consulting - AppIQ | C6: =+'2026 Detail'!C13 -> 163027.6 | D6: =+'2026 Detail'!D13 -> 123027.6 | E6: =+'2026 Detail'!E13 -> 366527.6 | F6: =+'2026 Detail'!F13 -> 386527.6 | G6: =+'2026 Detail'!G13 -> 268277.6 | H6: =+'2026 Detail'!H13 -> 268277.6 | I6: =+'2026 Detail'!I13 -> 403277.6 | J6: =+'2026 Detail'!J13 -> 390500 | ... N6: =+'2026 Detail'!N13 -> 550000 | P6: =SUM(C6:E6) -> 652582.8 | Q6: =SUM(F6:H6) -> 923082.8 | R6: =SUM(I6:K6) -> 1079777.6 | S6: =SUM(L6:N6) -> 1487000 | U6: =SUM(C6:N6) -> 4142443.2 | W6: =ROUND(SUM(P6:S6)-U6,2) -> 0
B8: Total Cash Collected | C8: =SUM(C5:C6) -> 289764.6 | D8: =SUM(D5:D6) -> 393187.6 | E8: =SUM(E5:E6) -> 589877.6 | F8: =SUM(F5:F6) -> 584457.6 | G8: =SUM(G5:G6) -> 420207.6 | H8: =SUM(H5:H6) -> 420207.6 | I8: =SUM(I5:I6) -> 550207.6 | J8: =SUM(J5:J6) -> 535500 | ... N8: =SUM(N5:N6) -> 680000 | P8: =SUM(P5:P6) -> 1272829.8 | Q8: =SUM(Q5:Q6) -> 1424872.8 | R8: =SUM(R5:R6) -> 1516707.6 | S8: =SUM(S5:S6) -> 1897000 | U8: =SUM(U5:U6) -> 6111410.2 | W8: =ROUND(SUM(P8:S8)-U8,2) -> 0
B10: Delivery | C10: =+'2026 Detail'!C17+'2026 Detail'!C18 -> 184080 | D10: =C10 -> 184080 | E10: =+'2026 Detail'!E17+'2026 Detail'!E18 -> 187171.8 | F10: =+'2026 Detail'!F17+'2026 Detail'!F18 -> 181171.8 | G10: =+'2026 Detail'!G17+'2026 Detail'!G18 -> 181171.8 | H10: =+'2026 Detail'!H17+'2026 Detail'!H18 -> 181171.8 | I10: =+'2026 Detail'!I17+'2026 Detail'!I18 -> 174671.8 | J10: =+'2026 Detail'!J17+'2026 Detail'!J18 -> 174671.8 | K10: =+'2026 Detail'!K17+'2026 Detail'!K18 -> 174671.8 | L10: =+'2026 Detail'!L17+'2026 Detail'!L18 -> 170171.8 | ... N10: =+'2026 Detail'!N17+'2026 Detail'!N18 -> 170171.8 | P10: =SUM(C10:E10) -> 555331.8 | Q10: =SUM(F10:H10) -> 543515.4 | R10: =SUM(I10:K10) -> 524015.4 | S10: =SUM(L10:N10) -> 510515.4 | U10: =SUM(C10:N10) -> 2133378 | W10: =ROUND(SUM(P10:S10)-U10,2) -> 0
B11: GTM | C11: =+'2026 Detail'!C19+'2026 Detail'!C20 -> 40630 | D11: =C11 -> 40630 | E11: =+'2026 Detail'!E19+'2026 Detail'!E20 -> 41546.5 | F11: =+'2026 Detail'!F19+'2026 Detail'!F20 -> 41546.5 | G11: =+'2026 Detail'!G19+'2026 Detail'!G20 -> 41546.5 | H11: =+'2026 Detail'!H19+'2026 Detail'!H20 -> 41546.5 | I11: =+'2026 Detail'!I19+'2026 Detail'!I20 -> 41546.5 | J11: =+'2026 Detail'!J19+'2026 Detail'!J20 -> 41546.5 | K11: =+'2026 Detail'!K19+'2026 Detail'!K20 -> 41546.5 | L11: =+'2026 Detail'!L19+'2026 Detail'!L20 -> 41546.5 | ... N11: =+'2026 Detail'!N19+'2026 Detail'!N20 -> 41546.5 | P11: =SUM(C11:E11) -> 122806.5 | Q11: =SUM(F11:H11) -> 124639.5 | R11: =SUM(I11:K11) -> 124639.5 | S11: =SUM(L11:N11) -> 124639.5 | U11: =SUM(C11:N11) -> 496725 | W11: =ROUND(SUM(P11:S11)-U11,2) -> 0
B12: Total Spend Classic | C12: =SUM(C10:C11) -> 224710 | D12: =SUM(D10:D11) -> 224710 | E12: =SUM(E10:E11) -> 228718.3 | F12: =SUM(F10:F11) -> 222718.3 | G12: =SUM(G10:G11) -> 222718.3 | H12: =SUM(H10:H11) -> 222718.3 | I12: =SUM(I10:I11) -> 216218.3 | J12: =SUM(J10:J11) -> 216218.3 | ... N12: =SUM(N10:N11) -> 211718.3 | P12: =SUM(P10:P11) -> 678138.3 | Q12: =SUM(Q10:Q11) -> 668154.9 | R12: =SUM(R10:R11) -> 648654.9 | S12: =SUM(S10:S11) -> 635154.9 | U12: =SUM(U10:U11) -> 2630103 | W12: =ROUND(SUM(P12:S12)-U12,2) -> 0
B14: Delivery | C14: =+'2026 Detail'!C23+'2026 Detail'!C24 -> 10600 | D14: =+'2026 Detail'!D23+'2026 Detail'!D24 -> 10600 | E14: =+'2026 Detail'!E23+'2026 Detail'!E24 -> 10600 | F14: =+'2026 Detail'!F23+'2026 Detail'!F24 -> 10600 | G14: =+'2026 Detail'!G23+'2026 Detail'!G24 -> 10600 | H14: =+'2026 Detail'!H23+'2026 Detail'!H24 -> 10600 | I14: =+'2026 Detail'!I23+'2026 Detail'!I24 -> 10600 | J14: =+'2026 Detail'!J23+'2026 Detail'!J24 -> 10600 | ... N14: =+'2026 Detail'!N23+'2026 Detail'!N24 -> 10600 | P14: =SUM(C14:E14) -> 31800 | Q14: =SUM(F14:H14) -> 31800 | R14: =SUM(I14:K14) -> 31800 | S14: =SUM(L14:N14) -> 31800 | U14: =SUM(C14:N14) -> 127200 | W14: =ROUND(SUM(P14:S14)-U14,2) -> 0
B15: GTM | C15: =+'2026 Detail'!C25+'2026 Detail'!C26 -> 47260 | D15: =+'2026 Detail'!D25+'2026 Detail'!D26 -> 47260 | E15: =+'2026 Detail'!E25+'2026 Detail'!E26 -> 47734 | F15: =+'2026 Detail'!F25+'2026 Detail'!F26 -> 34734 | G15: =+'2026 Detail'!G25+'2026 Detail'!G26 -> 34734 | H15: =+'2026 Detail'!H25+'2026 Detail'!H26 -> 34734 | I15: =+'2026 Detail'!I25+'2026 Detail'!I26 -> 34734 | J15: =+'2026 Detail'!J25+'2026 Detail'!J26 -> 34734 | ... N15: =+'2026 Detail'!N25+'2026 Detail'!N26 -> 34734 | P15: =SUM(C15:E15) -> 142254 | Q15: =SUM(F15:H15) -> 104202 | R15: =SUM(I15:K15) -> 104202 | S15: =SUM(L15:N15) -> 104202 | U15: =SUM(C15:N15) -> 454860 | W15: =ROUND(SUM(P15:S15)-U15,2) -> 0
B16: R&D | C16: =+'2026 Detail'!C27+'2026 Detail'!C28 -> 74520 | D16: =C16 -> 74520 | E16: =+'2026 Detail'!E27+'2026 Detail'!E28 -> 75498 | F16: =+'2026 Detail'!F27+'2026 Detail'!F28 -> 75498 | G16: =+'2026 Detail'!G27+'2026 Detail'!G28 -> 75498 | H16: =+'2026 Detail'!H27+'2026 Detail'!H28 -> 75498 | I16: =+'2026 Detail'!I27+'2026 Detail'!I28 -> 75498 | J16: =+'2026 Detail'!J27+'2026 Detail'!J28 -> 75498 | K16: =+'2026 Detail'!K27+'2026 Detail'!K28 -> 75498 | L16: =+'2026 Detail'!L27+'2026 Detail'!L28 -> 75498 | ... N16: =+'2026 Detail'!N27+'2026 Detail'!N28 -> 75498 | P16: =SUM(C16:E16) -> 224538 | Q16: =SUM(F16:H16) -> 226494 | R16: =SUM(I16:K16) -> 226494 | S16: =SUM(L16:N16) -> 226494 | U16: =SUM(C16:N16) -> 904020 | W16: =ROUND(SUM(P16:S16)-U16,2) -> 0
B17: Total Spend AppIQ | C17: =SUM(C14:C16) -> 132380 | D17: =SUM(D14:D16) -> 132380 | E17: =SUM(E14:E16) -> 133832 | F17: =SUM(F14:F16) -> 120832 | G17: =SUM(G14:G16) -> 120832 | H17: =SUM(H14:H16) -> 120832 | I17: =SUM(I14:I16) -> 120832 | J17: =SUM(J14:J16) -> 120832 | ... N17: =SUM(N14:N16) -> 120832 | P17: =SUM(P14:P16) -> 398592 | Q17: =SUM(Q14:Q16) -> 362496 | R17: =SUM(R14:R16) -> 362496 | S17: =SUM(S14:S16) -> 362496 | U17: =SUM(U14:U16) -> 1486080 | W17: =ROUND(SUM(P17:S17)-U17,2) -> 0
B19: Back Office | C19: =+'2026 Detail'!C33 -> 67260 | D19: =C19 -> 67260 | E19: =+'2026 Detail'!E33 -> 67260 | F19: =+'2026 Detail'!F33 -> 65760 | G19: =+'2026 Detail'!G33 -> 65760 | H19: =+'2026 Detail'!H33 -> 65760 | I19: =+'2026 Detail'!I33 -> 65260 | J19: =+'2026 Detail'!J33 -> 65260 | K19: =+'2026 Detail'!K33 -> 65260 | L19: =+'2026 Detail'!L33 -> 65260 | ... N19: =+'2026 Detail'!N33 -> 65260 | P19: =SUM(C19:E19) -> 201780 | Q19: =SUM(F19:H19) -> 197280 | R19: =SUM(I19:K19) -> 195780 | S19: =SUM(L19:N19) -> 195780 | U19: =SUM(C19:N19) -> 790620 | W19: =ROUND(SUM(P19:S19)-U19,2) -> 0
B20: Total Spend Back Office | C20: =SUM(C19:C19) -> 67260 | D20: =C20 -> 67260 | E20: =SUM(E19:E19) -> 67260 | F20: =SUM(F19:F19) -> 65760 | G20: =SUM(G19:G19) -> 65760 | H20: =SUM(H19:H19) -> 65760 | I20: =SUM(I19:I19) -> 65260 | J20: =SUM(J19:J19) -> 65260 | K20: =SUM(K19:K19) -> 65260 | L20: =SUM(L19:L19) -> 65260 | ... N20: =SUM(N19:N19) -> 65260 | P20: =SUM(P19:P19) -> 201780 | Q20: =SUM(Q19:Q19) -> 197280 | R20: =SUM(R19:R19) -> 195780 | S20: =SUM(S19:S19) -> 195780 | U20: =SUM(U19:U19) -> 790620 | W20: =ROUND(SUM(P20:S20)-U20,2) -> 0
B22: Rent | C22: =+'2026 Detail'!C35 -> 3550 | D22: =+'2026 Detail'!D35 -> 3550 | E22: =+'2026 Detail'!E35 -> 3550 | F22: =+'2026 Detail'!F35 -> 3550 | G22: =+'2026 Detail'!G35 -> 3550 | H22: =+'2026 Detail'!H35 -> 3550 | I22: =+'2026 Detail'!I35 -> 3550 | J22: =+'2026 Detail'!J35 -> 3550 | ... N22: =+'2026 Detail'!N35 -> 3550 | P22: =SUM(C22:E22) -> 10650 | Q22: =SUM(F22:H22) -> 10650 | R22: =SUM(I22:K22) -> 10650 | S22: =SUM(L22:N22) -> 10650 | U22: =SUM(C22:N22) -> 42600 | W22: =ROUND(SUM(P22:S22)-U22,2) -> 0
B23: Hardware & Software | C23: =+'2026 Detail'!C36 -> 4060.245 | D23: =+'2026 Detail'!D36 -> 4804.695 | E23: =+'2026 Detail'!E36 -> 13162.958 | F23: =+'2026 Detail'!F36 -> 11670.068 | G23: =+'2026 Detail'!G36 -> 26012.721 | H23: =+'2026 Detail'!H36 -> 24274.236 | I23: =+'2026 Detail'!I36 -> 23138.231 | J23: =+'2026 Detail'!J36 -> 96432.766 | ... N23: =+'2026 Detail'!N36 -> 12600 | P23: =SUM(C23:E23) -> 22027.897 | Q23: =SUM(F23:H23) -> 61957.025 | R23: =SUM(I23:K23) -> 130374.94 | S23: =SUM(L23:N23) -> 50723.253 | U23: =SUM(C23:N23) -> 265083.12 | W23: =ROUND(SUM(P23:S23)-U23,2) -> 0
B24: Office & Supplies | C24: =+'2026 Detail'!C37 -> 750 | D24: =+'2026 Detail'!D37 -> 750 | E24: =+'2026 Detail'!E37 -> 750 | F24: =+'2026 Detail'!F37 -> 750 | G24: =+'2026 Detail'!G37 -> 750 | H24: =+'2026 Detail'!H37 -> 750 | I24: =+'2026 Detail'!I37 -> 750 | J24: =+'2026 Detail'!J37 -> 750 | ... N24: =+'2026 Detail'!N37 -> 750 | P24: =SUM(C24:E24) -> 2250 | Q24: =SUM(F24:H24) -> 2250 | R24: =SUM(I24:K24) -> 2250 | S24: =SUM(L24:N24) -> 2250 | U24: =SUM(C24:N24) -> 9000 | W24: =ROUND(SUM(P24:S24)-U24,2) -> 0
B25: Insurance | C25: =+'2026 Detail'!C38 -> 511.8791 | D25: =+'2026 Detail'!D38 -> 8528.5854 | E25: =+'2026 Detail'!E38 -> 3182.5867 | F25: =+'2026 Detail'!F38 -> 9254.4367 | G25: =+'2026 Detail'!G38 -> 1593.9765 | H25: =+'2026 Detail'!H38 -> 3130.6747 | I25: =+'2026 Detail'!I38 -> 5747.6472 | J25: =+'2026 Detail'!J38 -> 1836.7372 | ... N25: =+'2026 Detail'!N38 -> 2575 | P25: =SUM(C25:E25) -> 12223.051 | Q25: =SUM(F25:H25) -> 13979.088 | R25: =SUM(I25:K25) -> 10715.059 | S25: =SUM(L25:N25) -> 10404.071 | U25: =SUM(C25:N25) -> 47321.269 | W25: =ROUND(SUM(P25:S25)-U25,2) -> 0
B26: Legal Fees | C26: =+'2026 Detail'!C39 -> 12500 | D26: =+'2026 Detail'!D39 -> 12500 | E26: =+'2026 Detail'!E39 -> 12500 | F26: =+'2026 Detail'!F39 -> 10000 | G26: =+'2026 Detail'!G39 -> 10000 | H26: =+'2026 Detail'!H39 -> 10000 | I26: =+'2026 Detail'!I39 -> 8000 | J26: =+'2026 Detail'!J39 -> 8000 | ... N26: =+'2026 Detail'!N39 -> 8000 | P26: =SUM(C26:E26) -> 37500 | Q26: =SUM(F26:H26) -> 30000 | R26: =SUM(I26:K26) -> 24000 | S26: =SUM(L26:N26) -> 24000 | U26: =SUM(C26:N26) -> 115500 | W26: =ROUND(SUM(P26:S26)-U26,2) -> 0
B27: Accounting & Tax Fees | C27: =+'2026 Detail'!C40 -> 2500 | D27: =+'2026 Detail'!D40 -> 1500 | E27: =+'2026 Detail'!E40 -> 2000 | F27: =+'2026 Detail'!F40 -> 1500 | G27: =+'2026 Detail'!G40 -> 1500 | H27: =+'2026 Detail'!H40 -> 2000 | I27: =+'2026 Detail'!I40 -> 1500 | J27: =+'2026 Detail'!J40 -> 1500 | ... N27: =+'2026 Detail'!N40 -> 2000 | P27: =SUM(C27:E27) -> 6000 | Q27: =SUM(F27:H27) -> 5000 | R27: =SUM(I27:K27) -> 5000 | S27: =SUM(L27:N27) -> 5000 | U27: =SUM(C27:N27) -> 21000 | W27: =ROUND(SUM(P27:S27)-U27,2) -> 0
B28: Professional Fees | C28: =+'2026 Detail'!C41 -> 5000 | D28: =+'2026 Detail'!D41 -> 5000 | E28: =+'2026 Detail'!E41 -> 5000 | F28: =+'2026 Detail'!F41 -> 5000 | G28: =+'2026 Detail'!G41 -> 5000 | H28: =+'2026 Detail'!H41 -> 5000 | I28: =+'2026 Detail'!I41 -> 5000 | J28: =+'2026 Detail'!J41 -> 5000 | ... N28: =+'2026 Detail'!N41 -> 5000 | P28: =SUM(C28:E28) -> 15000 | Q28: =SUM(F28:H28) -> 15000 | R28: =SUM(I28:K28) -> 15000 | S28: =SUM(L28:N28) -> 15000 | U28: =SUM(C28:N28) -> 60000 | W28: =ROUND(SUM(P28:S28)-U28,2) -> 0
B29: Taxes, Licenses & Permits | C29: =+'2026 Detail'!C42 -> 250 | D29: =+'2026 Detail'!D42 -> 250 | E29: =+'2026 Detail'!E42 -> 250 | F29: =+'2026 Detail'!F42 -> 250 | G29: =+'2026 Detail'!G42 -> 250 | H29: =+'2026 Detail'!H42 -> 250 | I29: =+'2026 Detail'!I42 -> 250 | J29: =+'2026 Detail'!J42 -> 250 | ... N29: =+'2026 Detail'!N42 -> 250 | P29: =SUM(C29:E29) -> 750 | Q29: =SUM(F29:H29) -> 750 | R29: =SUM(I29:K29) -> 750 | S29: =SUM(L29:N29) -> 750 | U29: =SUM(C29:N29) -> 3000 | W29: =ROUND(SUM(P29:S29)-U29,2) -> 0
B30: Travel & Meals | C30: =+'2026 Detail'!C43 -> 15000 | D30: =+'2026 Detail'!D43 -> 15000 | E30: =+'2026 Detail'!E43 -> 15000 | F30: =+'2026 Detail'!F43 -> 15000 | G30: =+'2026 Detail'!G43 -> 15000 | H30: =+'2026 Detail'!H43 -> 15000 | I30: =+'2026 Detail'!I43 -> 15000 | J30: =+'2026 Detail'!J43 -> 15000 | ... N30: =+'2026 Detail'!N43 -> 15000 | P30: =SUM(C30:E30) -> 45000 | Q30: =SUM(F30:H30) -> 45000 | R30: =SUM(I30:K30) -> 45000 | S30: =SUM(L30:N30) -> 45000 | U30: =SUM(C30:N30) -> 180000 | W30: =ROUND(SUM(P30:S30)-U30,2) -> 0
B31: Total Other Spend | C31: =SUM(C22:C30) -> 44122.124 | D31: =SUM(D22:D30) -> 51883.28 | E31: =SUM(E22:E30) -> 55395.544 | F31: =SUM(F22:F30) -> 56974.504 | G31: =SUM(G22:G30) -> 63656.698 | H31: =SUM(H22:H30) -> 63954.911 | I31: =SUM(I22:I30) -> 62935.878 | J31: =SUM(J22:J30) -> 132319.5 | ... N31: =SUM(N22:N30) -> 49725 | P31: =SUM(P22:P30) -> 151400.95 | Q31: =SUM(Q22:Q30) -> 184586.11 | R31: =SUM(R22:R30) -> 243740 | S31: =SUM(S22:S30) -> 163777.32 | U31: =SUM(U22:U30) -> 743504.38 | W31: =ROUND(SUM(P31:S31)-U31,2) -> 0
B33: Total Cash Disbursements | C33: =+C12+C17+C20+C31 -> 468472.12 | D33: =+D12+D17+D20+D31 -> 476233.28 | E33: =+E12+E17+E20+E31 -> 485205.84 | F33: =+F12+F17+F20+F31 -> 466284.8 | G33: =+G12+G17+G20+G31 -> 472967 | H33: =+H12+H17+H20+H31 -> 473265.21 | I33: =+I12+I17+I20+I31 -> 465246.18 | J33: =+J12+J17+J20+J31 -> 534629.8 | ... N33: =+N12+N17+N20+N31 -> 447535.3 | P33: =+P12+P17+P20+P31 -> 1429911.2 | Q33: =+Q12+Q17+Q20+Q31 -> 1412517 | R33: =+R12+R17+R20+R31 -> 1450670.9 | S33: =+S12+S17+S20+S31 -> 1357208.2 | U33: =+U12+U17+U20+U31 -> 5650307.4 | W33: =ROUND(SUM(P33:S33)-U33,2) -> 0
B35: Guarenteed Payments | C35: =+'2026 Detail'!C48 -> 0 | D35: =+'2026 Detail'!D48 -> 0 | E35: =+'2026 Detail'!E48 -> 0 | F35: =+'2026 Detail'!F48 -> 0 | G35: =+'2026 Detail'!G48 -> 0 | H35: =+'2026 Detail'!H48 -> 0 | I35: =+'2026 Detail'!I48 -> 0 | J35: =+'2026 Detail'!J48 -> 0 | ... N35: =+'2026 Detail'!N48 -> 0 | P35: =SUM(C35:E35) -> 0 | Q35: =SUM(F35:H35) -> 0 | R35: =SUM(I35:K35) -> 0 | S35: =SUM(L35:N35) -> 0 | U35: =SUM(C35:N35) -> 0 | W35: =ROUND(SUM(P35:S35)-U35,2) -> 0
B36: Youreka Labs Inc | C36: =+'2026 Detail'!C49 -> 0 | D36: =+'2026 Detail'!D49 -> 0 | E36: =+'2026 Detail'!E49 -> 0 | F36: =+'2026 Detail'!F49 -> 0 | G36: =+'2026 Detail'!G49 -> 0 | H36: =+'2026 Detail'!H49 -> 0 | I36: =+'2026 Detail'!I49 -> 0 | J36: =+'2026 Detail'!J49 -> 0 | ... N36: =+'2026 Detail'!N49 -> 0 | P36: =SUM(C36:E36) -> 0 | Q36: =SUM(F36:H36) -> 0 | R36: =SUM(I36:K36) -> 0 | S36: =SUM(L36:N36) -> 0 | U36: =SUM(C36:N36) -> 0 | W36: =ROUND(SUM(P36:S36)-U36,2) -> 0
B37: Brex | C37: =+'2026 Detail'!C50 -> 0 | D37: =+'2026 Detail'!D50 -> 0 | E37: =+'2026 Detail'!E50 -> 0 | F37: =+'2026 Detail'!F50 -> 0 | G37: =+'2026 Detail'!G50 -> 0 | H37: =+'2026 Detail'!H50 -> 0 | I37: =+'2026 Detail'!I50 -> 0 | J37: =+'2026 Detail'!J50 -> 0 | ... N37: =+'2026 Detail'!N50 -> 0 | P37: =SUM(C37:E37) -> 0 | Q37: =SUM(F37:H37) -> 0 | R37: =SUM(I37:K37) -> 0 | S37: =SUM(L37:N37) -> 0 | U37: =SUM(C37:N37) -> 0 | W37: =ROUND(SUM(P37:S37)-U37,2) -> 0
B38: Chase Visa | C38: =+'2026 Detail'!C51 -> 0 | D38: =+'2026 Detail'!D51 -> 0 | E38: =+'2026 Detail'!E51 -> 0 | F38: =+'2026 Detail'!F51 -> 0 | G38: =+'2026 Detail'!G51 -> 0 | H38: =+'2026 Detail'!H51 -> 0 | I38: =+'2026 Detail'!I51 -> 0 | J38: =+'2026 Detail'!J51 -> 0 | ... N38: =+'2026 Detail'!N51 -> 0 | P38: =SUM(C38:E38) -> 0 | Q38: =SUM(F38:H38) -> 0 | R38: =SUM(I38:K38) -> 0 | S38: =SUM(L38:N38) -> 0 | U38: =SUM(C38:N38) -> 0 | W38: =ROUND(SUM(P38:S38)-U38,2) -> 0
B39: Ramp | C39: =+'2026 Detail'!C52 -> 0 | D39: =+'2026 Detail'!D52 -> 0 | E39: =+'2026 Detail'!E52 -> 0 | F39: =+'2026 Detail'!F52 -> 0 | G39: =+'2026 Detail'!G52 -> 0 | H39: =+'2026 Detail'!H52 -> 0 | I39: =+'2026 Detail'!I52 -> 0 | J39: =+'2026 Detail'!J52 -> 0 | ... N39: =+'2026 Detail'!N52 -> 0 | P39: =SUM(C39:E39) -> 0 | Q39: =SUM(F39:H39) -> 0 | R39: =SUM(I39:K39) -> 0 | S39: =SUM(L39:N39) -> 0 | U39: =SUM(C39:N39) -> 0 | W39: =ROUND(SUM(P39:S39)-U39,2) -> 0
B40: Bank Fees | C40: =+'2026 Detail'!C53 -> -400 | D40: =+'2026 Detail'!D53 -> -400 | E40: =+'2026 Detail'!E53 -> -400 | F40: =+'2026 Detail'!F53 -> -400 | G40: =+'2026 Detail'!G53 -> -400 | H40: =+'2026 Detail'!H53 -> -400 | I40: =+'2026 Detail'!I53 -> -400 | J40: =+'2026 Detail'!J53 -> -400 | ... N40: =+'2026 Detail'!N53 -> -400 | P40: =SUM(C40:E40) -> -1200 | Q40: =SUM(F40:H40) -> -1200 | R40: =SUM(I40:K40) -> -1200 | S40: =SUM(L40:N40) -> -1200 | U40: =SUM(C40:N40) -> -4800 | W40: =ROUND(SUM(P40:S40)-U40,2) -> 0
B41: Interest | C41: =+'2026 Detail'!C54 -> 500 | D41: =+'2026 Detail'!D54 -> 400 | E41: =+'2026 Detail'!E54 -> 100 | F41: =+'2026 Detail'!F54 -> 200 | G41: =+'2026 Detail'!G54 -> 300 | H41: =+'2026 Detail'!H54 -> 200 | I41: =+'2026 Detail'!I54 -> 200 | J41: =+'2026 Detail'!J54 -> 200 | ... N41: =+'2026 Detail'!N54 -> 400 | P41: =SUM(C41:E41) -> 1000 | Q41: =SUM(F41:H41) -> 700 | R41: =SUM(I41:K41) -> 600 | S41: =SUM(L41:N41) -> 900 | U41: =SUM(C41:N41) -> 3200 | W41: =ROUND(SUM(P41:S41)-U41,2) -> 0
B43: Opening Cash Balance | C43: =+'2026 Detail'!C56 -> 964110.73 | D43: =+C48 -> 785503.21 | E43: =+D48 -> 702457.53 | F43: =+E48 -> 806829.29 | G43: =+F48 -> 924802.09 | H43: =+G48 -> 871942.69 | I43: =+H48 -> 818685.08 | J43: =+I48 -> 903446.5 | K43: =+J48 -> 904116.7 | ... N43: =+M48 -> 1191148.9 | P43: =+C43 -> 964110.73 | Q43: =+P48 -> 806829 | R43: =+Q48 -> 818685 | S43: =+R48 -> 884122 | U43: =+P43 -> 964110.73
B45: Net Change | C45: =C8-C33+SUM(C35:C41) -> -178607.52 | D45: =D8-D33+SUM(D35:D41) -> -83045.68 | E45: =E8-E33+SUM(E35:E41) -> 104371.76 | F45: =F8-F33+SUM(F35:F41) -> 117972.8 | G45: =G8-G33+SUM(G35:G41) -> -52859.398 | H45: =H8-H33+SUM(H35:H41) -> -53257.611 | I45: =I8-I33+SUM(I35:I41) -> 84761.422 | J45: =J8-J33+SUM(J35:J41) -> 670.1963 | ... N45: =N8-N33+SUM(N35:N41) -> 232464.7 | P45: =SUM(C45:E45) -> -157281.45 | Q45: =SUM(F45:H45) -> 11855.788 | R45: =SUM(I45:K45) -> 65436.7 | S45: =SUM(L45:N45) -> 539491.78 | U45: =SUM(C45:N45) -> 459502.82 | W45: =ROUND(SUM(P45:S45)-U45,2) -> 0
B46: Investment | C46: =+'2026 Detail'!C59 -> 0 | D46: =+'2026 Detail'!D59 -> 0 | E46: =+'2026 Detail'!E59 -> 0 | F46: =+'2026 Detail'!F59 -> 0 | G46: =+'2026 Detail'!G59 -> 0 | H46: =+'2026 Detail'!H59 -> 0 | I46: =+'2026 Detail'!I59 -> 0 | J46: =+'2026 Detail'!J59 -> 0 | ... N46: =+'2026 Detail'!N59 -> 0 | P46: =SUM(C46:E46) -> 0 | Q46: =SUM(F46:H46) -> 0 | R46: =SUM(I46:K46) -> 0 | S46: =SUM(L46:N46) -> 0 | U46: =SUM(C46:N46) -> 0 | W46: =ROUND(SUM(P46:S46)-U46,2) -> 0
B48: Ending Cash Balance | C48: =ROUND(+C43+C45+C46,2) -> 785503.21 | D48: =ROUND(+D43+D45+D46,2) -> 702457.53 | E48: =ROUND(+E43+E45+E46,2) -> 806829.29 | F48: =ROUND(+F43+F45+F46,2) -> 924802.09 | G48: =ROUND(+G43+G45+G46,2) -> 871942.69 | H48: =ROUND(+H43+H45+H46,2) -> 818685.08 | I48: =ROUND(+I43+I45+I46,2) -> 903446.5 | J48: =ROUND(+J43+J45+J46,2) -> 904116.7 | ... N48: =ROUND(+N43+N45+N46,2) -> 1423613.6 | P48: =ROUND(+P43+P45+P46,0) -> 806829 | Q48: =ROUND(+Q43+Q45+Q46,0) -> 818685 | R48: =ROUND(+R43+R45+R46,0) -> 884122 | S48: =ROUND(+S43+S45+S46,0) -> 1423614 | U48: =ROUND(+U43+U45+U46,0) -> 1423614
B50: Cash In | C50: =+C8 -> 289764.6 | D50: =+D8 -> 393187.6 | E50: =+E8 -> 589877.6 | F50: =+F8 -> 584457.6 | G50: =+G8 -> 420207.6 | H50: =+H8 -> 420207.6 | I50: =+I8 -> 550207.6 | J50: =+J8 -> 535500 | ... N50: =+N8 -> 680000 | P50: =+P8 -> 1272829.8 | Q50: =+Q8 -> 1424872.8 | R50: =+R8 -> 1516707.6 | S50: =+S8 -> 1897000 | U50: =+U8 -> 6111410.2
B51: Calculated COGS | C51: =+C10+C14 -> 194680 | D51: =+D10+D14 -> 194680 | E51: =+E10+E14 -> 197771.8 | F51: =+F10+F14 -> 191771.8 | G51: =+G10+G14 -> 191771.8 | H51: =+H10+H14 -> 191771.8 | I51: =+I10+I14 -> 185271.8 | J51: =+J10+J14 -> 185271.8 | ... N51: =+N10+N14 -> 180771.8 | P51: =+P10+P14 -> 587131.8 | Q51: =+Q10+Q14 -> 575315.4 | R51: =+R10+R14 -> 555815.4 | S51: =+S10+S14 -> 542315.4 | U51: =+U10+U14 -> 2260578
B52: Gross Margin | C52: =+C50-C51 -> 95084.6 | D52: =+D50-D51 -> 198507.6 | E52: =+E50-E51 -> 392105.8 | F52: =+F50-F51 -> 392685.8 | G52: =+G50-G51 -> 228435.8 | H52: =+H50-H51 -> 228435.8 | I52: =+I50-I51 -> 364935.8 | J52: =+J50-J51 -> 350228.2 | ... N52: =+N50-N51 -> 499228.2 | P52: =+P50-P51 -> 685698 | Q52: =+Q50-Q51 -> 849557.4 | R52: =+R50-R51 -> 960892.2 | S52: =+S50-S51 -> 1354684.6 | U52: =+U50-U51 -> 3850832.2
B53: GM % | C53: =+C52/C50 -> 0.32814429 | D53: =+D52/D50 -> 0.5048674 | E53: =+E52/E50 -> 0.664724 | F53: =+F52/F50 -> 0.67188073 | G53: =+G52/G50 -> 0.54362606 | H53: =+H52/H50 -> 0.54362606 | I53: =+I52/I50 -> 0.66326928 | J53: =+J52/J50 -> 0.65402092 | ... N53: =+N52/N50 -> 0.73415912 | P53: =+P52/P50 -> 0.53871932 | Q53: =+Q52/Q50 -> 0.59623385 | R53: =+R52/R50 -> 0.6335382 | S53: =+S52/S50 -> 0.71411945 | U53: =+U52/U50 -> 0.63010534
...

Sheet 2026 Summary (2)
B2: SYNAPTIC CASH FLOW FORECAST | C2: 46023 | D2: =EDATE(C2,1) -> 46054 | E2: =EDATE(D2,1) -> 46082 | F2: =EDATE(E2,1) -> 46113 | G2: =EDATE(F2,1) -> 46143 | H2: =EDATE(G2,1) -> 46174 | I2: =EDATE(H2,1) -> 46204 | J2: =EDATE(I2,1) -> 46235 | K2: =EDATE(J2,1) -> 46266 | ... N2: =EDATE(M2,1) -> 46357 | P2: Q1 | Q2: Q2 | R2: Q3 | S2: Q4 | U2: 2026 | W2: Check
B3: =+Version!$C$3 -> Y2025 12 v001
B5: Consulting - Classic | C5: =+'2026 Detail'!C8 -> 126737 | D5: =+'2026 Detail'!D8 -> 270160 | E5: =+'2026 Detail'!E8 -> 223350 | F5: =+'2026 Detail'!F8 -> 197930 | G5: =+'2026 Detail'!G8 -> 151930 | H5: =+'2026 Detail'!H8 -> 151930 | I5: =+'2026 Detail'!I8 -> 146930 | J5: =+'2026 Detail'!J8 -> 145000 | ... N5: =+'2026 Detail'!N8 -> 130000 | P5: =SUM(C5:E5) -> 620247 | Q5: =SUM(F5:H5) -> 501790 | R5: =SUM(I5:K5) -> 436930 | S5: =SUM(L5:N5) -> 410000 | U5: =SUM(C5:N5) -> 1968967 | W5: =ROUND(SUM(P5:S5)-U5,2) -> 0
B6: Consulting - AppIQ | C6: =+'2026 Detail'!C13 -> 163027.6 | D6: =+'2026 Detail'!D13 -> 123027.6 | E6: =+'2026 Detail'!E13 -> 366527.6 | F6: =+'2026 Detail'!F13 -> 386527.6 | G6: =+'2026 Detail'!G13 -> 268277.6 | H6: =+'2026 Detail'!H13 -> 268277.6 | I6: =+'2026 Detail'!I13 -> 403277.6 | J6: =+'2026 Detail'!J13 -> 390500 | ... N6: =+'2026 Detail'!N13 -> 550000 | P6: =SUM(C6:E6) -> 652582.8 | Q6: =SUM(F6:H6) -> 923082.8 | R6: =SUM(I6:K6) -> 1079777.6 | S6: =SUM(L6:N6) -> 1487000 | U6: =SUM(C6:N6) -> 4142443.2 | W6: =ROUND(SUM(P6:S6)-U6,2) -> 0
B8: Total Cash Collected | C8: =SUM(C5:C6) -> 289764.6 | D8: =SUM(D5:D6) -> 393187.6 | E8: =SUM(E5:E6) -> 589877.6 | F8: =SUM(F5:F6) -> 584457.6 | G8: =SUM(G5:G6) -> 420207.6 | H8: =SUM(H5:H6) -> 420207.6 | I8: =SUM(I5:I6) -> 550207.6 | J8: =SUM(J5:J6) -> 535500 | ... N8: =SUM(N5:N6) -> 680000 | P8: =SUM(P5:P6) -> 1272829.8 | Q8: =SUM(Q5:Q6) -> 1424872.8 | R8: =SUM(R5:R6) -> 1516707.6 | S8: =SUM(S5:S6) -> 1897000 | U8: =SUM(U5:U6) -> 6111410.2 | W8: =ROUND(SUM(P8:S8)-U8,2) -> 0
B10: Delivery | C10: =+'2026 Detail'!C17+'2026 Detail'!C18 -> 184080 | D10: =+'2026 Detail'!D17+'2026 Detail'!D18 -> 358933.05 | E10: =+'2026 Detail'!E17+'2026 Detail'!E18 -> 187171.8 | F10: =+'2026 Detail'!F17+'2026 Detail'!F18 -> 181171.8 | G10: =+'2026 Detail'!G17+'2026 Detail'!G18 -> 181171.8 | H10: =+'2026 Detail'!H17+'2026 Detail'!H18 -> 181171.8 | I10: =+'2026 Detail'!I17+'2026 Detail'!I18 -> 174671.8 | J10: =+'2026 Detail'!J17+'2026 Detail'!J18 -> 174671.8 | ... N10: =+'2026 Detail'!N17+'2026 Detail'!N18 -> 170171.8 | P10: =SUM(C10:E10) -> 730184.85 | Q10: =SUM(F10:H10) -> 543515.4 | R10: =SUM(I10:K10) -> 524015.4 | S10: =SUM(L10:N10) -> 510515.4 | U10: =SUM(C10:N10) -> 2308231 | W10: =ROUND(SUM(P10:S10)-U10,2) -> 0
B11: GTM | C11: =+'2026 Detail'!C19+'2026 Detail'!C20 -> 40630 | D11: =+'2026 Detail'!D19+'2026 Detail'!D20 -> 103559.49 | E11: =+'2026 Detail'!E19+'2026 Detail'!E20 -> 41546.5 | F11: =+'2026 Detail'!F19+'2026 Detail'!F20 -> 41546.5 | G11: =+'2026 Detail'!G19+'2026 Detail'!G20 -> 41546.5 | H11: =+'2026 Detail'!H19+'2026 Detail'!H20 -> 41546.5 | I11: =+'2026 Detail'!I19+'2026 Detail'!I20 -> 41546.5 | J11: =+'2026 Detail'!J19+'2026 Detail'!J20 -> 41546.5 | ... N11: =+'2026 Detail'!N19+'2026 Detail'!N20 -> 41546.5 | P11: =SUM(C11:E11) -> 185735.99 | Q11: =SUM(F11:H11) -> 124639.5 | R11: =SUM(I11:K11) -> 124639.5 | S11: =SUM(L11:N11) -> 124639.5 | U11: =SUM(C11:N11) -> 559654.49 | W11: =ROUND(SUM(P11:S11)-U11,2) -> 0
B12: Total Spend Classic | C12: =SUM(C10:C11) -> 224710 | D12: =SUM(D10:D11) -> 462492.54 | E12: =SUM(E10:E11) -> 228718.3 | F12: =SUM(F10:F11) -> 222718.3 | G12: =SUM(G10:G11) -> 222718.3 | H12: =SUM(H10:H11) -> 222718.3 | I12: =SUM(I10:I11) -> 216218.3 | J12: =SUM(J10:J11) -> 216218.3 | ... N12: =SUM(N10:N11) -> 211718.3 | P12: =SUM(P10:P11) -> 915920.84 | Q12: =SUM(Q10:Q11) -> 668154.9 | R12: =SUM(R10:R11) -> 648654.9 | S12: =SUM(S10:S11) -> 635154.9 | U12: =SUM(U10:U11) -> 2867885.5 | W12: =ROUND(SUM(P12:S12)-U12,2) -> 0
B14: Delivery | C14: =+'2026 Detail'!C23+'2026 Detail'!C24 -> 10600 | D14: =+'2026 Detail'!D23+'2026 Detail'!D24 -> 10600 | E14: =+'2026 Detail'!E23+'2026 Detail'!E24 -> 10600 | F14: =+'2026 Detail'!F23+'2026 Detail'!F24 -> 10600 | G14: =+'2026 Detail'!G23+'2026 Detail'!G24 -> 10600 | H14: =+'2026 Detail'!H23+'2026 Detail'!H24 -> 10600 | I14: =+'2026 Detail'!I23+'2026 Detail'!I24 -> 10600 | J14: =+'2026 Detail'!J23+'2026 Detail'!J24 -> 10600 | ... N14: =+'2026 Detail'!N23+'2026 Detail'!N24 -> 10600 | P14: =SUM(C14:E14) -> 31800 | Q14: =SUM(F14:H14) -> 31800 | R14: =SUM(I14:K14) -> 31800 | S14: =SUM(L14:N14) -> 31800 | U14: =SUM(C14:N14) -> 127200 | W14: =ROUND(SUM(P14:S14)-U14,2) -> 0
B15: GTM | C15: =+'2026 Detail'!C25+'2026 Detail'!C26 -> 47260 | D15: =+'2026 Detail'!D25+'2026 Detail'!D26 -> 47260 | E15: =+'2026 Detail'!E25+'2026 Detail'!E26 -> 47734 | F15: =+'2026 Detail'!F25+'2026 Detail'!F26 -> 34734 | G15: =+'2026 Detail'!G25+'2026 Detail'!G26 -> 34734 | H15: =+'2026 Detail'!H25+'2026 Detail'!H26 -> 34734 | I15: =+'2026 Detail'!I25+'2026 Detail'!I26 -> 34734 | J15: =+'2026 Detail'!J25+'2026 Detail'!J26 -> 34734 | ... N15: =+'2026 Detail'!N25+'2026 Detail'!N26 -> 34734 | P15: =SUM(C15:E15) -> 142254 | Q15: =SUM(F15:H15) -> 104202 | R15: =SUM(I15:K15) -> 104202 | S15: =SUM(L15:N15) -> 104202 | U15: =SUM(C15:N15) -> 454860 | W15: =ROUND(SUM(P15:S15)-U15,2) -> 0
B16: R&D | C16: =+'2026 Detail'!C27+'2026 Detail'!C28 -> 74520 | D16: =+'2026 Detail'!D27+'2026 Detail'!D28 -> 99357.75 | E16: =+'2026 Detail'!E27+'2026 Detail'!E28 -> 75498 | F16: =+'2026 Detail'!F27+'2026 Detail'!F28 -> 75498 | G16: =+'2026 Detail'!G27+'2026 Detail'!G28 -> 75498 | H16: =+'2026 Detail'!H27+'2026 Detail'!H28 -> 75498 | I16: =+'2026 Detail'!I27+'2026 Detail'!I28 -> 75498 | J16: =+'2026 Detail'!J27+'2026 Detail'!J28 -> 75498 | ... N16: =+'2026 Detail'!N27+'2026 Detail'!N28 -> 75498 | P16: =SUM(C16:E16) -> 249375.75 | Q16: =SUM(F16:H16) -> 226494 | R16: =SUM(I16:K16) -> 226494 | S16: =SUM(L16:N16) -> 226494 | U16: =SUM(C16:N16) -> 928857.75 | W16: =ROUND(SUM(P16:S16)-U16,2) -> 0
B17: Total Spend AppIQ | C17: =SUM(C14:C16) -> 132380 | D17: =SUM(D14:D16) -> 157217.75 | E17: =SUM(E14:E16) -> 133832 | F17: =SUM(F14:F16) -> 120832 | G17: =SUM(G14:G16) -> 120832 | H17: =SUM(H14:H16) -> 120832 | I17: =SUM(I14:I16) -> 120832 | J17: =SUM(J14:J16) -> 120832 | ... N17: =SUM(N14:N16) -> 120832 | P17: =SUM(P14:P16) -> 423429.75 | Q17: =SUM(Q14:Q16) -> 362496 | R17: =SUM(R14:R16) -> 362496 | S17: =SUM(S14:S16) -> 362496 | U17: =SUM(U14:U16) -> 1510917.8 | W17: =ROUND(SUM(P17:S17)-U17,2) -> 0
B19: Back Office | C19: =+'2026 Detail'!C33 -> 67260 | D19: =+'2026 Detail'!D33 -> 218460 | E19: =+'2026 Detail'!E33 -> 67260 | F19: =+'2026 Detail'!F33 -> 65760 | G19: =+'2026 Detail'!G33 -> 65760 | H19: =+'2026 Detail'!H33 -> 65760 | I19: =+'2026 Detail'!I33 -> 65260 | J19: =+'2026 Detail'!J33 -> 65260 | ... N19: =+'2026 Detail'!N33 -> 65260 | P19: =SUM(C19:E19) -> 352980 | Q19: =SUM(F19:H19) -> 197280 | R19: =SUM(I19:K19) -> 195780 | S19: =SUM(L19:N19) -> 195780 | U19: =SUM(C19:N19) -> 941820 | W19: =ROUND(SUM(P19:S19)-U19,2) -> 0
B20: Total Spend Back Office | C20: =SUM(C19:C19) -> 67260 | D20: =SUM(D19:D19) -> 218460 | E20: =SUM(E19:E19) -> 67260 | F20: =SUM(F19:F19) -> 65760 | G20: =SUM(G19:G19) -> 65760 | H20: =SUM(H19:H19) -> 65760 | I20: =SUM(I19:I19) -> 65260 | J20: =SUM(J19:J19) -> 65260 | ... N20: =SUM(N19:N19) -> 65260 | P20: =SUM(P19:P19) -> 352980 | Q20: =SUM(Q19:Q19) -> 197280 | R20: =SUM(R19:R19) -> 195780 | S20: =SUM(S19:S19) -> 195780 | U20: =SUM(U19:U19) -> 941820 | W20: =ROUND(SUM(P20:S20)-U20,2) -> 0
B22: Rent | C22: =+'2026 Detail'!C35 -> 3550 | D22: =+'2026 Detail'!D35 -> 3550 | E22: =+'2026 Detail'!E35 -> 3550 | F22: =+'2026 Detail'!F35 -> 3550 | G22: =+'2026 Detail'!G35 -> 3550 | H22: =+'2026 Detail'!H35 -> 3550 | I22: =+'2026 Detail'!I35 -> 3550 | J22: =+'2026 Detail'!J35 -> 3550 | ... N22: =+'2026 Detail'!N35 -> 3550 | P22: =SUM(C22:E22) -> 10650 | Q22: =SUM(F22:H22) -> 10650 | R22: =SUM(I22:K22) -> 10650 | S22: =SUM(L22:N22) -> 10650 | U22: =SUM(C22:N22) -> 42600 | W22: =ROUND(SUM(P22:S22)-U22,2) -> 0
B23: Hardware & Software | C23: =+'2026 Detail'!C36 -> 4060.245 | D23: =+'2026 Detail'!D36 -> 4804.695 | E23: =+'2026 Detail'!E36 -> 13162.958 | F23: =+'2026 Detail'!F36 -> 11670.068 | G23: =+'2026 Detail'!G36 -> 26012.721 | H23: =+'2026 Detail'!H36 -> 24274.236 | I23: =+'2026 Detail'!I36 -> 23138.231 | J23: =+'2026 Detail'!J36 -> 96432.766 | ... N23: =+'2026 Detail'!N36 -> 12600 | P23: =SUM(C23:E23) -> 22027.897 | Q23: =SUM(F23:H23) -> 61957.025 | R23: =SUM(I23:K23) -> 130374.94 | S23: =SUM(L23:N23) -> 50723.253 | U23: =SUM(C23:N23) -> 265083.12 | W23: =ROUND(SUM(P23:S23)-U23,2) -> 0
B24: Office & Supplies | C24: =+'2026 Detail'!C37 -> 750 | D24: =+'2026 Detail'!D37 -> 750 | E24: =+'2026 Detail'!E37 -> 750 | F24: =+'2026 Detail'!F37 -> 750 | G24: =+'2026 Detail'!G37 -> 750 | H24: =+'2026 Detail'!H37 -> 750 | I24: =+'2026 Detail'!I37 -> 750 | J24: =+'2026 Detail'!J37 -> 750 | ... N24: =+'2026 Detail'!N37 -> 750 | P24: =SUM(C24:E24) -> 2250 | Q24: =SUM(F24:H24) -> 2250 | R24: =SUM(I24:K24) -> 2250 | S24: =SUM(L24:N24) -> 2250 | U24: =SUM(C24:N24) -> 9000 | W24: =ROUND(SUM(P24:S24)-U24,2) -> 0
B25: Insurance | C25: =+'2026 Detail'!C38 -> 511.8791 | D25: =+'2026 Detail'!D38 -> 8528.5854 | E25: =+'2026 Detail'!E38 -> 3182.5867 | F25: =+'2026 Detail'!F38 -> 9254.4367 | G25: =+'2026 Detail'!G38 -> 1593.9765 | H25: =+'2026 Detail'!H38 -> 3130.6747 | I25: =+'2026 Detail'!I38 -> 5747.6472 | J25: =+'2026 Detail'!J38 -> 1836.7372 | ... N25: =+'2026 Detail'!N38 -> 2575 | P25: =SUM(C25:E25) -> 12223.051 | Q25: =SUM(F25:H25) -> 13979.088 | R25: =SUM(I25:K25) -> 10715.059 | S25: =SUM(L25:N25) -> 10404.071 | U25: =SUM(C25:N25) -> 47321.269 | W25: =ROUND(SUM(P25:S25)-U25,2) -> 0
B26: Legal Fees | C26: =+'2026 Detail'!C39 -> 12500 | D26: =+'2026 Detail'!D39 -> 12500 | E26: =+'2026 Detail'!E39 -> 12500 | F26: =+'2026 Detail'!F39 -> 10000 | G26: =+'2026 Detail'!G39 -> 10000 | H26: =+'2026 Detail'!H39 -> 10000 | I26: =+'2026 Detail'!I39 -> 8000 | J26: =+'2026 Detail'!J39 -> 8000 | ... N26: =+'2026 Detail'!N39 -> 8000 | P26: =SUM(C26:E26) -> 37500 | Q26: =SUM(F26:H26) -> 30000 | R26: =SUM(I26:K26) -> 24000 | S26: =SUM(L26:N26) -> 24000 | U26: =SUM(C26:N26) -> 115500 | W26: =ROUND(SUM(P26:S26)-U26,2) -> 0
B27: Accounting & Tax Fees | C27: =+'2026 Detail'!C40 -> 2500 | D27: =+'2026 Detail'!D40 -> 1500 | E27: =+'2026 Detail'!E40 -> 2000 | F27: =+'2026 Detail'!F40 -> 1500 | G27: =+'2026 Detail'!G40 -> 1500 | H27: =+'2026 Detail'!H40 -> 2000 | I27: =+'2026 Detail'!I40 -> 1500 | J27: =+'2026 Detail'!J40 -> 1500 | ... N27: =+'2026 Detail'!N40 -> 2000 | P27: =SUM(C27:E27) -> 6000 | Q27: =SUM(F27:H27) -> 5000 | R27: =SUM(I27:K27) -> 5000 | S27: =SUM(L27:N27) -> 5000 | U27: =SUM(C27:N27) -> 21000 | W27: =ROUND(SUM(P27:S27)-U27,2) -> 0
B28: Professional Fees | C28: =+'2026 Detail'!C41 -> 5000 | D28: =+'2026 Detail'!D41 -> 5000 | E28: =+'2026 Detail'!E41 -> 5000 | F28: =+'2026 Detail'!F41 -> 5000 | G28: =+'2026 Detail'!G41 -> 5000 | H28: =+'2026 Detail'!H41 -> 5000 | I28: =+'2026 Detail'!I41 -> 5000 | J28: =+'2026 Detail'!J41 -> 5000 | ... N28: =+'2026 Detail'!N41 -> 5000 | P28: =SUM(C28:E28) -> 15000 | Q28: =SUM(F28:H28) -> 15000 | R28: =SUM(I28:K28) -> 15000 | S28: =SUM(L28:N28) -> 15000 | U28: =SUM(C28:N28) -> 60000 | W28: =ROUND(SUM(P28:S28)-U28,2) -> 0
B29: Taxes, Licenses & Permits | C29: =+'2026 Detail'!C42 -> 250 | D29: =+'2026 Detail'!D42 -> 250 | E29: =+'2026 Detail'!E42 -> 250 | F29: =+'2026 Detail'!F42 -> 250 | G29: =+'2026 Detail'!G42 -> 250 | H29: =+'2026 Detail'!H42 -> 250 | I29: =+'2026 Detail'!I42 -> 250 | J29: =+'2026 Detail'!J42 -> 250 | ... N29: =+'2026 Detail'!N42 -> 250 | P29: =SUM(C29:E29) -> 750 | Q29: =SUM(F29:H29) -> 750 | R29: =SUM(I29:K29) -> 750 | S29: =SUM(L29:N29) -> 750 | U29: =SUM(C29:N29) -> 3000 | W29: =ROUND(SUM(P29:S29)-U29,2) -> 0
B30: Travel & Meals | C30: =+'2026 Detail'!C43 -> 15000 | D30: =+'2026 Detail'!D43 -> 15000 | E30: =+'2026 Detail'!E43 -> 15000 | F30: =+'2026 Detail'!F43 -> 15000 | G30: =+'2026 Detail'!G43 -> 15000 | H30: =+'2026 Detail'!H43 -> 15000 | I30: =+'2026 Detail'!I43 -> 15000 | J30: =+'2026 Detail'!J43 -> 15000 | ... N30: =+'2026 Detail'!N43 -> 15000 | P30: =SUM(C30:E30) -> 45000 | Q30: =SUM(F30:H30) -> 45000 | R30: =SUM(I30:K30) -> 45000 | S30: =SUM(L30:N30) -> 45000 | U30: =SUM(C30:N30) -> 180000 | W30: =ROUND(SUM(P30:S30)-U30,2) -> 0
B31: Total Other Spend | C31: =SUM(C22:C30) -> 44122.124 | D31: =SUM(D22:D30) -> 51883.28 | E31: =SUM(E22:E30) -> 55395.544 | F31: =SUM(F22:F30) -> 56974.504 | G31: =SUM(G22:G30) -> 63656.698 | H31: =SUM(H22:H30) -> 63954.911 | I31: =SUM(I22:I30) -> 62935.878 | J31: =SUM(J22:J30) -> 132319.5 | ... N31: =SUM(N22:N30) -> 49725 | P31: =SUM(P22:P30) -> 151400.95 | Q31: =SUM(Q22:Q30) -> 184586.11 | R31: =SUM(R22:R30) -> 243740 | S31: =SUM(S22:S30) -> 163777.32 | U31: =SUM(U22:U30) -> 743504.38 | W31: =ROUND(SUM(P31:S31)-U31,2) -> 0
B33: Total Cash Disbursements | C33: =+C12+C17+C20+C31 -> 468472.12 | D33: =+D12+D17+D20+D31 -> 890053.57 | E33: =+E12+E17+E20+E31 -> 485205.84 | F33: =+F12+F17+F20+F31 -> 466284.8 | G33: =+G12+G17+G20+G31 -> 472967 | H33: =+H12+H17+H20+H31 -> 473265.21 | I33: =+I12+I17+I20+I31 -> 465246.18 | J33: =+J12+J17+J20+J31 -> 534629.8 | ... N33: =+N12+N17+N20+N31 -> 447535.3 | P33: =+P12+P17+P20+P31 -> 1843731.5 | Q33: =+Q12+Q17+Q20+Q31 -> 1412517 | R33: =+R12+R17+R20+R31 -> 1450670.9 | S33: =+S12+S17+S20+S31 -> 1357208.2 | U33: =+U12+U17+U20+U31 -> 6064127.7 | W33: =ROUND(SUM(P33:S33)-U33,2) -> 0
B35: Guarenteed Payments | C35: =+'2026 Detail'!C48 -> 0 | D35: =+'2026 Detail'!D48 -> 0 | E35: =+'2026 Detail'!E48 -> 0 | F35: =+'2026 Detail'!F48 -> 0 | G35: =+'2026 Detail'!G48 -> 0 | H35: =+'2026 Detail'!H48 -> 0 | I35: =+'2026 Detail'!I48 -> 0 | J35: =+'2026 Detail'!J48 -> 0 | ... N35: =+'2026 Detail'!N48 -> 0 | P35: =SUM(C35:E35) -> 0 | Q35: =SUM(F35:H35) -> 0 | R35: =SUM(I35:K35) -> 0 | S35: =SUM(L35:N35) -> 0 | U35: =SUM(C35:N35) -> 0 | W35: =ROUND(SUM(P35:S35)-U35,2) -> 0
B36: Youreka Labs Inc | C36: =+'2026 Detail'!C49 -> 0 | D36: =+'2026 Detail'!D49 -> 0 | E36: =+'2026 Detail'!E49 -> 0 | F36: =+'2026 Detail'!F49 -> 0 | G36: =+'2026 Detail'!G49 -> 0 | H36: =+'2026 Detail'!H49 -> 0 | I36: =+'2026 Detail'!I49 -> 0 | J36: =+'2026 Detail'!J49 -> 0 | ... N36: =+'2026 Detail'!N49 -> 0 | P36: =SUM(C36:E36) -> 0 | Q36: =SUM(F36:H36) -> 0 | R36: =SUM(I36:K36) -> 0 | S36: =SUM(L36:N36) -> 0 | U36: =SUM(C36:N36) -> 0 | W36: =ROUND(SUM(P36:S36)-U36,2) -> 0
B37: Brex | C37: =+'2026 Detail'!C50 -> 0 | D37: =+'2026 Detail'!D50 -> 0 | E37: =+'2026 Detail'!E50 -> 0 | F37: =+'2026 Detail'!F50 -> 0 | G37: =+'2026 Detail'!G50 -> 0 | H37: =+'2026 Detail'!H50 -> 0 | I37: =+'2026 Detail'!I50 -> 0 | J37: =+'2026 Detail'!J50 -> 0 | ... N37: =+'2026 Detail'!N50 -> 0 | P37: =SUM(C37:E37) -> 0 | Q37: =SUM(F37:H37) -> 0 | R37: =SUM(I37:K37) -> 0 | S37: =SUM(L37:N37) -> 0 | U37: =SUM(C37:N37) -> 0 | W37: =ROUND(SUM(P37:S37)-U37,2) -> 0
B38: Chase Visa | C38: =+'2026 Detail'!C51 -> 0 | D38: =+'2026 Detail'!D51 -> 0 | E38: =+'2026 Detail'!E51 -> 0 | F38: =+'2026 Detail'!F51 -> 0 | G38: =+'2026 Detail'!G51 -> 0 | H38: =+'2026 Detail'!H51 -> 0 | I38: =+'2026 Detail'!I51 -> 0 | J38: =+'2026 Detail'!J51 -> 0 | ... N38: =+'2026 Detail'!N51 -> 0 | P38: =SUM(C38:E38) -> 0 | Q38: =SUM(F38:H38) -> 0 | R38: =SUM(I38:K38) -> 0 | S38: =SUM(L38:N38) -> 0 | U38: =SUM(C38:N38) -> 0 | W38: =ROUND(SUM(P38:S38)-U38,2) -> 0
B39: Ramp | C39: =+'2026 Detail'!C52 -> 0 | D39: =+'2026 Detail'!D52 -> 0 | E39: =+'2026 Detail'!E52 -> 0 | F39: =+'2026 Detail'!F52 -> 0 | G39: =+'2026 Detail'!G52 -> 0 | H39: =+'2026 Detail'!H52 -> 0 | I39: =+'2026 Detail'!I52 -> 0 | J39: =+'2026 Detail'!J52 -> 0 | ... N39: =+'2026 Detail'!N52 -> 0 | P39: =SUM(C39:E39) -> 0 | Q39: =SUM(F39:H39) -> 0 | R39: =SUM(I39:K39) -> 0 | S39: =SUM(L39:N39) -> 0 | U39: =SUM(C39:N39) -> 0 | W39: =ROUND(SUM(P39:S39)-U39,2) -> 0
B40: Bank Fees | C40: =+'2026 Detail'!C53 -> -400 | D40: =+'2026 Detail'!D53 -> -400 | E40: =+'2026 Detail'!E53 -> -400 | F40: =+'2026 Detail'!F53 -> -400 | G40: =+'2026 Detail'!G53 -> -400 | H40: =+'2026 Detail'!H53 -> -400 | I40: =+'2026 Detail'!I53 -> -400 | J40: =+'2026 Detail'!J53 -> -400 | ... N40: =+'2026 Detail'!N53 -> -400 | P40: =SUM(C40:E40) -> -1200 | Q40: =SUM(F40:H40) -> -1200 | R40: =SUM(I40:K40) -> -1200 | S40: =SUM(L40:N40) -> -1200 | U40: =SUM(C40:N40) -> -4800 | W40: =ROUND(SUM(P40:S40)-U40,2) -> 0
B41: Interest | C41: =+'2026 Detail'!C54 -> 500 | D41: =+'2026 Detail'!D54 -> 400 | E41: =+'2026 Detail'!E54 -> 100 | F41: =+'2026 Detail'!F54 -> 200 | G41: =+'2026 Detail'!G54 -> 300 | H41: =+'2026 Detail'!H54 -> 200 | I41: =+'2026 Detail'!I54 -> 200 | J41: =+'2026 Detail'!J54 -> 200 | ... N41: =+'2026 Detail'!N54 -> 400 | P41: =SUM(C41:E41) -> 1000 | Q41: =SUM(F41:H41) -> 700 | R41: =SUM(I41:K41) -> 600 | S41: =SUM(L41:N41) -> 900 | U41: =SUM(C41:N41) -> 3200 | W41: =ROUND(SUM(P41:S41)-U41,2) -> 0
B43: Opening Cash Balance | C43: =+'2026 Detail'!C56 -> 964110.73 | D43: =+C48 -> 785503.21 | E43: =+D48 -> 288637.24 | F43: =+E48 -> 393009 | G43: =+F48 -> 510981.8 | H43: =+G48 -> 458122.4 | I43: =+H48 -> 404864.79 | J43: =+I48 -> 489626.21 | K43: =+J48 -> 490296.41 | ... N43: =+M48 -> 777328.56 | P43: =+C43 -> 964110.73 | Q43: =+P48 -> 393009 | R43: =+Q48 -> 404865 | S43: =+R48 -> 470302 | U43: =+P43 -> 964110.73
B45: Net Change | C45: =C8-C33+SUM(C35:C41) -> -178607.52 | D45: =D8-D33+SUM(D35:D41) -> -496865.97 | E45: =E8-E33+SUM(E35:E41) -> 104371.76 | F45: =F8-F33+SUM(F35:F41) -> 117972.8 | G45: =G8-G33+SUM(G35:G41) -> -52859.398 | H45: =H8-H33+SUM(H35:H41) -> -53257.611 | I45: =I8-I33+SUM(I35:I41) -> 84761.422 | J45: =J8-J33+SUM(J35:J41) -> 670.1963 | ... N45: =N8-N33+SUM(N35:N41) -> 232464.7 | P45: =SUM(C45:E45) -> -571101.74 | Q45: =SUM(F45:H45) -> 11855.788 | R45: =SUM(I45:K45) -> 65436.7 | S45: =SUM(L45:N45) -> 539491.78 | U45: =SUM(C45:N45) -> 45682.528 | W45: =ROUND(SUM(P45:S45)-U45,2) -> 0
B46: Investment | C46: =+'2026 Detail'!C59 -> 0 | D46: =+'2026 Detail'!D59 -> 0 | E46: =+'2026 Detail'!E59 -> 0 | F46: =+'2026 Detail'!F59 -> 0 | G46: =+'2026 Detail'!G59 -> 0 | H46: =+'2026 Detail'!H59 -> 0 | I46: =+'2026 Detail'!I59 -> 0 | J46: =+'2026 Detail'!J59 -> 0 | ... N46: =+'2026 Detail'!N59 -> 0 | P46: =SUM(C46:E46) -> 0 | Q46: =SUM(F46:H46) -> 0 | R46: =SUM(I46:K46) -> 0 | S46: =SUM(L46:N46) -> 0 | U46: =SUM(C46:N46) -> 0 | W46: =ROUND(SUM(P46:S46)-U46,2) -> 0
B48: Ending Cash Balance | C48: =ROUND(+C43+C45+C46,2) -> 785503.21 | D48: =ROUND(+D43+D45+D46,2) -> 288637.24 | E48: =ROUND(+E43+E45+E46,2) -> 393009 | F48: =ROUND(+F43+F45+F46,2) -> 510981.8 | G48: =ROUND(+G43+G45+G46,2) -> 458122.4 | H48: =ROUND(+H43+H45+H46,2) -> 404864.79 | I48: =ROUND(+I43+I45+I46,2) -> 489626.21 | J48: =ROUND(+J43+J45+J46,2) -> 490296.41 | ... N48: =ROUND(+N43+N45+N46,2) -> 1009793.3 | P48: =ROUND(+P43+P45+P46,0) -> 393009 | Q48: =ROUND(+Q43+Q45+Q46,0) -> 404865 | R48: =ROUND(+R43+R45+R46,0) -> 470302 | S48: =ROUND(+S43+S45+S46,0) -> 1009794 | U48: =ROUND(+U43+U45+U46,0) -> 1009793
B50: Cash In | C50: =+C8 -> 289764.6 | D50: =+D8 -> 393187.6 | E50: =+E8 -> 589877.6 | F50: =+F8 -> 584457.6 | G50: =+G8 -> 420207.6 | H50: =+H8 -> 420207.6 | I50: =+I8 -> 550207.6 | J50: =+J8 -> 535500 | ... N50: =+N8 -> 680000 | P50: =+P8 -> 1272829.8 | Q50: =+Q8 -> 1424872.8 | R50: =+R8 -> 1516707.6 | S50: =+S8 -> 1897000 | U50: =+U8 -> 6111410.2
B51: Calculated COGS | C51: =+C10+C14 -> 194680 | D51: =+D10+D14 -> 369533.05 | E51: =+E10+E14 -> 197771.8 | F51: =+F10+F14 -> 191771.8 | G51: =+G10+G14 -> 191771.8 | H51: =+H10+H14 -> 191771.8 | I51: =+I10+I14 -> 185271.8 | J51: =+J10+J14 -> 185271.8 | ... N51: =+N10+N14 -> 180771.8 | P51: =+P10+P14 -> 761984.85 | Q51: =+Q10+Q14 -> 575315.4 | R51: =+R10+R14 -> 555815.4 | S51: =+S10+S14 -> 542315.4 | U51: =+U10+U14 -> 2435431
B52: Gross Margin | C52: =+C50-C51 -> 95084.6 | D52: =+D50-D51 -> 23654.551 | E52: =+E50-E51 -> 392105.8 | F52: =+F50-F51 -> 392685.8 | G52: =+G50-G51 -> 228435.8 | H52: =+H50-H51 -> 228435.8 | I52: =+I50-I51 -> 364935.8 | J52: =+J50-J51 -> 350228.2 | ... N52: =+N50-N51 -> 499228.2 | P52: =+P50-P51 -> 510844.95 | Q52: =+Q50-Q51 -> 849557.4 | R52: =+R50-R51 -> 960892.2 | S52: =+S50-S51 -> 1354684.6 | U52: =+U50-U51 -> 3675979.2
B53: GM % | C53: =+C52/C50 -> 0.32814429 | D53: =+D52/D50 -> 0.060160979 | E53: =+E52/E50 -> 0.664724 | F53: =+F52/F50 -> 0.67188073 | G53: =+G52/G50 -> 0.54362606 | H53: =+H52/H50 -> 0.54362606 | I53: =+I52/I50 -> 0.66326928 | J53: =+J52/J50 -> 0.65402092 | ... N53: =+N52/N50 -> 0.73415912 | P53: =+P52/P50 -> 0.40134584 | Q53: =+Q52/Q50 -> 0.59623385 | R53: =+R52/R50 -> 0.6335382 | S53: =+S52/S50 -> 0.71411945 | U53: =+U52/U50 -> 0.60149442
...

Sheet Assumptions
A1: Assumptions
A2: =+Version!$C$3 -> Y2025 12 v001
A4: =ROW()-3 -> 1 | B4: Y2025 cash collections based on actual & known invoicing
A5: =ROW()-3 -> 2 | B5: Y2026 cash collections based on actual, known & forecast (highighted in purple on (1) Collections tab
A6: =ROW()-3 -> 3 | B6: Employee bonus payouts @ 70% (equal to Y2025 accrual) and paid out in February 2026
A7: =ROW()-3 -> 4 | B7: Employee raises of 3% effective in March 2026
A8: =ROW()-3 -> 5 | B8: Employee commissions of $4600 per month beginning October 2025
A9: =ROW()-3 -> 6 | B9: No headcount changes to current team of 14
A10: =ROW()-3 -> 7 | B10: Benefit increase of 6.1% covered by employer
A11: =ROW()-3 -> 8 | B11: Contractors at current levels with some additions - need to review one by one together to confirm
A12: =ROW()-3 -> 9 | B12: Hardware and software cost increase by 5% from 2025 to 2026
A13: =ROW()-3 -> 10 | B13: Office & insurance cost remain flat year over year
A14: =ROW()-3 -> 11 | B14: Legal cost reduces to run rate at end of Y2025
A15: =ROW()-3 -> 12 | B15: Accounting & tax cost reduced due to new agreement with SC&H
... A17: =ROW()-3 -> 14 | B17: Travel cost baselined at last four months of Y2025

Sheet Overview
B2: SYNAPTIC CASH FLOW FORECAST | C2: Q1-2025 | D2: Q2-2025 | E2: Q3-2025 | F2: Q4-2025 | H2: Q1-2026 | I2: Q2-2026 | J2: Q3-2026 | K2: Q4-2026 | M2: 2025 | N2: 2026 | P2: 26v25 B (W) $ | Q2: 26v25 B (W) %
B3: =+Version!$C$3 -> Y2025 12 v001
B5: Classic | C5: =+'2025 Detail'!P8 -> 728757.46 | D5: =+'2025 Detail'!Q8 -> 444190.5 | E5: =+'2025 Detail'!R8 -> 447319.5 | F5: =+'2025 Detail'!S8 -> 766915.5 | H5: =+'2026 Detail'!P8 -> 620247 | I5: =+'2026 Detail'!Q8 -> 501790 | J5: =+'2026 Detail'!R8 -> 436930 | K5: =+'2026 Detail'!S8 -> 410000 | M5: =SUM(C5:F5) -> 2387183 | N5: =SUM(H5:K5) -> 1968967 | P5: =+N5-M5 -> -418215.96 | Q5: =+P5/M5 -> -0.17519225
B6: AppIQ | C6: =+'2025 Detail'!P13 -> 176292.98 | D6: =+'2025 Detail'!Q13 -> 76692 | E6: =+'2025 Detail'!R13 -> 172277.6 | F6: =+'2025 Detail'!S13 -> 779860.4 | H6: =+'2026 Detail'!P13 -> 652582.8 | I6: =+'2026 Detail'!Q13 -> 923082.8 | J6: =+'2026 Detail'!R13 -> 1079777.6 | K6: =+'2026 Detail'!S13 -> 1487000 | M6: =SUM(C6:F6) -> 1205123 | N6: =SUM(H6:K6) -> 4142443.2 | P6: =+N6-M6 -> 2937320.2 | Q6: =+P6/M6 -> 2.4373614
B7: Cash Collected | C7: =SUM(C5:C6) -> 905050.44 | D7: =SUM(D5:D6) -> 520882.5 | E7: =SUM(E5:E6) -> 619597.1 | F7: =SUM(F5:F6) -> 1546775.9 | H7: =SUM(H5:H6) -> 1272829.8 | I7: =SUM(I5:I6) -> 1424872.8 | J7: =SUM(J5:J6) -> 1516707.6 | K7: =SUM(K5:K6) -> 1897000 | M7: =SUM(M5:M6) -> 3592305.9 | N7: =SUM(N5:N6) -> 6111410.2 | P7: =SUM(P5:P6) -> 2519104.3 | Q7: =+P7/M7 -> 0.70124992
N8: 6.2
B9: Classic | C9: =+C5/C$7 -> 0.80521198 | D9: =+D5/D$7 -> 0.85276526 | E9: =+E5/E$7 -> 0.72195222 | F9: =+F5/F$7 -> 0.49581552 | H9: =+H5/H$7 -> 0.48729767 | I9: =+I5/I$7 -> 0.35216477 | J9: =+J5/J$7 -> 0.28807794 | K9: =+K5/K$7 -> 0.21613073 | M9: =+M5/M$7 -> 0.66452663 | N9: =+N5/N$7 -> 0.32217883
B10: AppIQ | C10: =+C6/C$7 -> 0.19478802 | D10: =+D6/D$7 -> 0.14723474 | E10: =+E6/E$7 -> 0.27804778 | F10: =+F6/F$7 -> 0.50418448 | H10: =+H6/H$7 -> 0.51270233 | I10: =+I6/I$7 -> 0.64783523 | J10: =+J6/J$7 -> 0.71192206 | K10: =+K6/K$7 -> 0.78386927 | M10: =+M6/M$7 -> 0.33547337 | N10: =+N6/N$7 -> 0.67782117
B12: Delivery (COGS) | C12: =+'2025 Detail'!P17+'2025 Detail'!P18+'2025 Detail'!P23+'2025 Detail'!P24 -> 834144.13 | D12: =+'2025 Detail'!Q17+'2025 Detail'!Q18+'2025 Detail'!Q23+'2025 Detail'!Q24 -> 576858.66 | E12: =+'2025 Detail'!R17+'2025 Detail'!R18+'2025 Detail'!R23+'2025 Detail'!R24 -> 562447.14 | F12: =+'2025 Detail'!S17+'2025 Detail'!S18+'2025 Detail'!S23+'2025 Detail'!S24 -> 584581.13 | H12: =+'2026 Detail'!P17+'2026 Detail'!P18+'2026 Detail'!P23+'2026 Detail'!P24 -> 761984.85 | I12: =+'2026 Detail'!Q17+'2026 Detail'!Q18+'2026 Detail'!Q23+'2026 Detail'!Q24 -> 575315.4 | J12: =+'2026 Detail'!R17+'2026 Detail'!R18+'2026 Detail'!R23+'2026 Detail'!R24 -> 555815.4 | K12: =+'2026 Detail'!S17+'2026 Detail'!S18+'2026 Detail'!S23+'2026 Detail'!S24 -> 542315.4 | M12: =SUM(C12:F12) -> 2558031.1 | N12: =SUM(H12:K12) -> 2435431 | P12: =+M12-N12 -> 122600.02 | Q12: =+P12/M12 -> 0.047927493
B14: Gross Margin | C14: =+C7-C12 -> 70906.308 | D14: =+D7-D12 -> -55976.161 | E14: =+E7-E12 -> 57149.956 | F14: =+F7-F12 -> 962194.77 | H14: =+H7-H12 -> 510844.95 | I14: =+I7-I12 -> 849557.4 | J14: =+J7-J12 -> 960892.2 | K14: =+K7-K12 -> 1354684.6 | M14: =+M7-M12 -> 1034274.9 | N14: =+N7-N12 -> 3675979.2 | P14: =+N14-M14 -> 2641704.3 | Q14: =+P14/M14 -> 2.5541607
B15: Gross Margin % | C15: =+C14/C7 -> 0.078345146 | D15: =+D14/D7 -> -0.10746408 | E15: =+E14/E7 -> 0.092237288 | F15: =+F14/F7 -> 0.62206476 | H15: =+H14/H7 -> 0.40134584 | I15: =+I14/I7 -> 0.59623385 | J15: =+J14/J7 -> 0.6335382 | K15: =+K14/K7 -> 0.71411945 | M15: =+M14/M7 -> 0.28791392 | N15: =+N14/N7 -> 0.60149442
B17: Research & Development | C17: =+'2025 Detail'!P27+'2025 Detail'!P28 -> 238999.44 | D17: =+'2025 Detail'!Q27+'2025 Detail'!Q28 -> 293164.95 | E17: =+'2025 Detail'!R27+'2025 Detail'!R28 -> 304995.69 | F17: =+'2025 Detail'!S27+'2025 Detail'!S28 -> 260047.26 | H17: =+'2026 Detail'!P27+'2026 Detail'!P28 -> 249375.75 | I17: =+'2026 Detail'!Q27+'2026 Detail'!Q28 -> 226494 | J17: =+'2026 Detail'!R27+'2026 Detail'!R28 -> 226494 | K17: =+'2026 Detail'!S27+'2026 Detail'!S28 -> 226494 | M17: =SUM(C17:F17) -> 1097207.3 | N17: =SUM(H17:K17) -> 928857.75 | P17: =+M17-N17 -> 168349.59 | Q17: =+P17/M17 -> 0.15343462
B18: Go to Market | C18: =+'2025 Detail'!P19+'2025 Detail'!P20+'2025 Detail'!P25+'2025 Detail'!P26 -> 344879.09 | D18: =+'2025 Detail'!Q19+'2025 Detail'!Q20+'2025 Detail'!Q25+'2025 Detail'!Q26 -> 434425.35 | E18: =+'2025 Detail'!R19+'2025 Detail'!R20+'2025 Detail'!R25+'2025 Detail'!R26 -> 354262.14 | F18: =+'2025 Detail'!S19+'2025 Detail'!S20+'2025 Detail'!S25+'2025 Detail'!S26 -> 271117.28 | H18: =+'2026 Detail'!P19+'2026 Detail'!P20+'2026 Detail'!P25+'2026 Detail'!P26 -> 327989.99 | I18: =+'2026 Detail'!Q19+'2026 Detail'!Q20+'2026 Detail'!Q25+'2026 Detail'!Q26 -> 228841.5 | J18: =+'2026 Detail'!R19+'2026 Detail'!R20+'2026 Detail'!R25+'2026 Detail'!R26 -> 228841.5 | K18: =+'2026 Detail'!S19+'2026 Detail'!S20+'2026 Detail'!S25+'2026 Detail'!S26 -> 228841.5 | M18: =SUM(C18:F18) -> 1404683.9 | N18: =SUM(H18:K18) -> 1014514.5 | P18: =+M18-N18 -> 390169.37 | Q18: =+P18/M18 -> 0.27776312
B19: Back Office & Administrative | C19: =+'2025 Detail'!P33 -> 277163.6 | D19: =+'2025 Detail'!Q33 -> 233495.23 | E19: =+'2025 Detail'!R33 -> 235870.15 | F19: =+'2025 Detail'!S33 -> 209935.82 | H19: =+'2026 Detail'!P33 -> 352980 | I19: =+'2026 Detail'!Q33 -> 197280 | J19: =+'2026 Detail'!R33 -> 195780 | K19: =+'2026 Detail'!S33 -> 195780 | M19: =SUM(C19:F19) -> 956464.79 | N19: =SUM(H19:K19) -> 941820 | P19: =+M19-N19 -> 14644.792 | Q19: =+P19/M19 -> 0.015311376
B20: Other | C20: ='2025 Detail'!P44-SUM('2025 Detail'!P48:P54) -> 168230.69 | D20: ='2025 Detail'!Q44-SUM('2025 Detail'!Q48:Q54) -> 260628.4 | E20: ='2025 Detail'!R44-SUM('2025 Detail'!R48:R54) -> 231119.46 | F20: ='2025 Detail'!S44-SUM('2025 Detail'!S48:S54) -> 186169.49 | H20: ='2026 Detail'!P44-SUM('2026 Detail'!P48:P54) -> 151600.95 | I20: ='2026 Detail'!Q44-SUM('2026 Detail'!Q48:Q54) -> 185086.11 | J20: ='2026 Detail'!R44-SUM('2026 Detail'!R48:R54) -> 244340 | K20: ='2026 Detail'!S44-SUM('2026 Detail'!S48:S54) -> 164077.32 | M20: =SUM(C20:F20) -> 846148.04 | N20: =SUM(H20:K20) -> 745104.38 | P20: =+M20-N20 -> 101043.66 | Q20: =+P20/M20 -> 0.11941605
B21: Operating Cost | C21: =SUM(C17:C20) -> 1029272.8 | D21: =SUM(D17:D20) -> 1221713.9 | E21: =SUM(E17:E20) -> 1126247.4 | F21: =SUM(F17:F20) -> 927269.84 | H21: =SUM(H17:H20) -> 1081946.7 | I21: =SUM(I17:I20) -> 837701.61 | J21: =SUM(J17:J20) -> 895455.5 | K21: =SUM(K17:K20) -> 815192.82 | M21: =SUM(M17:M20) -> 4304504 | N21: =SUM(N17:N20) -> 3630296.6 | P21: =+M21-N21 -> 674207.4 | Q21: =+P21/M21 -> 0.15662836
B23: Research & Development | C23: =+C17/C$7 -> 0.26407306 | D23: =+D17/D$7 -> 0.56282357 | E23: =+E17/E$7 -> 0.49224842 | F23: =+F17/F$7 -> 0.16812213 | H23: =+H17/H$7 -> 0.19592231 | I23: =+I17/I$7 -> 0.15895735 | J23: =+J17/J$7 -> 0.14933267 | K23: =+K17/K$7 -> 0.11939589 | M23: =+M17/M$7 -> 0.3054326 | N23: =+N17/N$7 -> 0.15198747
B24: Go to Market | C24: =+C18/C$7 -> 0.38106063 | D24: =+D18/D$7 -> 0.83401795 | E24: =+E18/E$7 -> 0.5717621 | F24: =+F18/F$7 -> 0.17527896 | H24: =+H18/H$7 -> 0.25768566 | I24: =+I18/I$7 -> 0.16060486 | J24: =+J18/J$7 -> 0.15088043 | K24: =+K18/K$7 -> 0.12063337 | M24: =+M18/M$7 -> 0.39102568 | N24: =+N18/N$7 -> 0.16600334
B25: Back Office & Administrative | C25: =+C20/C$7 -> 0.18587991 | D25: =+D20/D$7 -> 0.50035929 | E25: =+E20/E$7 -> 0.37301572 | F25: =+F20/F$7 -> 0.1203597 | H25: =+H20/H$7 -> 0.11910544 | I25: =+I20/I$7 -> 0.12989659 | J25: =+J20/J$7 -> 0.16109895 | K25: =+K20/K$7 -> 0.086493054 | M25: =+M20/M$7 -> 0.23554454 | N25: =+N20/N$7 -> 0.12192021
B27: Opening Cash Balance | C27: =+'2025 Detail'!P56 -> 3334341 | D27: =+C32 -> 3325973 | E27: =+D32 -> 2023283 | F27: =+E32 -> 954186 | H27: =+F32 -> 964111 | I27: =+H32 -> 393009 | J27: =+I32 -> 404865 | K27: =+J32 -> 470302 | M27: =+C27 -> 3334341 | N27: =+M32 -> 964111
B29: Net Change | C29: =+C7-C12-C21 -> -958366.51 | D29: =+D7-D12-D21 -> -1277690.1 | E29: =+E7-E12-E21 -> -1069097.5 | F29: =+F7-F12-F21 -> 34924.93 | H29: =+H7-H12-H21 -> -571101.74 | I29: =+I7-I12-I21 -> 11855.788 | J29: =+J7-J12-J21 -> 65436.7 | K29: =+K7-K12-K21 -> 539491.78 | M29: =SUM(C29:F29) -> -3270229.2 | N29: =SUM(H29:K29) -> 45682.528 | P29: =+N29-M29 -> 3315911.7 | Q29: =+P29/ABS(M29) -> 1.0139692
B30: Investment | C30: =+'2025 Detail'!P59 -> 949998.86 | D30: =+'2025 Detail'!Q59 -> -25000 | E30: =+'2025 Detail'!R59 -> 0 | F30: =+'2025 Detail'!S59 -> -25000 | H30: =+'2026 Detail'!P59 -> 0 | I30: =+'2026 Detail'!Q59 -> 0 | J30: =+'2026 Detail'!R59 -> 0 | K30: =+'2026 Detail'!S59 -> 0 | M30: =SUM(C30:F30) -> 899998.86 | N30: =SUM(H30:K30) -> 0
B32: Ending Cash Balance | C32: =ROUND(+C27+C29+C30,0) -> 3325973 | D32: =ROUND(+D27+D29+D30,0) -> 2023283 | E32: =ROUND(+E27+E29+E30,0) -> 954186 | F32: =ROUND(+F27+F29+F30,0) -> 964111 | H32: =ROUND(+H27+H29+H30,0) -> 393009 | I32: =ROUND(+I27+I29+I30,0) -> 404865 | J32: =ROUND(+J27+J29+J30,0) -> 470302 | K32: =ROUND(+K27+K29+K30,0) -> 1009794 | M32: =ROUND(+M27+M29+M30,0) -> 964111 | N32: =ROUND(+N27+N29+N30,0) -> 1009794
B34: Check | C34: =+C32-'2025 Detail'!P61 -> 0 | D34: =+D32-'2025 Detail'!Q61 -> 0 | E34: =+E32-'2025 Detail'!R61 -> 0 | F34: =+F32-'2025 Detail'!S61 -> 0 | H34: =+H32-'2026 Detail'!P61 -> 0 | I34: =+I32-'2026 Detail'!Q61 -> 0 | J34: =+J32-'2026 Detail'!R61 -> 0 | K34: =+K32-'2026 Detail'!S61 -> 0 | M34: =+M32-'2025 Detail'!U61 -> 0 | N34: =+N32-'2026 Detail'!U61 -> 1

Sheet 2025 to 2026 Detail View
B2: SYNAPTIC CASH FLOW FORECAST | C2: Q1-2025 | D2: Q2-2025 | E2: Q3-2025 | F2: Q4-2025 | H2: Q1-2026 | I2: Q2-2026 | J2: Q3-2026 | K2: Q4-2026 | M2: 2025 | N2: 2026 | P2: 26v25 B (W) $ | Q2: 26v25 B (W) % | S2: Check | T2: Check
B3: =+Version!$C$3 -> Y2025 12 v001
B5: HLS | C5: =+'2025 Detail'!P5 -> 144854.4 | D5: =+'2025 Detail'!Q5 -> 68681.25 | E5: =+'2025 Detail'!R5 -> 28510 | F5: =+'2025 Detail'!S5 -> 6540 | H5: =+'2026 Detail'!P5 -> 5790 | I5: =+'2026 Detail'!Q5 -> 5790 | J5: =+'2026 Detail'!R5 -> 1930 | K5: =+'2026 Detail'!S5 -> 0 | M5: =SUM(C5:F5) -> 248585.65 | N5: =SUM(H5:K5) -> 13510 | P5: =+N5-M5 -> -235075.65 | Q5: =+P5/M5 -> -0.94565253 | S5: =+M5-'2025 Detail'!U5 -> 0 | T5: =+N5-'2026 Detail'!U5 -> 0
B6: PSS | C6: =+'2025 Detail'!P6 -> 374941.7 | D6: =+'2025 Detail'!Q6 -> 349616.4 | E6: =+'2025 Detail'!R6 -> 281609.6 | F6: =+'2025 Detail'!S6 -> 534745 | H6: =+'2026 Detail'!P6 -> 494607 | I6: =+'2026 Detail'!Q6 -> 376000 | J6: =+'2026 Detail'!R6 -> 330000 | K6: =+'2026 Detail'!S6 -> 320000 | M6: =SUM(C6:F6) -> 1540912.7 | N6: =SUM(H6:K6) -> 1520607 | P6: =+N6-M6 -> -20305.7 | Q6: =+P6/M6 -> -0.01317771 | S6: =+M6-'2025 Detail'!U6 -> 0 | T6: =+N6-'2026 Detail'!U6 -> 0
B7: ENT | C7: =+'2025 Detail'!P7 -> 208961.36 | D7: =+'2025 Detail'!Q7 -> 25892.85 | E7: =+'2025 Detail'!R7 -> 137199.9 | F7: =+'2025 Detail'!S7 -> 225630.5 | H7: =+'2026 Detail'!P7 -> 119850 | I7: =+'2026 Detail'!Q7 -> 120000 | J7: =+'2026 Detail'!R7 -> 105000 | K7: =+'2026 Detail'!S7 -> 90000 | M7: =SUM(C7:F7) -> 597684.61 | N7: =SUM(H7:K7) -> 434850 | P7: =+N7-M7 -> -162834.61 | Q7: =+P7/M7 -> -0.27244237 | S7: =+M7-'2025 Detail'!U7 -> 0 | T7: =+N7-'2026 Detail'!U7 -> 0
B8: Total Classic | C8: =SUM(C5:C7) -> 728757.46 | D8: =SUM(D5:D7) -> 444190.5 | E8: =SUM(E5:E7) -> 447319.5 | F8: =SUM(F5:F7) -> 766915.5 | H8: =SUM(H5:H7) -> 620247 | I8: =SUM(I5:I7) -> 501790 | J8: =SUM(J5:J7) -> 436930 | K8: =SUM(K5:K7) -> 410000 | M8: =SUM(M5:M7) -> 2387183 | N8: =SUM(N5:N7) -> 1968967 | P8: =+N8-M8 -> -418215.96 | Q8: =+P8/M8 -> -0.17519225 | S8: =+M8-'2025 Detail'!U8 -> 0 | T8: =+N8-'2026 Detail'!U8 -> 0
B10: HLS | C10: =+'2025 Detail'!P10 -> 176292.98 | D10: =+'2025 Detail'!Q10 -> 41705 | E10: =+'2025 Detail'!R10 -> 0 | F10: =+'2025 Detail'!S10 -> 306250 | H10: =+'2026 Detail'!P10 -> 190750 | I10: =+'2026 Detail'!Q10 -> 336250 | J10: =+'2026 Detail'!R10 -> 456000 | K10: =+'2026 Detail'!S10 -> 550000 | M10: =SUM(C10:F10) -> 524247.98 | N10: =SUM(H10:K10) -> 1533000 | P10: =+N10-M10 -> 1008752 | Q10: =+P10/M10 -> 1.9241887 | S10: =+M10-'2025 Detail'!U10 -> 0 | T10: =+N10-'2026 Detail'!U10 -> 0
B11: PSS | C11: =+'2025 Detail'!P11 -> 0 | D11: =+'2025 Detail'!Q11 -> 9987 | E11: =+'2025 Detail'!R11 -> 39277.6 | F11: =+'2025 Detail'!S11 -> 387610.4 | H11: =+'2026 Detail'!P11 -> 367832.8 | I11: =+'2026 Detail'!Q11 -> 472832.8 | J11: =+'2026 Detail'!R11 -> 503777.6 | K11: =+'2026 Detail'!S11 -> 750000 | M11: =SUM(C11:F11) -> 436875 | N11: =SUM(H11:K11) -> 2094443.2 | P11: =+N11-M11 -> 1657568.2 | Q11: =+P11/M11 -> 3.7941475 | S11: =+M11-'2025 Detail'!U11 -> 0 | T11: =+N11-'2026 Detail'!U11 -> 0
B12: ENT | C12: =+'2025 Detail'!P12 -> 0 | D12: =+'2025 Detail'!Q12 -> 25000 | E12: =+'2025 Detail'!R12 -> 133000 | F12: =+'2025 Detail'!S12 -> 86000 | H12: =+'2026 Detail'!P12 -> 94000 | I12: =+'2026 Detail'!Q12 -> 114000 | J12: =+'2026 Detail'!R12 -> 120000 | K12: =+'2026 Detail'!S12 -> 187000 | M12: =SUM(C12:F12) -> 244000 | N12: =SUM(H12:K12) -> 515000 | P12: =+N12-M12 -> 271000 | Q12: =+P12/M12 -> 1.1106557 | S12: =+M12-'2025 Detail'!U12 -> 0 | T12: =+N12-'2026 Detail'!U12 -> 0
B13: Total AppIQ | C13: =SUM(C10:C12) -> 176292.98 | D13: =SUM(D10:D12) -> 76692 | E13: =SUM(E10:E12) -> 172277.6 | F13: =SUM(F10:F12) -> 779860.4 | H13: =SUM(H10:H12) -> 652582.8 | I13: =SUM(I10:I12) -> 923082.8 | J13: =SUM(J10:J12) -> 1079777.6 | K13: =SUM(K10:K12) -> 1487000 | M13: =SUM(M10:M12) -> 1205123 | N13: =SUM(N10:N12) -> 4142443.2 | P13: =+N13-M13 -> 2937320.2 | Q13: =+P13/M13 -> 2.4373614 | S13: =+M13-'2025 Detail'!U13 -> 0 | T13: =+N13-'2026 Detail'!U13 -> 0
B15: Total Cash Collected | C15: =+C8+C13 -> 905050.44 | D15: =+D8+D13 -> 520882.5 | E15: =+E8+E13 -> 619597.1 | F15: =+F8+F13 -> 1546775.9 | H15: =+H8+H13 -> 1272829.8 | I15: =+I8+I13 -> 1424872.8 | J15: =+J8+J13 -> 1516707.6 | K15: =+K8+K13 -> 1897000 | M15: =+M8+M13 -> 3592305.9 | N15: =+N8+N13 -> 6111410.2 | P15: =+P8+P13 -> 2519104.3 | Q15: =+P15/M15 -> 0.70124992 | S15: =+M15-'2025 Detail'!U15 -> 0 | T15: =+N15-'2026 Detail'!U15 -> 0
B17: Delivery - W2 | C17: =+'2025 Detail'!P17 -> 569426.75 | D17: =+'2025 Detail'!Q17 -> 382702.66 | E17: =+'2025 Detail'!R17 -> 374597.06 | F17: =+'2025 Detail'!S17 -> 372284.88 | H17: =+'2026 Detail'!P17 -> 557684.85 | I17: =+'2026 Detail'!Q17 -> 389015.4 | J17: =+'2026 Detail'!R17 -> 389015.4 | K17: =+'2026 Detail'!S17 -> 389015.4 | M17: =SUM(C17:F17) -> 1699011.4 | N17: =SUM(H17:K17) -> 1724731 | P17: =+M17-N17 -> -25719.694 | Q17: =+P17/M17 -> -0.015138035 | S17: =+M17-'2025 Detail'!U17 -> 0 | T17: =+N17-'2026 Detail'!U17 -> 0
