Workbook

Sheet Executive Summary
A1: HELM - 12 Month Expense Model
A3: Category | B3: Jan-26 | C3: Feb-26 | D3: Mar-26 | E3: Apr-26 | F3: May-26 | G3: Jun-26 | H3: Jul-26 | I3: Aug-26 | J3: Sep-26 | K3: Oct-26 | L3: Nov-26 | M3: Dec-26 | N3: Jan-27 | O3: Feb-27 | P3: Mar-27 | Q3: Apr-27 | R3: May-27 | S3: Jun-27 | T3: Jul-27 | U3: Aug-27 | V3: Sep-27 | W3: Oct-27 | X3: Nov-27 | Y3: Dec-27 | Z3: Q1 2026 | AA3: Q2 2026 | AB3: Q3 2026 | AC3: Q4 2026 | AD3: 2026 Total | AE3: Q1 2027 | AF3: Q2 2027 | AG3: Q3 2027 | AH3: Q4 2027 | AI3: 2027 Total | AJ3: Grand Total
A4: Team Expenses | B4: ='Headcount Detail'!E29 -> 61062.5 | C4: ='Headcount Detail'!F29 -> 67937.5 | D4: ='Headcount Detail'!G29 -> 251937.5 | E4: ='Headcount Detail'!H29 -> 201937.5 | F4: ='Headcount Detail'!I29 -> 232187.5 | G4: ='Headcount Detail'!J29 -> 222187.5 | H4: ='Headcount Detail'!K29 -> 249062.5 | I4: ='Headcount Detail'!L29 -> 239062.5 | ... AJ4: ='Headcount Detail'!AM29 -> 5350375
A5: Infrastructure & Operating | B5: ='Infrastructure Detail'!E14 -> 8500 | C5: ='Infrastructure Detail'!F14 -> 9125 | D5: ='Infrastructure Detail'!G14 -> 9804.75 | E5: ='Infrastructure Detail'!H14 -> 10544.443 | F5: ='Infrastructure Detail'!I14 -> 11349.778 | G5: ='Infrastructure Detail'!J14 -> 12227.017 | H5: ='Infrastructure Detail'!K14 -> 13183.031 | I5: ='Infrastructure Detail'!L14 -> 14225.371 | ... AJ5: ='Infrastructure Detail'!AM14 -> 573054.81
A6: Go-to-Market | B6: ='Go-to-Market Detail'!E14 -> 24500 | C6: ='Go-to-Market Detail'!F14 -> 26165 | D6: ='Go-to-Market Detail'!G14 -> 28010.65 | E6: ='Go-to-Market Detail'!H14 -> 30058.849 | F6: ='Go-to-Market Detail'!I14 -> 32334.297 | G6: ='Go-to-Market Detail'!J14 -> 34864.873 | H6: ='Go-to-Market Detail'!K14 -> 37682.049 | I6: ='Go-to-Market Detail'!L14 -> 40821.372 | ... AJ6: ='Go-to-Market Detail'!AM14 -> 1839190.4
A7: R&D / Product Development | B7: ='R&D Detail'!E10 -> 0 | C7: ='R&D Detail'!F10 -> 0 | D7: ='R&D Detail'!G10 -> 0 | E7: ='R&D Detail'!H10 -> 0 | F7: ='R&D Detail'!I10 -> 0 | G7: ='R&D Detail'!J10 -> 0 | H7: ='R&D Detail'!K10 -> 0 | I7: ='R&D Detail'!L10 -> 0 | ... AJ7: ='R&D Detail'!AM10 -> 0
A8: TOTAL EXPENSES | B8: =SUM(B4:B7) -> 94062.5 | C8: =SUM(C4:C7) -> 103227.5 | D8: =SUM(D4:D7) -> 289752.9 | E8: =SUM(E4:E7) -> 242540.79 | F8: =SUM(F4:F7) -> 275871.58 | G8: =SUM(G4:G7) -> 269279.39 | H8: =SUM(H4:H7) -> 299927.58 | I8: =SUM(I4:I7) -> 294109.24 | ... AJ8: =SUM(AJ4:AJ7) -> 7762620.2
A9: Cumulative Total Expenses | B9: =B8 -> 94062.5 | C9: =B9+C8 -> 197290 | D9: =C9+D8 -> 487042.9 | E9: =D9+E8 -> 729583.69 | F9: =E9+F8 -> 1005455.3 | G9: =F9+G8 -> 1274734.7 | H9: =G9+H8 -> 1574662.2 | I9: =H9+I8 -> 1868771.5 | J9: =I9+J8 -> 2167519.3 | ... Y9: =X9+Y8 -> 7762620.2 | Z9: =D9 -> 487042.9 | AA9: =G9 -> 1274734.7 | AB9: =J9 -> 2167519.3 | AC9: =M9 -> 3097023.3 | AD9: =AC9 -> 3097023.3 | AE9: =P9 -> 4090814.2 | AF9: =S9 -> 5173704.4 | AG9: =V9 -> 6380906.5 | AH9: =Y9 -> 7762620.2 | AI9: =AH9 -> 7762620.2 | AJ9: =Y9 -> 7762620.2

Sheet All Detail
A1: EVOLVE - All Expense Details
A3: Category / Line Item | B3: Jan-26 | C3: Feb-26 | D3: Mar-26 | E3: Apr-26 | F3: May-26 | G3: Jun-26 | H3: Jul-26 | I3: Aug-26 | J3: Sep-26 | K3: Oct-26 | L3: Nov-26 | M3: Dec-26 | N3: Jan-27 | O3: Feb-27 | P3: Mar-27 | Q3: Apr-27 | R3: May-27 | S3: Jun-27 | T3: Jul-27 | U3: Aug-27 | V3: Sep-27 | W3: Oct-27 | X3: Nov-27 | Y3: Dec-27 | Z3: Q1 2026 | AA3: Q2 2026 | AB3: Q3 2026 | AC3: Q4 2026 | AD3: 2026 Total | AE3: Q1 2027 | AF3: Q2 2027 | AG3: Q3 2027 | AH3: Q4 2027 | AI3: 2027 Total | AJ3: Grand Total
A4: TEAM EXPENSES
A5: Base Salaries
A6: =" "&'Headcount Detail'!A2 -> CEO | B6: ='Headcount Detail'!E2 -> 0 | C6: ='Headcount Detail'!F2 -> 0 | D6: ='Headcount Detail'!G2 -> 41666.667 | E6: ='Headcount Detail'!H2 -> 41666.667 | F6: ='Headcount Detail'!I2 -> 41666.667 | G6: ='Headcount Detail'!J2 -> 41666.667 | H6: ='Headcount Detail'!K2 -> 41666.667 | I6: ='Headcount Detail'!L2 -> 41666.667 | ... AJ6: ='Headcount Detail'!AM2 -> 916666.67
A7: =" "&'Headcount Detail'!A3 -> Product Lead | B7: ='Headcount Detail'!E3 -> 0 | C7: ='Headcount Detail'!F3 -> 0 | D7: ='Headcount Detail'!G3 -> 20833.333 | E7: ='Headcount Detail'!H3 -> 20833.333 | F7: ='Headcount Detail'!I3 -> 20833.333 | G7: ='Headcount Detail'!J3 -> 20833.333 | H7: ='Headcount Detail'!K3 -> 20833.333 | I7: ='Headcount Detail'!L3 -> 20833.333 | ... AJ7: ='Headcount Detail'!AM3 -> 458333.33
A8: =" "&'Headcount Detail'!A4 -> Architect #1 (Dom) | B8: ='Headcount Detail'!E4 -> 15416.667 | C8: ='Headcount Detail'!F4 -> 15416.667 | D8: ='Headcount Detail'!G4 -> 15416.667 | E8: ='Headcount Detail'!H4 -> 15416.667 | F8: ='Headcount Detail'!I4 -> 15416.667 | G8: ='Headcount Detail'!J4 -> 15416.667 | H8: ='Headcount Detail'!K4 -> 15416.667 | I8: ='Headcount Detail'!L4 -> 15416.667 | ... AJ8: ='Headcount Detail'!AM4 -> 370000
A9: =" "&'Headcount Detail'!A5 -> Engineer #1 | B9: ='Headcount Detail'!E5 -> 0 | C9: ='Headcount Detail'!F5 -> 0 | D9: ='Headcount Detail'!G5 -> 16666.667 | E9: ='Headcount Detail'!H5 -> 16666.667 | F9: ='Headcount Detail'!I5 -> 16666.667 | G9: ='Headcount Detail'!J5 -> 16666.667 | H9: ='Headcount Detail'!K5 -> 16666.667 | I9: ='Headcount Detail'!L5 -> 16666.667 | ... AJ9: ='Headcount Detail'!AM5 -> 366666.67
A10: =" "&'Headcount Detail'!A6 -> Engineer #2 | B10: ='Headcount Detail'!E6 -> 0 | C10: ='Headcount Detail'!F6 -> 0 | D10: ='Headcount Detail'!G6 -> 0 | E10: ='Headcount Detail'!H6 -> 0 | F10: ='Headcount Detail'!I6 -> 15000 | G10: ='Headcount Detail'!J6 -> 15000 | H10: ='Headcount Detail'!K6 -> 15000 | I10: ='Headcount Detail'!L6 -> 15000 | ... AJ10: ='Headcount Detail'!AM6 -> 300000
A11: =" "&'Headcount Detail'!A13 -> Engineer #3 | B11: ='Headcount Detail'!E13 -> 0 | C11: ='Headcount Detail'!F13 -> 0 | D11: ='Headcount Detail'!G13 -> 0 | E11: ='Headcount Detail'!H13 -> 0 | F11: ='Headcount Detail'!I13 -> 0 | G11: ='Headcount Detail'!J13 -> 0 | H11: ='Headcount Detail'!K13 -> 0 | I11: ='Headcount Detail'!L13 -> 0 | ... AJ11: ='Headcount Detail'!AM13 -> 0
A12: =" "&'Headcount Detail'!A7 -> Outsource Engineering | B12: ='Headcount Detail'!E7 -> 15000 | C12: ='Headcount Detail'!F7 -> 15000 | D12: ='Headcount Detail'!G7 -> 15000 | E12: ='Headcount Detail'!H7 -> 15000 | F12: ='Headcount Detail'!I7 -> 15000 | G12: ='Headcount Detail'!J7 -> 15000 | H12: ='Headcount Detail'!K7 -> 15000 | I12: ='Headcount Detail'!L7 -> 15000 | ... AJ12: ='Headcount Detail'!AM7 -> 360000
A13: =" "&'Headcount Detail'!A8 -> Sales Rep #1 | B13: ='Headcount Detail'!E8 -> 0 | C13: ='Headcount Detail'!F8 -> 0 | D13: ='Headcount Detail'!G8 -> 12500 | E13: ='Headcount Detail'!H8 -> 12500 | F13: ='Headcount Detail'!I8 -> 12500 | G13: ='Headcount Detail'!J8 -> 12500 | H13: ='Headcount Detail'!K8 -> 12500 | I13: ='Headcount Detail'!L8 -> 12500 | ... AJ13: ='Headcount Detail'!AM8 -> 275000
A14: =" "&'Headcount Detail'!A12 -> Sales Rep #2 | B14: ='Headcount Detail'!E12 -> 0 | C14: ='Headcount Detail'!F12 -> 0 | D14: ='Headcount Detail'!G12 -> 0 | E14: ='Headcount Detail'!H12 -> 0 | F14: ='Headcount Detail'!I12 -> 0 | G14: ='Headcount Detail'!J12 -> 0 | H14: ='Headcount Detail'!K12 -> 12500 | I14: ='Headcount Detail'!L12 -> 12500 | ... AJ14: ='Headcount Detail'!AM12 -> 225000
A15: =" "&'Headcount Detail'!A9 -> Marketing Lead | B15: ='Headcount Detail'!E9 -> 0 | C15: ='Headcount Detail'!F9 -> 12500 | D15: ='Headcount Detail'!G9 -> 12500 | E15: ='Headcount Detail'!H9 -> 12500 | F15: ='Headcount Detail'!I9 -> 12500 | G15: ='Headcount Detail'!J9 -> 12500 | H15: ='Headcount Detail'!K9 -> 12500 | I15: ='Headcount Detail'!L9 -> 12500 | ... AJ15: ='Headcount Detail'!AM9 -> 287500
A16: =" "&'Headcount Detail'!A10 -> Customer Success Lead | B16: ='Headcount Detail'!E10 -> 0 | C16: ='Headcount Detail'!F10 -> 0 | D16: ='Headcount Detail'!G10 -> 15000 | E16: ='Headcount Detail'!H10 -> 15000 | F16: ='Headcount Detail'!I10 -> 15000 | G16: ='Headcount Detail'!J10 -> 15000 | H16: ='Headcount Detail'!K10 -> 15000 | I16: ='Headcount Detail'!L10 -> 15000 | ... AJ16: ='Headcount Detail'!AM10 -> 330000
A17: =" "&'Headcount Detail'!A11 -> Developer Advocate | B17: ='Headcount Detail'!E11 -> 0 | C17: ='Headcount Detail'!F11 -> 0 | D17: ='Headcount Detail'!G11 -> 0 | E17: ='Headcount Detail'!H11 -> 0 | F17: ='Headcount Detail'!I11 -> 0 | G17: ='Headcount Detail'!J11 -> 0 | H17: ='Headcount Detail'!K11 -> 0 | I17: ='Headcount Detail'!L11 -> 0 | ... AJ17: ='Headcount Detail'!AM11 -> 0
A18: =" "&'Headcount Detail'!A14 -> Customer Success Manager | B18: ='Headcount Detail'!E14 -> 0 | C18: ='Headcount Detail'!F14 -> 0 | D18: ='Headcount Detail'!G14 -> 0 | E18: ='Headcount Detail'!H14 -> 0 | F18: ='Headcount Detail'!I14 -> 0 | G18: ='Headcount Detail'!J14 -> 0 | H18: ='Headcount Detail'!K14 -> 0 | I18: ='Headcount Detail'!L14 -> 0 | ... AJ18: ='Headcount Detail'!AM14 -> 0
A19: =" "&'Headcount Detail'!A15 -> Enterprise Sales Lead | B19: ='Headcount Detail'!E15 -> 0 | C19: ='Headcount Detail'!F15 -> 0 | D19: ='Headcount Detail'!G15 -> 0 | E19: ='Headcount Detail'!H15 -> 0 | F19: ='Headcount Detail'!I15 -> 0 | G19: ='Headcount Detail'!J15 -> 0 | H19: ='Headcount Detail'!K15 -> 0 | I19: ='Headcount Detail'!L15 -> 0 | ... AJ19: ='Headcount Detail'!AM15 -> 0
A20: =" "&'Headcount Detail'!A16 -> Head of Customer Success | B20: ='Headcount Detail'!E16 -> 0 | C20: ='Headcount Detail'!F16 -> 0 | D20: ='Headcount Detail'!G16 -> 0 | E20: ='Headcount Detail'!H16 -> 0 | F20: ='Headcount Detail'!I16 -> 0 | G20: ='Headcount Detail'!J16 -> 0 | H20: ='Headcount Detail'!K16 -> 0 | I20: ='Headcount Detail'!L16 -> 0 | ... AJ20: ='Headcount Detail'!AM16 -> 0
A21: =" "&'Headcount Detail'!A17 -> Senior Sales Rep | B21: ='Headcount Detail'!E17 -> 0 | C21: ='Headcount Detail'!F17 -> 0 | D21: ='Headcount Detail'!G17 -> 0 | E21: ='Headcount Detail'!H17 -> 0 | F21: ='Headcount Detail'!I17 -> 0 | G21: ='Headcount Detail'!J17 -> 0 | H21: ='Headcount Detail'!K17 -> 0 | I21: ='Headcount Detail'!L17 -> 0 | ... AJ21: ='Headcount Detail'!AM17 -> 0
A22: =" "&'Headcount Detail'!A18 -> Product Manager | B22: ='Headcount Detail'!E18 -> 0 | C22: ='Headcount Detail'!F18 -> 0 | D22: ='Headcount Detail'!G18 -> 0 | E22: ='Headcount Detail'!H18 -> 0 | F22: ='Headcount Detail'!I18 -> 0 | G22: ='Headcount Detail'!J18 -> 0 | H22: ='Headcount Detail'!K18 -> 0 | I22: ='Headcount Detail'!L18 -> 0 | ... AJ22: ='Headcount Detail'!AM18 -> 0
A23: =" "&'Headcount Detail'!A19 -> Senior Engineer | B23: ='Headcount Detail'!E19 -> 0 | C23: ='Headcount Detail'!F19 -> 0 | D23: ='Headcount Detail'!G19 -> 0 | E23: ='Headcount Detail'!H19 -> 0 | F23: ='Headcount Detail'!I19 -> 0 | G23: ='Headcount Detail'!J19 -> 0 | H23: ='Headcount Detail'!K19 -> 0 | I23: ='Headcount Detail'!L19 -> 0 | ... AJ23: ='Headcount Detail'!AM19 -> 0
A24: =" "&'Headcount Detail'!A20 -> Marketing Manager | B24: ='Headcount Detail'!E20 -> 0 | C24: ='Headcount Detail'!F20 -> 0 | D24: ='Headcount Detail'!G20 -> 0 | E24: ='Headcount Detail'!H20 -> 0 | F24: ='Headcount Detail'!I20 -> 0 | G24: ='Headcount Detail'!J20 -> 0 | H24: ='Headcount Detail'!K20 -> 0 | I24: ='Headcount Detail'!L20 -> 0 | ... AJ24: ='Headcount Detail'!AM20 -> 0
A25: =" "&'Headcount Detail'!A21 -> Customer Success Rep | B25: ='Headcount Detail'!E21 -> 0 | C25: ='Headcount Detail'!F21 -> 0 | D25: ='Headcount Detail'!G21 -> 0 | E25: ='Headcount Detail'!H21 -> 0 | F25: ='Headcount Detail'!I21 -> 0 | G25: ='Headcount Detail'!J21 -> 0 | H25: ='Headcount Detail'!K21 -> 0 | I25: ='Headcount Detail'!L21 -> 0 | ... AJ25: ='Headcount Detail'!AM21 -> 0
A26: =" "&'Headcount Detail'!A22 -> Part-time CFO | B26: ='Headcount Detail'!E22 -> 0 | C26: ='Headcount Detail'!F22 -> 0 | D26: ='Headcount Detail'!G22 -> 0 | E26: ='Headcount Detail'!H22 -> 0 | F26: ='Headcount Detail'!I22 -> 0 | G26: ='Headcount Detail'!J22 -> 0 | H26: ='Headcount Detail'!K22 -> 0 | I26: ='Headcount Detail'!L22 -> 0 | ... AJ26: ='Headcount Detail'!AM22 -> 0
A27: =" "&'Headcount Detail'!A23 -> Part-time Legal Counsel | B27: ='Headcount Detail'!E23 -> 0 | C27: ='Headcount Detail'!F23 -> 0 | D27: ='Headcount Detail'!G23 -> 0 | E27: ='Headcount Detail'!H23 -> 0 | F27: ='Headcount Detail'!I23 -> 0 | G27: ='Headcount Detail'!J23 -> 0 | H27: ='Headcount Detail'!K23 -> 0 | I27: ='Headcount Detail'!L23 -> 0 | ... AJ27: ='Headcount Detail'!AM23 -> 0
A28: =" "&'Headcount Detail'!A24 -> Technical Advisors (3) | B28: ='Headcount Detail'!E24 -> 0 | C28: ='Headcount Detail'!F24 -> 0 | D28: ='Headcount Detail'!G24 -> 0 | E28: ='Headcount Detail'!H24 -> 0 | F28: ='Headcount Detail'!I24 -> 0 | G28: ='Headcount Detail'!J24 -> 0 | H28: ='Headcount Detail'!K24 -> 0 | I28: ='Headcount Detail'!L24 -> 0 | ... AJ28: ='Headcount Detail'!AM24 -> 0
A29: =" "&'Headcount Detail'!A25 -> Industry Advisors (2) | B29: ='Headcount Detail'!E25 -> 0 | C29: ='Headcount Detail'!F25 -> 0 | D29: ='Headcount Detail'!G25 -> 0 | E29: ='Headcount Detail'!H25 -> 0 | F29: ='Headcount Detail'!I25 -> 0 | G29: ='Headcount Detail'!J25 -> 0 | H29: ='Headcount Detail'!K25 -> 0 | I29: ='Headcount Detail'!L25 -> 0 | ... AJ29: ='Headcount Detail'!AM25 -> 0
A30: Subtotal: Base Salaries | B30: ='Headcount Detail'!E26 -> 30416.667 | C30: ='Headcount Detail'!F26 -> 42916.667 | D30: ='Headcount Detail'!G26 -> 149583.33 | E30: ='Headcount Detail'!H26 -> 149583.33 | F30: ='Headcount Detail'!I26 -> 164583.33 | G30: ='Headcount Detail'!J26 -> 164583.33 | H30: ='Headcount Detail'!K26 -> 177083.33 | I30: ='Headcount Detail'!L26 -> 177083.33 | ... AJ30: ='Headcount Detail'!AM26 -> 3889166.7
A31: Benefits & Taxes (35%) | B31: ='Headcount Detail'!E27 -> 10645.833 | C31: ='Headcount Detail'!F27 -> 15020.833 | D31: ='Headcount Detail'!G27 -> 52354.167 | E31: ='Headcount Detail'!H27 -> 52354.167 | F31: ='Headcount Detail'!I27 -> 57604.167 | G31: ='Headcount Detail'!J27 -> 57604.167 | H31: ='Headcount Detail'!K27 -> 61979.167 | I31: ='Headcount Detail'!L27 -> 61979.167 | ... AJ31: ='Headcount Detail'!AM27 -> 1361208.3
A32: Recruiting Expenses | B32: ='Headcount Detail'!E28 -> 20000 | C32: ='Headcount Detail'!F28 -> 10000 | D32: ='Headcount Detail'!G28 -> 50000 | E32: ='Headcount Detail'!H28 -> 0 | F32: ='Headcount Detail'!I28 -> 10000 | G32: ='Headcount Detail'!J28 -> 0 | H32: ='Headcount Detail'!K28 -> 10000 | I32: ='Headcount Detail'!L28 -> 0 | ... AJ32: ='Headcount Detail'!AM28 -> 100000
A33: TOTAL TEAM EXPENSES | B33: ='Headcount Detail'!E29 -> 61062.5 | C33: ='Headcount Detail'!F29 -> 67937.5 | D33: ='Headcount Detail'!G29 -> 251937.5 | E33: ='Headcount Detail'!H29 -> 201937.5 | F33: ='Headcount Detail'!I29 -> 232187.5 | G33: ='Headcount Detail'!J29 -> 222187.5 | H33: ='Headcount Detail'!K29 -> 249062.5 | I33: ='Headcount Detail'!L29 -> 239062.5 | ... AJ33: ='Headcount Detail'!AM29 -> 5350375
A34: Cumulative Team Expenses | B34: ='Headcount Detail'!E30 -> 61062.5 | C34: ='Headcount Detail'!F30 -> 129000 | D34: ='Headcount Detail'!G30 -> 380937.5 | E34: ='Headcount Detail'!H30 -> 582875 | F34: ='Headcount Detail'!I30 -> 815062.5 | G34: ='Headcount Detail'!J30 -> 1037250 | H34: ='Headcount Detail'!K30 -> 1286312.5 | I34: ='Headcount Detail'!L30 -> 1525375 | ... AJ34: ='Headcount Detail'!AM30 -> 5350375
A36: INFRASTRUCTURE & OPERATING
A37: =" "&'Infrastructure Detail'!A4 -> Cloud Infrastructure (AWS/GCP) | B37: ='Infrastructure Detail'!E4 -> 5000 | C37: ='Infrastructure Detail'!F4 -> 5500 | D37: ='Infrastructure Detail'!G4 -> 6050 | E37: ='Infrastructure Detail'!H4 -> 6655 | F37: ='Infrastructure Detail'!I4 -> 7320.5 | G37: ='Infrastructure Detail'!J4 -> 8052.55 | H37: ='Infrastructure Detail'!K4 -> 8857.805 | I37: ='Infrastructure Detail'!L4 -> 9743.5855 | ... AJ37: ='Infrastructure Detail'!AM4 -> 442486.63
A38: =" "&'Infrastructure Detail'!A5 -> Edge LLM Development Tools | B38: ='Infrastructure Detail'!E5 -> 0 | C38: ='Infrastructure Detail'!F5 -> 0 | D38: ='Infrastructure Detail'!G5 -> 0 | E38: ='Infrastructure Detail'!H5 -> 0 | F38: ='Infrastructure Detail'!I5 -> 0 | G38: ='Infrastructure Detail'!J5 -> 0 | H38: ='Infrastructure Detail'!K5 -> 0 | I38: ='Infrastructure Detail'!L5 -> 0 | ... AJ38: ='Infrastructure Detail'!AM5 -> 0
A39: =" "&'Infrastructure Detail'!A6 -> Development Tools & Software | B39: ='Infrastructure Detail'!E6 -> 2500 | C39: ='Infrastructure Detail'!F6 -> 2575 | D39: ='Infrastructure Detail'!G6 -> 2652.25 | E39: ='Infrastructure Detail'!H6 -> 2731.8175 | F39: ='Infrastructure Detail'!I6 -> 2813.772 | G39: ='Infrastructure Detail'!J6 -> 2898.1852 | H39: ='Infrastructure Detail'!K6 -> 2985.1307 | I39: ='Infrastructure Detail'!L6 -> 3074.6847 | ... AJ39: ='Infrastructure Detail'!AM6 -> 86066.176
A40: =" "&'Infrastructure Detail'!A7 -> Security & Compliance Tools | B40: ='Infrastructure Detail'!E7 -> 0 | C40: ='Infrastructure Detail'!F7 -> 0 | D40: ='Infrastructure Detail'!G7 -> 0 | E40: ='Infrastructure Detail'!H7 -> 0 | F40: ='Infrastructure Detail'!I7 -> 0 | G40: ='Infrastructure Detail'!J7 -> 0 | H40: ='Infrastructure Detail'!K7 -> 0 | I40: ='Infrastructure Detail'!L7 -> 0 | ... AJ40: ='Infrastructure Detail'!AM7 -> 0
A41: =" "&'Infrastructure Detail'!A8 -> Data Storage & Processing | B41: ='Infrastructure Detail'!E8 -> 0 | C41: ='Infrastructure Detail'!F8 -> 0 | D41: ='Infrastructure Detail'!G8 -> 0 | E41: ='Infrastructure Detail'!H8 -> 0 | F41: ='Infrastructure Detail'!I8 -> 0 | G41: ='Infrastructure Detail'!J8 -> 0 | H41: ='Infrastructure Detail'!K8 -> 0 | I41: ='Infrastructure Detail'!L8 -> 0 | ... AJ41: ='Infrastructure Detail'!AM8 -> 0
A42: =" "&'Infrastructure Detail'!A9 -> DevOps & Monitoring | B42: ='Infrastructure Detail'!E9 -> 0 | C42: ='Infrastructure Detail'!F9 -> 0 | D42: ='Infrastructure Detail'!G9 -> 0 | E42: ='Infrastructure Detail'!H9 -> 0 | F42: ='Infrastructure Detail'!I9 -> 0 | G42: ='Infrastructure Detail'!J9 -> 0 | H42: ='Infrastructure Detail'!K9 -> 0 | I42: ='Infrastructure Detail'!L9 -> 0 | ... AJ42: ='Infrastructure Detail'!AM9 -> 0
...

Sheet Headcount Detail
A1: Role | B1: Annual Salary | C1: Start Month | D1: Monthly Salary | E1: Jan-26 | F1: Feb-26 | G1: Mar-26 | H1: Apr-26 | I1: May-26 | J1: Jun-26 | K1: Jul-26 | L1: Aug-26 | M1: Sep-26 | N1: Oct-26 | O1: Nov-26 | P1: Dec-26 | Q1: Jan-27 | R1: Feb-27 | S1: Mar-27 | T1: Apr-27 | U1: May-27 | V1: Jun-27 | W1: Jul-27 | X1: Aug-27 | Y1: Sep-27 | Z1: Oct-27 | AA1: Nov-27 | AB1: Dec-27 | AC1: Q1 2026 | AD1: Q2 2026 | AE1: Q3 2026 | AF1: Q4 2026 | AG1: 2026 Total | AH1: Q1 2027 | AI1: Q2 2027 | AJ1: Q3 2027 | AK1: Q4 2027 | AL1: 2027 Total | AM1: Grand Total
A2: CEO | B2: 500000 | C2: 3 | D2: =B2/12 -> 41666.667 | E2: =IF(1>=C2,D2,0) -> 0 | F2: =IF(2>=C2,D2,0) -> 0 | G2: =IF(3>=C2,D2,0) -> 41666.667 | H2: =IF(4>=C2,D2,0) -> 41666.667 | I2: =IF(5>=C2,D2,0) -> 41666.667 | J2: =IF(6>=C2,D2,0) -> 41666.667 | K2: =IF(7>=C2,D2,0) -> 41666.667 | L2: =IF(8>=C2,D2,0) -> 41666.667 | M2: =IF(9>=C2,D2,0) -> 41666.667 | N2: =IF(10>=C2,D2,0) -> 41666.667 | O2: =IF(11>=C2,D2,0) -> 41666.667 | P2: =IF(12>=C2,D2,0) -> 41666.667 | Q2: =IF(13>=C2,D2,0) -> 41666.667 | R2: =IF(14>=C2,D2,0) -> 41666.667 | S2: =IF(15>=C2,D2,0) -> 41666.667 | T2: =IF(16>=C2,D2,0) -> 41666.667 | U2: =IF(17>=C2,D2,0) -> 41666.667 | V2: =IF(18>=C2,D2,0) -> 41666.667 | W2: =IF(19>=C2,D2,0) -> 41666.667 | X2: =IF(20>=C2,D2,0) -> 41666.667 | Y2: =IF(21>=C2,D2,0) -> 41666.667 | Z2: =IF(22>=C2,D2,0) -> 41666.667 | AA2: =IF(23>=C2,D2,0) -> 41666.667 | AB2: =IF(24>=C2,D2,0) -> 41666.667 | AC2: =SUM(E2:G2) -> 41666.667 | AD2: =SUM(H2:J2) -> 125000 | AE2: =SUM(K2:M2) -> 125000 | AF2: =SUM(N2:P2) -> 125000 | AG2: =SUM(AC2:AF2) -> 416666.67 | AH2: =SUM(Q2:S2) -> 125000 | AI2: =SUM(T2:V2) -> 125000 | AJ2: =SUM(W2:Y2) -> 125000 | AK2: =SUM(Z2:AB2) -> 125000 | AL2: =SUM(AH2:AK2) -> 500000 | AM2: =AG2+AL2 -> 916666.67
A3: Product Lead | B3: 250000 | C3: 3 | D3: =B3/12 -> 20833.333 | E3: =IF(1>=C3,D3,0) -> 0 | F3: =IF(2>=C3,D3,0) -> 0 | G3: =IF(3>=C3,D3,0) -> 20833.333 | H3: =IF(4>=C3,D3,0) -> 20833.333 | I3: =IF(5>=C3,D3,0) -> 20833.333 | J3: =IF(6>=C3,D3,0) -> 20833.333 | K3: =IF(7>=C3,D3,0) -> 20833.333 | L3: =IF(8>=C3,D3,0) -> 20833.333 | M3: =IF(9>=C3,D3,0) -> 20833.333 | N3: =IF(10>=C3,D3,0) -> 20833.333 | O3: =IF(11>=C3,D3,0) -> 20833.333 | P3: =IF(12>=C3,D3,0) -> 20833.333 | Q3: =IF(13>=C3,D3,0) -> 20833.333 | R3: =IF(14>=C3,D3,0) -> 20833.333 | S3: =IF(15>=C3,D3,0) -> 20833.333 | T3: =IF(16>=C3,D3,0) -> 20833.333 | U3: =IF(17>=C3,D3,0) -> 20833.333 | V3: =IF(18>=C3,D3,0) -> 20833.333 | W3: =IF(19>=C3,D3,0) -> 20833.333 | X3: =IF(20>=C3,D3,0) -> 20833.333 | Y3: =IF(21>=C3,D3,0) -> 20833.333 | Z3: =IF(22>=C3,D3,0) -> 20833.333 | AA3: =IF(23>=C3,D3,0) -> 20833.333 | AB3: =IF(24>=C3,D3,0) -> 20833.333 | AC3: =SUM(E3:G3) -> 20833.333 | AD3: =SUM(H3:J3) -> 62500 | AE3: =SUM(K3:M3) -> 62500 | AF3: =SUM(N3:P3) -> 62500 | AG3: =SUM(AC3:AF3) -> 208333.33 | AH3: =SUM(Q3:S3) -> 62500 | AI3: =SUM(T3:V3) -> 62500 | AJ3: =SUM(W3:Y3) -> 62500 | AK3: =SUM(Z3:AB3) -> 62500 | AL3: =SUM(AH3:AK3) -> 250000 | AM3: =AG3+AL3 -> 458333.33
A4: Architect #1 (Dom) | B4: 185000 | C4: 1 | D4: =B4/12 -> 15416.667 | E4: =IF(1>=C4,D4,0) -> 15416.667 | F4: =IF(2>=C4,D4,0) -> 15416.667 | G4: =IF(3>=C4,D4,0) -> 15416.667 | H4: =IF(4>=C4,D4,0) -> 15416.667 | I4: =IF(5>=C4,D4,0) -> 15416.667 | J4: =IF(6>=C4,D4,0) -> 15416.667 | K4: =IF(7>=C4,D4,0) -> 15416.667 | L4: =IF(8>=C4,D4,0) -> 15416.667 | M4: =IF(9>=C4,D4,0) -> 15416.667 | N4: =IF(10>=C4,D4,0) -> 15416.667 | O4: =IF(11>=C4,D4,0) -> 15416.667 | P4: =IF(12>=C4,D4,0) -> 15416.667 | Q4: =IF(13>=C4,D4,0) -> 15416.667 | R4: =IF(14>=C4,D4,0) -> 15416.667 | S4: =IF(15>=C4,D4,0) -> 15416.667 | T4: =IF(16>=C4,D4,0) -> 15416.667 | U4: =IF(17>=C4,D4,0) -> 15416.667 | V4: =IF(18>=C4,D4,0) -> 15416.667 | W4: =IF(19>=C4,D4,0) -> 15416.667 | X4: =IF(20>=C4,D4,0) -> 15416.667 | Y4: =IF(21>=C4,D4,0) -> 15416.667 | Z4: =IF(22>=C4,D4,0) -> 15416.667 | AA4: =IF(23>=C4,D4,0) -> 15416.667 | AB4: =IF(24>=C4,D4,0) -> 15416.667 | AC4: =SUM(E4:G4) -> 46250 | AD4: =SUM(H4:J4) -> 46250 | AE4: =SUM(K4:M4) -> 46250 | AF4: =SUM(N4:P4) -> 46250 | AG4: =SUM(AC4:AF4) -> 185000 | AH4: =SUM(Q4:S4) -> 46250 | AI4: =SUM(T4:V4) -> 46250 | AJ4: =SUM(W4:Y4) -> 46250 | AK4: =SUM(Z4:AB4) -> 46250 | AL4: =SUM(AH4:AK4) -> 185000 | AM4: =AG4+AL4 -> 370000
A5: Engineer #1 | B5: 200000 | C5: 3 | D5: =B5/12 -> 16666.667 | E5: =IF(1>=C5,D5,0) -> 0 | F5: =IF(2>=C5,D5,0) -> 0 | G5: =IF(3>=C5,D5,0) -> 16666.667 | H5: =IF(4>=C5,D5,0) -> 16666.667 | I5: =IF(5>=C5,D5,0) -> 16666.667 | J5: =IF(6>=C5,D5,0) -> 16666.667 | K5: =IF(7>=C5,D5,0) -> 16666.667 | L5: =IF(8>=C5,D5,0) -> 16666.667 | M5: =IF(9>=C5,D5,0) -> 16666.667 | N5: =IF(10>=C5,D5,0) -> 16666.667 | O5: =IF(11>=C5,D5,0) -> 16666.667 | P5: =IF(12>=C5,D5,0) -> 16666.667 | Q5: =IF(13>=C5,D5,0) -> 16666.667 | R5: =IF(14>=C5,D5,0) -> 16666.667 | S5: =IF(15>=C5,D5,0) -> 16666.667 | T5: =IF(16>=C5,D5,0) -> 16666.667 | U5: =IF(17>=C5,D5,0) -> 16666.667 | V5: =IF(18>=C5,D5,0) -> 16666.667 | W5: =IF(19>=C5,D5,0) -> 16666.667 | X5: =IF(20>=C5,D5,0) -> 16666.667 | Y5: =IF(21>=C5,D5,0) -> 16666.667 | Z5: =IF(22>=C5,D5,0) -> 16666.667 | AA5: =IF(23>=C5,D5,0) -> 16666.667 | AB5: =IF(24>=C5,D5,0) -> 16666.667 | AC5: =SUM(E5:G5) -> 16666.667 | AD5: =SUM(H5:J5) -> 50000 | AE5: =SUM(K5:M5) -> 50000 | AF5: =SUM(N5:P5) -> 50000 | AG5: =SUM(AC5:AF5) -> 166666.67 | AH5: =SUM(Q5:S5) -> 50000 | AI5: =SUM(T5:V5) -> 50000 | AJ5: =SUM(W5:Y5) -> 50000 | AK5: =SUM(Z5:AB5) -> 50000 | AL5: =SUM(AH5:AK5) -> 200000 | AM5: =AG5+AL5 -> 366666.67
A6: Engineer #2 | B6: 180000 | C6: 5 | D6: =B6/12 -> 15000 | E6: =IF(1>=C6,D6,0) -> 0 | F6: =IF(2>=C6,D6,0) -> 0 | G6: =IF(3>=C6,D6,0) -> 0 | H6: =IF(4>=C6,D6,0) -> 0 | I6: =IF(5>=C6,D6,0) -> 15000 | J6: =IF(6>=C6,D6,0) -> 15000 | K6: =IF(7>=C6,D6,0) -> 15000 | L6: =IF(8>=C6,D6,0) -> 15000 | M6: =IF(9>=C6,D6,0) -> 15000 | N6: =IF(10>=C6,D6,0) -> 15000 | O6: =IF(11>=C6,D6,0) -> 15000 | P6: =IF(12>=C6,D6,0) -> 15000 | Q6: =IF(13>=C6,D6,0) -> 15000 | R6: =IF(14>=C6,D6,0) -> 15000 | S6: =IF(15>=C6,D6,0) -> 15000 | T6: =IF(16>=C6,D6,0) -> 15000 | U6: =IF(17>=C6,D6,0) -> 15000 | V6: =IF(18>=C6,D6,0) -> 15000 | W6: =IF(19>=C6,D6,0) -> 15000 | X6: =IF(20>=C6,D6,0) -> 15000 | Y6: =IF(21>=C6,D6,0) -> 15000 | Z6: =IF(22>=C6,D6,0) -> 15000 | AA6: =IF(23>=C6,D6,0) -> 15000 | AB6: =IF(24>=C6,D6,0) -> 15000 | AC6: =SUM(E6:G6) -> 0 | AD6: =SUM(H6:J6) -> 30000 | AE6: =SUM(K6:M6) -> 45000 | AF6: =SUM(N6:P6) -> 45000 | AG6: =SUM(AC6:AF6) -> 120000 | AH6: =SUM(Q6:S6) -> 45000 | AI6: =SUM(T6:V6) -> 45000 | AJ6: =SUM(W6:Y6) -> 45000 | AK6: =SUM(Z6:AB6) -> 45000 | AL6: =SUM(AH6:AK6) -> 180000 | AM6: =AG6+AL6 -> 300000
A7: Outsource Engineering | B7: =15*12000 -> 180000 | C7: 1 | D7: =B7/12 -> 15000 | E7: =IF(1>=C7,D7,0) -> 15000 | F7: =IF(2>=C7,D7,0) -> 15000 | G7: =IF(3>=C7,D7,0) -> 15000 | H7: =IF(4>=C7,D7,0) -> 15000 | I7: =IF(5>=C7,D7,0) -> 15000 | J7: =IF(6>=C7,D7,0) -> 15000 | K7: =IF(7>=C7,D7,0) -> 15000 | L7: =IF(8>=C7,D7,0) -> 15000 | M7: =IF(9>=C7,D7,0) -> 15000 | N7: =IF(10>=C7,D7,0) -> 15000 | O7: =IF(11>=C7,D7,0) -> 15000 | P7: =IF(12>=C7,D7,0) -> 15000 | Q7: =IF(13>=C7,D7,0) -> 15000 | R7: =IF(14>=C7,D7,0) -> 15000 | S7: =IF(15>=C7,D7,0) -> 15000 | T7: =IF(16>=C7,D7,0) -> 15000 | U7: =IF(17>=C7,D7,0) -> 15000 | V7: =IF(18>=C7,D7,0) -> 15000 | W7: =IF(19>=C7,D7,0) -> 15000 | X7: =IF(20>=C7,D7,0) -> 15000 | Y7: =IF(21>=C7,D7,0) -> 15000 | Z7: =IF(22>=C7,D7,0) -> 15000 | AA7: =IF(23>=C7,D7,0) -> 15000 | AB7: =IF(24>=C7,D7,0) -> 15000 | AC7: =SUM(E7:G7) -> 45000 | AD7: =SUM(H7:J7) -> 45000 | AE7: =SUM(K7:M7) -> 45000 | AF7: =SUM(N7:P7) -> 45000 | AG7: =SUM(AC7:AF7) -> 180000 | AH7: =SUM(Q7:S7) -> 45000 | AI7: =SUM(T7:V7) -> 45000 | AJ7: =SUM(W7:Y7) -> 45000 | AK7: =SUM(Z7:AB7) -> 45000 | AL7: =SUM(AH7:AK7) -> 180000 | AM7: =AG7+AL7 -> 360000
A8: Sales Rep #1 | B8: 150000 | C8: 3 | D8: =B8/12 -> 12500 | E8: =IF(1>=C8,D8,0) -> 0 | F8: =IF(2>=C8,D8,0) -> 0 | G8: =IF(3>=C8,D8,0) -> 12500 | H8: =IF(4>=C8,D8,0) -> 12500 | I8: =IF(5>=C8,D8,0) -> 12500 | J8: =IF(6>=C8,D8,0) -> 12500 | K8: =IF(7>=C8,D8,0) -> 12500 | L8: =IF(8>=C8,D8,0) -> 12500 | M8: =IF(9>=C8,D8,0) -> 12500 | N8: =IF(10>=C8,D8,0) -> 12500 | O8: =IF(11>=C8,D8,0) -> 12500 | P8: =IF(12>=C8,D8,0) -> 12500 | Q8: =IF(13>=C8,D8,0) -> 12500 | R8: =IF(14>=C8,D8,0) -> 12500 | S8: =IF(15>=C8,D8,0) -> 12500 | T8: =IF(16>=C8,D8,0) -> 12500 | U8: =IF(17>=C8,D8,0) -> 12500 | V8: =IF(18>=C8,D8,0) -> 12500 | W8: =IF(19>=C8,D8,0) -> 12500 | X8: =IF(20>=C8,D8,0) -> 12500 | Y8: =IF(21>=C8,D8,0) -> 12500 | Z8: =IF(22>=C8,D8,0) -> 12500 | AA8: =IF(23>=C8,D8,0) -> 12500 | AB8: =IF(24>=C8,D8,0) -> 12500 | AC8: =SUM(E8:G8) -> 12500 | AD8: =SUM(H8:J8) -> 37500 | AE8: =SUM(K8:M8) -> 37500 | AF8: =SUM(N8:P8) -> 37500 | AG8: =SUM(AC8:AF8) -> 125000 | AH8: =SUM(Q8:S8) -> 37500 | AI8: =SUM(T8:V8) -> 37500 | AJ8: =SUM(W8:Y8) -> 37500 | AK8: =SUM(Z8:AB8) -> 37500 | AL8: =SUM(AH8:AK8) -> 150000 | AM8: =AG8+AL8 -> 275000
A9: Marketing Lead | B9: 150000 | C9: 2 | D9: =B9/12 -> 12500 | E9: =IF(1>=C9,D9,0) -> 0 | F9: =IF(2>=C9,D9,0) -> 12500 | G9: =IF(3>=C9,D9,0) -> 12500 | H9: =IF(4>=C9,D9,0) -> 12500 | I9: =IF(5>=C9,D9,0) -> 12500 | J9: =IF(6>=C9,D9,0) -> 12500 | K9: =IF(7>=C9,D9,0) -> 12500 | L9: =IF(8>=C9,D9,0) -> 12500 | M9: =IF(9>=C9,D9,0) -> 12500 | N9: =IF(10>=C9,D9,0) -> 12500 | O9: =IF(11>=C9,D9,0) -> 12500 | P9: =IF(12>=C9,D9,0) -> 12500 | Q9: =IF(13>=C9,D9,0) -> 12500 | R9: =IF(14>=C9,D9,0) -> 12500 | S9: =IF(15>=C9,D9,0) -> 12500 | T9: =IF(16>=C9,D9,0) -> 12500 | U9: =IF(17>=C9,D9,0) -> 12500 | V9: =IF(18>=C9,D9,0) -> 12500 | W9: =IF(19>=C9,D9,0) -> 12500 | X9: =IF(20>=C9,D9,0) -> 12500 | Y9: =IF(21>=C9,D9,0) -> 12500 | Z9: =IF(22>=C9,D9,0) -> 12500 | AA9: =IF(23>=C9,D9,0) -> 12500 | AB9: =IF(24>=C9,D9,0) -> 12500 | AC9: =SUM(E9:G9) -> 25000 | AD9: =SUM(H9:J9) -> 37500 | AE9: =SUM(K9:M9) -> 37500 | AF9: =SUM(N9:P9) -> 37500 | AG9: =SUM(AC9:AF9) -> 137500 | AH9: =SUM(Q9:S9) -> 37500 | AI9: =SUM(T9:V9) -> 37500 | AJ9: =SUM(W9:Y9) -> 37500 | AK9: =SUM(Z9:AB9) -> 37500 | AL9: =SUM(AH9:AK9) -> 150000 | AM9: =AG9+AL9 -> 287500
A10: Customer Success Lead | B10: 180000 | C10: 3 | D10: =B10/12 -> 15000 | E10: =IF(1>=C10,D10,0) -> 0 | F10: =IF(2>=C10,D10,0) -> 0 | G10: =IF(3>=C10,D10,0) -> 15000 | H10: =IF(4>=C10,D10,0) -> 15000 | I10: =IF(5>=C10,D10,0) -> 15000 | J10: =IF(6>=C10,D10,0) -> 15000 | K10: =IF(7>=C10,D10,0) -> 15000 | L10: =IF(8>=C10,D10,0) -> 15000 | M10: =IF(9>=C10,D10,0) -> 15000 | N10: =IF(10>=C10,D10,0) -> 15000 | O10: =IF(11>=C10,D10,0) -> 15000 | P10: =IF(12>=C10,D10,0) -> 15000 | Q10: =IF(13>=C10,D10,0) -> 15000 | R10: =IF(14>=C10,D10,0) -> 15000 | S10: =IF(15>=C10,D10,0) -> 15000 | T10: =IF(16>=C10,D10,0) -> 15000 | U10: =IF(17>=C10,D10,0) -> 15000 | V10: =IF(18>=C10,D10,0) -> 15000 | W10: =IF(19>=C10,D10,0) -> 15000 | X10: =IF(20>=C10,D10,0) -> 15000 | Y10: =IF(21>=C10,D10,0) -> 15000 | Z10: =IF(22>=C10,D10,0) -> 15000 | AA10: =IF(23>=C10,D10,0) -> 15000 | AB10: =IF(24>=C10,D10,0) -> 15000 | AC10: =SUM(E10:G10) -> 15000 | AD10: =SUM(H10:J10) -> 45000 | AE10: =SUM(K10:M10) -> 45000 | AF10: =SUM(N10:P10) -> 45000 | AG10: =SUM(AC10:AF10) -> 150000 | AH10: =SUM(Q10:S10) -> 45000 | AI10: =SUM(T10:V10) -> 45000 | AJ10: =SUM(W10:Y10) -> 45000 | AK10: =SUM(Z10:AB10) -> 45000 | AL10: =SUM(AH10:AK10) -> 180000 | AM10: =AG10+AL10 -> 330000
A11: Developer Advocate | B11: 140000 | C11: 25 | D11: =B11/12 -> 11666.667 | E11: =IF(1>=C11,D11,0) -> 0 | F11: =IF(2>=C11,D11,0) -> 0 | G11: =IF(3>=C11,D11,0) -> 0 | H11: =IF(4>=C11,D11,0) -> 0 | I11: =IF(5>=C11,D11,0) -> 0 | J11: =IF(6>=C11,D11,0) -> 0 | K11: =IF(7>=C11,D11,0) -> 0 | L11: =IF(8>=C11,D11,0) -> 0 | M11: =IF(9>=C11,D11,0) -> 0 | N11: =IF(10>=C11,D11,0) -> 0 | O11: =IF(11>=C11,D11,0) -> 0 | P11: =IF(12>=C11,D11,0) -> 0 | Q11: =IF(13>=C11,D11,0) -> 0 | R11: =IF(14>=C11,D11,0) -> 0 | S11: =IF(15>=C11,D11,0) -> 0 | T11: =IF(16>=C11,D11,0) -> 0 | U11: =IF(17>=C11,D11,0) -> 0 | V11: =IF(18>=C11,D11,0) -> 0 | W11: =IF(19>=C11,D11,0) -> 0 | X11: =IF(20>=C11,D11,0) -> 0 | Y11: =IF(21>=C11,D11,0) -> 0 | Z11: =IF(22>=C11,D11,0) -> 0 | AA11: =IF(23>=C11,D11,0) -> 0 | AB11: =IF(24>=C11,D11,0) -> 0 | AC11: =SUM(E11:G11) -> 0 | AD11: =SUM(H11:J11) -> 0 | AE11: =SUM(K11:M11) -> 0 | AF11: =SUM(N11:P11) -> 0 | AG11: =SUM(AC11:AF11) -> 0 | AH11: =SUM(Q11:S11) -> 0 | AI11: =SUM(T11:V11) -> 0 | AJ11: =SUM(W11:Y11) -> 0 | AK11: =SUM(Z11:AB11) -> 0 | AL11: =SUM(AH11:AK11) -> 0 | AM11: =AG11+AL11 -> 0
A12: Sales Rep #2 | B12: 150000 | C12: 7 | D12: =B12/12 -> 12500 | E12: =IF(1>=C12,D12,0) -> 0 | F12: =IF(2>=C12,D12,0) -> 0 | G12: =IF(3>=C12,D12,0) -> 0 | H12: =IF(4>=C12,D12,0) -> 0 | I12: =IF(5>=C12,D12,0) -> 0 | J12: =IF(6>=C12,D12,0) -> 0 | K12: =IF(7>=C12,D12,0) -> 12500 | L12: =IF(8>=C12,D12,0) -> 12500 | M12: =IF(9>=C12,D12,0) -> 12500 | N12: =IF(10>=C12,D12,0) -> 12500 | O12: =IF(11>=C12,D12,0) -> 12500 | P12: =IF(12>=C12,D12,0) -> 12500 | Q12: =IF(13>=C12,D12,0) -> 12500 | R12: =IF(14>=C12,D12,0) -> 12500 | S12: =IF(15>=C12,D12,0) -> 12500 | T12: =IF(16>=C12,D12,0) -> 12500 | U12: =IF(17>=C12,D12,0) -> 12500 | V12: =IF(18>=C12,D12,0) -> 12500 | W12: =IF(19>=C12,D12,0) -> 12500 | X12: =IF(20>=C12,D12,0) -> 12500 | Y12: =IF(21>=C12,D12,0) -> 12500 | Z12: =IF(22>=C12,D12,0) -> 12500 | AA12: =IF(23>=C12,D12,0) -> 12500 | AB12: =IF(24>=C12,D12,0) -> 12500 | AC12: =SUM(E12:G12) -> 0 | AD12: =SUM(H12:J12) -> 0 | AE12: =SUM(K12:M12) -> 37500 | AF12: =SUM(N12:P12) -> 37500 | AG12: =SUM(AC12:AF12) -> 75000 | AH12: =SUM(Q12:S12) -> 37500 | AI12: =SUM(T12:V12) -> 37500 | AJ12: =SUM(W12:Y12) -> 37500 | AK12: =SUM(Z12:AB12) -> 37500 | AL12: =SUM(AH12:AK12) -> 150000 | AM12: =AG12+AL12 -> 225000
A13: Engineer #3 | B13: 180000 | C13: 25 | D13: =B13/12 -> 15000 | E13: =IF(1>=C13,D13,0) -> 0 | F13: =IF(2>=C13,D13,0) -> 0 | G13: =IF(3>=C13,D13,0) -> 0 | H13: =IF(4>=C13,D13,0) -> 0 | I13: =IF(5>=C13,D13,0) -> 0 | J13: =IF(6>=C13,D13,0) -> 0 | K13: =IF(7>=C13,D13,0) -> 0 | L13: =IF(8>=C13,D13,0) -> 0 | M13: =IF(9>=C13,D13,0) -> 0 | N13: =IF(10>=C13,D13,0) -> 0 | O13: =IF(11>=C13,D13,0) -> 0 | P13: =IF(12>=C13,D13,0) -> 0 | Q13: =IF(13>=C13,D13,0) -> 0 | R13: =IF(14>=C13,D13,0) -> 0 | S13: =IF(15>=C13,D13,0) -> 0 | T13: =IF(16>=C13,D13,0) -> 0 | U13: =IF(17>=C13,D13,0) -> 0 | V13: =IF(18>=C13,D13,0) -> 0 | W13: =IF(19>=C13,D13,0) -> 0 | X13: =IF(20>=C13,D13,0) -> 0 | Y13: =IF(21>=C13,D13,0) -> 0 | Z13: =IF(22>=C13,D13,0) -> 0 | AA13: =IF(23>=C13,D13,0) -> 0 | AB13: =IF(24>=C13,D13,0) -> 0 | AC13: =SUM(E13:G13) -> 0 | AD13: =SUM(H13:J13) -> 0 | AE13: =SUM(K13:M13) -> 0 | AF13: =SUM(N13:P13) -> 0 | AG13: =SUM(AC13:AF13) -> 0 | AH13: =SUM(Q13:S13) -> 0 | AI13: =SUM(T13:V13) -> 0 | AJ13: =SUM(W13:Y13) -> 0 | AK13: =SUM(Z13:AB13) -> 0 | AL13: =SUM(AH13:AK13) -> 0 | AM13: =AG13+AL13 -> 0
A14: Customer Success Manager | B14: 120000 | C14: 25 | D14: =B14/12 -> 10000 | E14: =IF(1>=C14,D14,0) -> 0 | F14: =IF(2>=C14,D14,0) -> 0 | G14: =IF(3>=C14,D14,0) -> 0 | H14: =IF(4>=C14,D14,0) -> 0 | I14: =IF(5>=C14,D14,0) -> 0 | J14: =IF(6>=C14,D14,0) -> 0 | K14: =IF(7>=C14,D14,0) -> 0 | L14: =IF(8>=C14,D14,0) -> 0 | M14: =IF(9>=C14,D14,0) -> 0 | N14: =IF(10>=C14,D14,0) -> 0 | O14: =IF(11>=C14,D14,0) -> 0 | P14: =IF(12>=C14,D14,0) -> 0 | Q14: =IF(13>=C14,D14,0) -> 0 | R14: =IF(14>=C14,D14,0) -> 0 | S14: =IF(15>=C14,D14,0) -> 0 | T14: =IF(16>=C14,D14,0) -> 0 | U14: =IF(17>=C14,D14,0) -> 0 | V14: =IF(18>=C14,D14,0) -> 0 | W14: =IF(19>=C14,D14,0) -> 0 | X14: =IF(20>=C14,D14,0) -> 0 | Y14: =IF(21>=C14,D14,0) -> 0 | Z14: =IF(22>=C14,D14,0) -> 0 | AA14: =IF(23>=C14,D14,0) -> 0 | AB14: =IF(24>=C14,D14,0) -> 0 | AC14: =SUM(E14:G14) -> 0 | AD14: =SUM(H14:J14) -> 0 | AE14: =SUM(K14:M14) -> 0 | AF14: =SUM(N14:P14) -> 0 | AG14: =SUM(AC14:AF14) -> 0 | AH14: =SUM(Q14:S14) -> 0 | AI14: =SUM(T14:V14) -> 0 | AJ14: =SUM(W14:Y14) -> 0 | AK14: =SUM(Z14:AB14) -> 0 | AL14: =SUM(AH14:AK14) -> 0 | AM14: =AG14+AL14 -> 0
A15: Enterprise Sales Lead | B15: 160000 | C15: 25 | D15: =B15/12 -> 13333.333 | E15: =IF(1>=C15,D15,0) -> 0 | F15: =IF(2>=C15,D15,0) -> 0 | G15: =IF(3>=C15,D15,0) -> 0 | H15: =IF(4>=C15,D15,0) -> 0 | I15: =IF(5>=C15,D15,0) -> 0 | J15: =IF(6>=C15,D15,0) -> 0 | K15: =IF(7>=C15,D15,0) -> 0 | L15: =IF(8>=C15,D15,0) -> 0 | M15: =IF(9>=C15,D15,0) -> 0 | N15: =IF(10>=C15,D15,0) -> 0 | O15: =IF(11>=C15,D15,0) -> 0 | P15: =IF(12>=C15,D15,0) -> 0 | Q15: =IF(13>=C15,D15,0) -> 0 | R15: =IF(14>=C15,D15,0) -> 0 | S15: =IF(15>=C15,D15,0) -> 0 | T15: =IF(16>=C15,D15,0) -> 0 | U15: =IF(17>=C15,D15,0) -> 0 | V15: =IF(18>=C15,D15,0) -> 0 | W15: =IF(19>=C15,D15,0) -> 0 | X15: =IF(20>=C15,D15,0) -> 0 | Y15: =IF(21>=C15,D15,0) -> 0 | Z15: =IF(22>=C15,D15,0) -> 0 | AA15: =IF(23>=C15,D15,0) -> 0 | AB15: =IF(24>=C15,D15,0) -> 0 | AC15: =SUM(E15:G15) -> 0 | AD15: =SUM(H15:J15) -> 0 | AE15: =SUM(K15:M15) -> 0 | AF15: =SUM(N15:P15) -> 0 | AG15: =SUM(AC15:AF15) -> 0 | AH15: =SUM(Q15:S15) -> 0 | AI15: =SUM(T15:V15) -> 0 | AJ15: =SUM(W15:Y15) -> 0 | AK15: =SUM(Z15:AB15) -> 0 | AL15: =SUM(AH15:AK15) -> 0 | AM15: =AG15+AL15 -> 0
A16: Head of Customer Success | B16: 150000 | C16: 25 | D16: =B16/12 -> 12500 | E16: =IF(1>=C16,D16,0) -> 0 | F16: =IF(2>=C16,D16,0) -> 0 | G16: =IF(3>=C16,D16,0) -> 0 | H16: =IF(4>=C16,D16,0) -> 0 | I16: =IF(5>=C16,D16,0) -> 0 | J16: =IF(6>=C16,D16,0) -> 0 | K16: =IF(7>=C16,D16,0) -> 0 | L16: =IF(8>=C16,D16,0) -> 0 | M16: =IF(9>=C16,D16,0) -> 0 | N16: =IF(10>=C16,D16,0) -> 0 | O16: =IF(11>=C16,D16,0) -> 0 | P16: =IF(12>=C16,D16,0) -> 0 | Q16: =IF(13>=C16,D16,0) -> 0 | R16: =IF(14>=C16,D16,0) -> 0 | S16: =IF(15>=C16,D16,0) -> 0 | T16: =IF(16>=C16,D16,0) -> 0 | U16: =IF(17>=C16,D16,0) -> 0 | V16: =IF(18>=C16,D16,0) -> 0 | W16: =IF(19>=C16,D16,0) -> 0 | X16: =IF(20>=C16,D16,0) -> 0 | Y16: =IF(21>=C16,D16,0) -> 0 | Z16: =IF(22>=C16,D16,0) -> 0 | AA16: =IF(23>=C16,D16,0) -> 0 | AB16: =IF(24>=C16,D16,0) -> 0 | AC16: =SUM(E16:G16) -> 0 | AD16: =SUM(H16:J16) -> 0 | AE16: =SUM(K16:M16) -> 0 | AF16: =SUM(N16:P16) -> 0 | AG16: =SUM(AC16:AF16) -> 0 | AH16: =SUM(Q16:S16) -> 0 | AI16: =SUM(T16:V16) -> 0 | AJ16: =SUM(W16:Y16) -> 0 | AK16: =SUM(Z16:AB16) -> 0 | AL16: =SUM(AH16:AK16) -> 0 | AM16: =AG16+AL16 -> 0
A17: Senior Sales Rep | B17: 130000 | C17: 25 | D17: =B17/12 -> 10833.333 | E17: =IF(1>=C17,D17,0) -> 0 | F17: =IF(2>=C17,D17,0) -> 0 | G17: =IF(3>=C17,D17,0) -> 0 | H17: =IF(4>=C17,D17,0) -> 0 | I17: =IF(5>=C17,D17,0) -> 0 | J17: =IF(6>=C17,D17,0) -> 0 | K17: =IF(7>=C17,D17,0) -> 0 | L17: =IF(8>=C17,D17,0) -> 0 | M17: =IF(9>=C17,D17,0) -> 0 | N17: =IF(10>=C17,D17,0) -> 0 | O17: =IF(11>=C17,D17,0) -> 0 | P17: =IF(12>=C17,D17,0) -> 0 | Q17: =IF(13>=C17,D17,0) -> 0 | R17: =IF(14>=C17,D17,0) -> 0 | S17: =IF(15>=C17,D17,0) -> 0 | T17: =IF(16>=C17,D17,0) -> 0 | U17: =IF(17>=C17,D17,0) -> 0 | V17: =IF(18>=C17,D17,0) -> 0 | W17: =IF(19>=C17,D17,0) -> 0 | X17: =IF(20>=C17,D17,0) -> 0 | Y17: =IF(21>=C17,D17,0) -> 0 | Z17: =IF(22>=C17,D17,0) -> 0 | AA17: =IF(23>=C17,D17,0) -> 0 | AB17: =IF(24>=C17,D17,0) -> 0 | AC17: =SUM(E17:G17) -> 0 | AD17: =SUM(H17:J17) -> 0 | AE17: =SUM(K17:M17) -> 0 | AF17: =SUM(N17:P17) -> 0 | AG17: =SUM(AC17:AF17) -> 0 | AH17: =SUM(Q17:S17) -> 0 | AI17: =SUM(T17:V17) -> 0 | AJ17: =SUM(W17:Y17) -> 0 | AK17: =SUM(Z17:AB17) -> 0 | AL17: =SUM(AH17:AK17) -> 0 | AM17: =AG17+AL17 -> 0
A18: Product Manager | B18: 140000 | C18: 25 | D18: =B18/12 -> 11666.667 | E18: =IF(1>=C18,D18,0) -> 0 | F18: =IF(2>=C18,D18,0) -> 0 | G18: =IF(3>=C18,D18,0) -> 0 | H18: =IF(4>=C18,D18,0) -> 0 | I18: =IF(5>=C18,D18,0) -> 0 | J18: =IF(6>=C18,D18,0) -> 0 | K18: =IF(7>=C18,D18,0) -> 0 | L18: =IF(8>=C18,D18,0) -> 0 | M18: =IF(9>=C18,D18,0) -> 0 | N18: =IF(10>=C18,D18,0) -> 0 | O18: =IF(11>=C18,D18,0) -> 0 | P18: =IF(12>=C18,D18,0) -> 0 | Q18: =IF(13>=C18,D18,0) -> 0 | R18: =IF(14>=C18,D18,0) -> 0 | S18: =IF(15>=C18,D18,0) -> 0 | T18: =IF(16>=C18,D18,0) -> 0 | U18: =IF(17>=C18,D18,0) -> 0 | V18: =IF(18>=C18,D18,0) -> 0 | W18: =IF(19>=C18,D18,0) -> 0 | X18: =IF(20>=C18,D18,0) -> 0 | Y18: =IF(21>=C18,D18,0) -> 0 | Z18: =IF(22>=C18,D18,0) -> 0 | AA18: =IF(23>=C18,D18,0) -> 0 | AB18: =IF(24>=C18,D18,0) -> 0 | AC18: =SUM(E18:G18) -> 0 | AD18: =SUM(H18:J18) -> 0 | AE18: =SUM(K18:M18) -> 0 | AF18: =SUM(N18:P18) -> 0 | AG18: =SUM(AC18:AF18) -> 0 | AH18: =SUM(Q18:S18) -> 0 | AI18: =SUM(T18:V18) -> 0 | AJ18: =SUM(W18:Y18) -> 0 | AK18: =SUM(Z18:AB18) -> 0 | AL18: =SUM(AH18:AK18) -> 0 | AM18: =AG18+AL18 -> 0
A19: Senior Engineer | B19: 170000 | C19: 25 | D19: =B19/12 -> 14166.667 | E19: =IF(1>=C19,D19,0) -> 0 | F19: =IF(2>=C19,D19,0) -> 0 | G19: =IF(3>=C19,D19,0) -> 0 | H19: =IF(4>=C19,D19,0) -> 0 | I19: =IF(5>=C19,D19,0) -> 0 | J19: =IF(6>=C19,D19,0) -> 0 | K19: =IF(7>=C19,D19,0) -> 0 | L19: =IF(8>=C19,D19,0) -> 0 | M19: =IF(9>=C19,D19,0) -> 0 | N19: =IF(10>=C19,D19,0) -> 0 | O19: =IF(11>=C19,D19,0) -> 0 | P19: =IF(12>=C19,D19,0) -> 0 | Q19: =IF(13>=C19,D19,0) -> 0 | R19: =IF(14>=C19,D19,0) -> 0 | S19: =IF(15>=C19,D19,0) -> 0 | T19: =IF(16>=C19,D19,0) -> 0 | U19: =IF(17>=C19,D19,0) -> 0 | V19: =IF(18>=C19,D19,0) -> 0 | W19: =IF(19>=C19,D19,0) -> 0 | X19: =IF(20>=C19,D19,0) -> 0 | Y19: =IF(21>=C19,D19,0) -> 0 | Z19: =IF(22>=C19,D19,0) -> 0 | AA19: =IF(23>=C19,D19,0) -> 0 | AB19: =IF(24>=C19,D19,0) -> 0 | AC19: =SUM(E19:G19) -> 0 | AD19: =SUM(H19:J19) -> 0 | AE19: =SUM(K19:M19) -> 0 | AF19: =SUM(N19:P19) -> 0 | AG19: =SUM(AC19:AF19) -> 0 | AH19: =SUM(Q19:S19) -> 0 | AI19: =SUM(T19:V19) -> 0 | AJ19: =SUM(W19:Y19) -> 0 | AK19: =SUM(Z19:AB19) -> 0 | AL19: =SUM(AH19:AK19) -> 0 | AM19: =AG19+AL19 -> 0
... A25: Industry Advisors (2) | B25: 30000 | C25: 25 | D25: =B25/12 -> 2500 | E25: =IF(1>=C25,D25,0) -> 0 | F25: =IF(2>=C25,D25,0) -> 0 | G25: =IF(3>=C25,D25,0) -> 0 | H25: =IF(4>=C25,D25,0) -> 0 | I25: =IF(5>=C25,D25,0) -> 0 | J25: =IF(6>=C25,D25,0) -> 0 | K25: =IF(7>=C25,D25,0) -> 0 | L25: =IF(8>=C25,D25,0) -> 0 | M25: =IF(9>=C25,D25,0) -> 0 | N25: =IF(10>=C25,D25,0) -> 0 | O25: =IF(11>=C25,D25,0) -> 0 | P25: =IF(12>=C25,D25,0) -> 0 | Q25: =IF(13>=C25,D25,0) -> 0 | R25: =IF(14>=C25,D25,0) -> 0 | S25: =IF(15>=C25,D25,0) -> 0 | T25: =IF(16>=C25,D25,0) -> 0 | U25: =IF(17>=C25,D25,0) -> 0 | V25: =IF(18>=C25,D25,0) -> 0 | W25: =IF(19>=C25,D25,0) -> 0 | X25: =IF(20>=C25,D25,0) -> 0 | Y25: =IF(21>=C25,D25,0) -> 0 | Z25: =IF(22>=C25,D25,0) -> 0 | AA25: =IF(23>=C25,D25,0) -> 0 | AB25: =IF(24>=C25,D25,0) -> 0 | AC25: =SUM(E25:G25) -> 0 | AD25: =SUM(H25:J25) -> 0 | AE25: =SUM(K25:M25) -> 0 | AF25: =SUM(N25:P25) -> 0 | AG25: =SUM(AC25:AF25) -> 0 | AH25: =SUM(Q25:S25) -> 0 | AI25: =SUM(T25:V25) -> 0 | AJ25: =SUM(W25:Y25) -> 0 | AK25: =SUM(Z25:AB25) -> 0 | AL25: =SUM(AH25:AK25) -> 0 | AM25: =AG25+AL25 -> 0
A26: Subtotal: Base Salaries | D26: =SUM(D2:D25) -> 311833.33 | E26: =SUM(E2:E25) -> 30416.667 | F26: =SUM(F2:F25) -> 42916.667 | G26: =SUM(G2:G25) -> 149583.33 | H26: =SUM(H2:H25) -> 149583.33 | I26: =SUM(I2:I25) -> 164583.33 | J26: =SUM(J2:J25) -> 164583.33 | K26: =SUM(K2:K25) -> 177083.33 | ... AM26: =SUM(AM2:AM25) -> 3889166.7
A27: Benefits & Taxes | B27: 30 | C27: of base salary | D27: =D26*B27 -> 9355000 | E27: =E26*0.35 -> 10645.833 | F27: =F26*0.35 -> 15020.833 | G27: =G26*0.35 -> 52354.167 | H27: =H26*0.35 -> 52354.167 | I27: =I26*0.35 -> 57604.167 | J27: =J26*0.35 -> 57604.167 | K27: =K26*0.35 -> 61979.167 | L27: =L26*0.35 -> 61979.167 | ... AM27: =AM26*0.35 -> 1361208.3
A28: Recruiting Expenses | B28: 10000 | C28: per hire | E28: =B28*SUMPRODUCT((C2:C25=1)*1) -> 20000 | F28: =B28*SUMPRODUCT((C2:C25=2)*1) -> 10000 | G28: =B28*SUMPRODUCT((C2:C25=3)*1) -> 50000 | H28: =B28*SUMPRODUCT((C2:C25=4)*1) -> 0 | I28: =B28*SUMPRODUCT((C2:C25=5)*1) -> 10000 | J28: =B28*SUMPRODUCT((C2:C25=6)*1) -> 0 | K28: =B28*SUMPRODUCT((C2:C25=7)*1) -> 10000 | L28: =B28*SUMPRODUCT((C2:C25=8)*1) -> 0 | M28: =B28*SUMPRODUCT((C2:C25=9)*1) -> 0 | N28: =B28*SUMPRODUCT((C2:C25=10)*1) -> 0 | O28: =B28*SUMPRODUCT((C2:C25=11)*1) -> 0 | P28: =B28*SUMPRODUCT((C2:C25=12)*1) -> 0 | Q28: =B28*SUMPRODUCT((C2:C25=13)*1) -> 0 | R28: =B28*SUMPRODUCT((C2:C25=14)*1) -> 0 | S28: =B28*SUMPRODUCT((C2:C25=15)*1) -> 0 | T28: =B28*SUMPRODUCT((C2:C25=16)*1) -> 0 | U28: =B28*SUMPRODUCT((C2:C25=17)*1) -> 0 | V28: =B28*SUMPRODUCT((C2:C25=18)*1) -> 0 | W28: =B28*SUMPRODUCT((C2:C25=19)*1) -> 0 | X28: =B28*SUMPRODUCT((C2:C25=20)*1) -> 0 | Y28: =B28*SUMPRODUCT((C2:C25=21)*1) -> 0 | Z28: =B28*SUMPRODUCT((C2:C25=22)*1) -> 0 | AA28: =B28*SUMPRODUCT((C2:C25=23)*1) -> 0 | AB28: =B28*SUMPRODUCT((C2:C25=24)*1) -> 0 | AC28: =SUM(E28:G28) -> 80000 | AD28: =SUM(H28:J28) -> 10000 | AE28: =SUM(K28:M28) -> 10000 | AF28: =SUM(N28:P28) -> 0 | AG28: =SUM(AC28:AF28) -> 100000 | AH28: =SUM(Q28:S28) -> 0 | AI28: =SUM(T28:V28) -> 0 | AJ28: =SUM(W28:Y28) -> 0 | AK28: =SUM(Z28:AB28) -> 0 | AL28: =SUM(AH28:AK28) -> 0 | AM28: =AG28+AL28 -> 100000
A29: TOTAL TEAM EXPENSES | D29: =D26+D27+D28 -> 9666833.3 | E29: =E26+E27+E28 -> 61062.5 | F29: =F26+F27+F28 -> 67937.5 | G29: =G26+G27+G28 -> 251937.5 | H29: =H26+H27+H28 -> 201937.5 | I29: =I26+I27+I28 -> 232187.5 | J29: =J26+J27+J28 -> 222187.5 | K29: =K26+K27+K28 -> 249062.5 | ... AM29: =AM26+AM27+AM28 -> 5350375
A30: Cumulative Team Expenses | E30: =E29 -> 61062.5 | F30: =E30+F29 -> 129000 | G30: =F30+G29 -> 380937.5 | H30: =G30+H29 -> 582875 | I30: =H30+I29 -> 815062.5 | J30: =I30+J29 -> 1037250 | K30: =J30+K29 -> 1286312.5 | L30: =K30+L29 -> 1525375 | M30: =L30+M29 -> 1764437.5 | ... AB30: =AA30+AB29 -> 5350375 | AC30: =G30 -> 380937.5 | AD30: =J30 -> 1037250 | AE30: =M30 -> 1764437.5 | AF30: =P30 -> 2481625 | AG30: =AF30 -> 2481625 | AH30: =S30 -> 3198812.5 | AI30: =V30 -> 3916000 | AJ30: =Y30 -> 4633187.5 | AK30: =AB30 -> 5350375 | AL30: =AK30 -> 5350375 | AM30: =AB30 -> 5350375

Sheet Infrastructure Detail
A1: Infrastructure & Operating
A3: Line Item | B3: Base Monthly | C3: Growth Rate | D3: Notes / Assumptions | E3: Jan-26 | F3: Feb-26 | G3: Mar-26 | H3: Apr-26 | I3: May-26 | J3: Jun-26 | K3: Jul-26 | L3: Aug-26 | M3: Sep-26 | N3: Oct-26 | O3: Nov-26 | P3: Dec-26 | Q3: Jan-27 | R3: Feb-27 | S3: Mar-27 | T3: Apr-27 | U3: May-27 | V3: Jun-27 | W3: Jul-27 | X3: Aug-27 | Y3: Sep-27 | Z3: Oct-27 | AA3: Nov-27 | AB3: Dec-27 | AC3: Q1 2026 | AD3: Q2 2026 | AE3: Q3 2026 | AF3: Q4 2026 | AG3: 2026 Total | AH3: Q1 2027 | AI3: Q2 2027 | AJ3: Q3 2027 | AK3: Q4 2027 | AL3: 2027 Total | AM3: Grand Total
A4: Cloud Infrastructure (AWS/GCP) | B4: 5000 | C4: 0.1 | D4: Scales with user growth and data processing | E4: =B4*POWER(1+C4,0) -> 5000 | F4: =B4*POWER(1+C4,1) -> 5500 | G4: =B4*POWER(1+C4,2) -> 6050 | H4: =B4*POWER(1+C4,3) -> 6655 | I4: =B4*POWER(1+C4,4) -> 7320.5 | J4: =B4*POWER(1+C4,5) -> 8052.55 | K4: =B4*POWER(1+C4,6) -> 8857.805 | L4: =B4*POWER(1+C4,7) -> 9743.5855 | M4: =B4*POWER(1+C4,8) -> 10717.944 | N4: =B4*POWER(1+C4,9) -> 11789.738 | O4: =B4*POWER(1+C4,10) -> 12968.712 | P4: =B4*POWER(1+C4,11) -> 14265.584 | Q4: =B4*POWER(1+C4,12) -> 15692.142 | R4: =B4*POWER(1+C4,13) -> 17261.356 | S4: =B4*POWER(1+C4,14) -> 18987.492 | T4: =B4*POWER(1+C4,15) -> 20886.241 | U4: =B4*POWER(1+C4,16) -> 22974.865 | V4: =B4*POWER(1+C4,17) -> 25272.351 | W4: =B4*POWER(1+C4,18) -> 27799.587 | X4: =B4*POWER(1+C4,19) -> 30579.545 | Y4: =B4*POWER(1+C4,20) -> 33637.5 | Z4: =B4*POWER(1+C4,21) -> 37001.25 | AA4: =B4*POWER(1+C4,22) -> 40701.375 | AB4: =B4*POWER(1+C4,23) -> 44771.512 | AC4: =SUM(E4:G4) -> 16550 | AD4: =SUM(H4:J4) -> 22028.05 | AE4: =SUM(K4:M4) -> 29319.335 | AF4: =SUM(N4:P4) -> 39024.034 | AG4: =SUM(AC4:AF4) -> 106921.42 | AH4: =SUM(Q4:S4) -> 51940.99 | AI4: =SUM(T4:V4) -> 69133.457 | AJ4: =SUM(W4:Y4) -> 92016.632 | AK4: =SUM(Z4:AB4) -> 122474.14 | AL4: =SUM(AH4:AK4) -> 335565.21 | AM4: =AG4+AL4 -> 442486.63
A5: Edge LLM Development Tools | C5: 0.05 | D5: Model training and optimization tools | E5: =B5*POWER(1+C5,0) -> 0 | F5: =B5*POWER(1+C5,1) -> 0 | G5: =B5*POWER(1+C5,2) -> 0 | H5: =B5*POWER(1+C5,3) -> 0 | I5: =B5*POWER(1+C5,4) -> 0 | J5: =B5*POWER(1+C5,5) -> 0 | K5: =B5*POWER(1+C5,6) -> 0 | L5: =B5*POWER(1+C5,7) -> 0 | M5: =B5*POWER(1+C5,8) -> 0 | N5: =B5*POWER(1+C5,9) -> 0 | O5: =B5*POWER(1+C5,10) -> 0 | P5: =B5*POWER(1+C5,11) -> 0 | Q5: =B5*POWER(1+C5,12) -> 0 | R5: =B5*POWER(1+C5,13) -> 0 | S5: =B5*POWER(1+C5,14) -> 0 | T5: =B5*POWER(1+C5,15) -> 0 | U5: =B5*POWER(1+C5,16) -> 0 | V5: =B5*POWER(1+C5,17) -> 0 | W5: =B5*POWER(1+C5,18) -> 0 | X5: =B5*POWER(1+C5,19) -> 0 | Y5: =B5*POWER(1+C5,20) -> 0 | Z5: =B5*POWER(1+C5,21) -> 0 | AA5: =B5*POWER(1+C5,22) -> 0 | AB5: =B5*POWER(1+C5,23) -> 0 | AC5: =SUM(E5:G5) -> 0 | AD5: =SUM(H5:J5) -> 0 | AE5: =SUM(K5:M5) -> 0 | AF5: =SUM(N5:P5) -> 0 | AG5: =SUM(AC5:AF5) -> 0 | AH5: =SUM(Q5:S5) -> 0 | AI5: =SUM(T5:V5) -> 0 | AJ5: =SUM(W5:Y5) -> 0 | AK5: =SUM(Z5:AB5) -> 0 | AL5: =SUM(AH5:AK5) -> 0 | AM5: =AG5+AL5 -> 0
A6: Development Tools & Software | B6: 2500 | C6: 0.03 | D6: IDEs, collaboration tools, per-seat licenses | E6: =B6*POWER(1+C6,0) -> 2500 | F6: =B6*POWER(1+C6,1) -> 2575 | G6: =B6*POWER(1+C6,2) -> 2652.25 | H6: =B6*POWER(1+C6,3) -> 2731.8175 | I6: =B6*POWER(1+C6,4) -> 2813.772 | J6: =B6*POWER(1+C6,5) -> 2898.1852 | K6: =B6*POWER(1+C6,6) -> 2985.1307 | L6: =B6*POWER(1+C6,7) -> 3074.6847 | M6: =B6*POWER(1+C6,8) -> 3166.9252 | N6: =B6*POWER(1+C6,9) -> 3261.933 | O6: =B6*POWER(1+C6,10) -> 3359.7909 | P6: =B6*POWER(1+C6,11) -> 3460.5847 | Q6: =B6*POWER(1+C6,12) -> 3564.4022 | R6: =B6*POWER(1+C6,13) -> 3671.3343 | S6: =B6*POWER(1+C6,14) -> 3781.4743 | T6: =B6*POWER(1+C6,15) -> 3894.9185 | U6: =B6*POWER(1+C6,16) -> 4011.7661 | V6: =B6*POWER(1+C6,17) -> 4132.1191 | W6: =B6*POWER(1+C6,18) -> 4256.0827 | X6: =B6*POWER(1+C6,19) -> 4383.7651 | Y6: =B6*POWER(1+C6,20) -> 4515.2781 | Z6: =B6*POWER(1+C6,21) -> 4650.7364 | AA6: =B6*POWER(1+C6,22) -> 4790.2585 | AB6: =B6*POWER(1+C6,23) -> 4933.9663 | AC6: =SUM(E6:G6) -> 7727.25 | AD6: =SUM(H6:J6) -> 8443.7747 | AE6: =SUM(K6:M6) -> 9226.7406 | AF6: =SUM(N6:P6) -> 10082.309 | AG6: =SUM(AC6:AF6) -> 35480.074 | AH6: =SUM(Q6:S6) -> 11017.211 | AI6: =SUM(T6:V6) -> 12038.804 | AJ6: =SUM(W6:Y6) -> 13155.126 | AK6: =SUM(Z6:AB6) -> 14374.961 | AL6: =SUM(AH6:AK6) -> 50586.102 | AM6: =AG6+AL6 -> 86066.176
A7: Security & Compliance Tools | C7: 0.05 | D7: SOC 2, penetration testing, monitoring | E7: =B7*POWER(1+C7,0) -> 0 | F7: =B7*POWER(1+C7,1) -> 0 | G7: =B7*POWER(1+C7,2) -> 0 | H7: =B7*POWER(1+C7,3) -> 0 | I7: =B7*POWER(1+C7,4) -> 0 | J7: =B7*POWER(1+C7,5) -> 0 | K7: =B7*POWER(1+C7,6) -> 0 | L7: =B7*POWER(1+C7,7) -> 0 | M7: =B7*POWER(1+C7,8) -> 0 | N7: =B7*POWER(1+C7,9) -> 0 | O7: =B7*POWER(1+C7,10) -> 0 | P7: =B7*POWER(1+C7,11) -> 0 | Q7: =B7*POWER(1+C7,12) -> 0 | R7: =B7*POWER(1+C7,13) -> 0 | S7: =B7*POWER(1+C7,14) -> 0 | T7: =B7*POWER(1+C7,15) -> 0 | U7: =B7*POWER(1+C7,16) -> 0 | V7: =B7*POWER(1+C7,17) -> 0 | W7: =B7*POWER(1+C7,18) -> 0 | X7: =B7*POWER(1+C7,19) -> 0 | Y7: =B7*POWER(1+C7,20) -> 0 | Z7: =B7*POWER(1+C7,21) -> 0 | AA7: =B7*POWER(1+C7,22) -> 0 | AB7: =B7*POWER(1+C7,23) -> 0 | AC7: =SUM(E7:G7) -> 0 | AD7: =SUM(H7:J7) -> 0 | AE7: =SUM(K7:M7) -> 0 | AF7: =SUM(N7:P7) -> 0 | AG7: =SUM(AC7:AF7) -> 0 | AH7: =SUM(Q7:S7) -> 0 | AI7: =SUM(T7:V7) -> 0 | AJ7: =SUM(W7:Y7) -> 0 | AK7: =SUM(Z7:AB7) -> 0 | AL7: =SUM(AH7:AK7) -> 0 | AM7: =AG7+AL7 -> 0
A8: Data Storage & Processing | C8: 0.02 | D8: Database, data warehouse, analytics storage | E8: =B8*POWER(1+C8,0) -> 0 | F8: =B8*POWER(1+C8,1) -> 0 | G8: =B8*POWER(1+C8,2) -> 0 | H8: =B8*POWER(1+C8,3) -> 0 | I8: =B8*POWER(1+C8,4) -> 0 | J8: =B8*POWER(1+C8,5) -> 0 | K8: =B8*POWER(1+C8,6) -> 0 | L8: =B8*POWER(1+C8,7) -> 0 | M8: =B8*POWER(1+C8,8) -> 0 | N8: =B8*POWER(1+C8,9) -> 0 | O8: =B8*POWER(1+C8,10) -> 0 | P8: =B8*POWER(1+C8,11) -> 0 | Q8: =B8*POWER(1+C8,12) -> 0 | R8: =B8*POWER(1+C8,13) -> 0 | S8: =B8*POWER(1+C8,14) -> 0 | T8: =B8*POWER(1+C8,15) -> 0 | U8: =B8*POWER(1+C8,16) -> 0 | V8: =B8*POWER(1+C8,17) -> 0 | W8: =B8*POWER(1+C8,18) -> 0 | X8: =B8*POWER(1+C8,19) -> 0 | Y8: =B8*POWER(1+C8,20) -> 0 | Z8: =B8*POWER(1+C8,21) -> 0 | AA8: =B8*POWER(1+C8,22) -> 0 | AB8: =B8*POWER(1+C8,23) -> 0 | AC8: =SUM(E8:G8) -> 0 | AD8: =SUM(H8:J8) -> 0 | AE8: =SUM(K8:M8) -> 0 | AF8: =SUM(N8:P8) -> 0 | AG8: =SUM(AC8:AF8) -> 0 | AH8: =SUM(Q8:S8) -> 0 | AI8: =SUM(T8:V8) -> 0 | AJ8: =SUM(W8:Y8) -> 0 | AK8: =SUM(Z8:AB8) -> 0 | AL8: =SUM(AH8:AK8) -> 0 | AM8: =AG8+AL8 -> 0
A9: DevOps & Monitoring | C9: 0.05 | D9: CI/CD, APM, logging, alerting tools | E9: =B9*POWER(1+C9,0) -> 0 | F9: =B9*POWER(1+C9,1) -> 0 | G9: =B9*POWER(1+C9,2) -> 0 | H9: =B9*POWER(1+C9,3) -> 0 | I9: =B9*POWER(1+C9,4) -> 0 | J9: =B9*POWER(1+C9,5) -> 0 | K9: =B9*POWER(1+C9,6) -> 0 | L9: =B9*POWER(1+C9,7) -> 0 | M9: =B9*POWER(1+C9,8) -> 0 | N9: =B9*POWER(1+C9,9) -> 0 | O9: =B9*POWER(1+C9,10) -> 0 | P9: =B9*POWER(1+C9,11) -> 0 | Q9: =B9*POWER(1+C9,12) -> 0 | R9: =B9*POWER(1+C9,13) -> 0 | S9: =B9*POWER(1+C9,14) -> 0 | T9: =B9*POWER(1+C9,15) -> 0 | U9: =B9*POWER(1+C9,16) -> 0 | V9: =B9*POWER(1+C9,17) -> 0 | W9: =B9*POWER(1+C9,18) -> 0 | X9: =B9*POWER(1+C9,19) -> 0 | Y9: =B9*POWER(1+C9,20) -> 0 | Z9: =B9*POWER(1+C9,21) -> 0 | AA9: =B9*POWER(1+C9,22) -> 0 | AB9: =B9*POWER(1+C9,23) -> 0 | AC9: =SUM(E9:G9) -> 0 | AD9: =SUM(H9:J9) -> 0 | AE9: =SUM(K9:M9) -> 0 | AF9: =SUM(N9:P9) -> 0 | AG9: =SUM(AC9:AF9) -> 0 | AH9: =SUM(Q9:S9) -> 0 | AI9: =SUM(T9:V9) -> 0 | AJ9: =SUM(W9:Y9) -> 0 | AK9: =SUM(Z9:AB9) -> 0 | AL9: =SUM(AH9:AK9) -> 0 | AM9: =AG9+AL9 -> 0
A10: Office Space & Equipment | B10: 1000 | C10: 0.05 | D10: Rent, furniture, equipment for growing team | E10: =B10*POWER(1+C10,0) -> 1000 | F10: =B10*POWER(1+C10,1) -> 1050 | G10: =B10*POWER(1+C10,2) -> 1102.5 | H10: =B10*POWER(1+C10,3) -> 1157.625 | I10: =B10*POWER(1+C10,4) -> 1215.5062 | J10: =B10*POWER(1+C10,5) -> 1276.2816 | K10: =B10*POWER(1+C10,6) -> 1340.0956 | L10: =B10*POWER(1+C10,7) -> 1407.1004 | M10: =B10*POWER(1+C10,8) -> 1477.4554 | N10: =B10*POWER(1+C10,9) -> 1551.3282 | O10: =B10*POWER(1+C10,10) -> 1628.8946 | P10: =B10*POWER(1+C10,11) -> 1710.3394 | Q10: =B10*POWER(1+C10,12) -> 1795.8563 | R10: =B10*POWER(1+C10,13) -> 1885.6491 | S10: =B10*POWER(1+C10,14) -> 1979.9316 | T10: =B10*POWER(1+C10,15) -> 2078.9282 | U10: =B10*POWER(1+C10,16) -> 2182.8746 | V10: =B10*POWER(1+C10,17) -> 2292.0183 | W10: =B10*POWER(1+C10,18) -> 2406.6192 | X10: =B10*POWER(1+C10,19) -> 2526.9502 | Y10: =B10*POWER(1+C10,20) -> 2653.2977 | Z10: =B10*POWER(1+C10,21) -> 2785.9626 | AA10: =B10*POWER(1+C10,22) -> 2925.2607 | AB10: =B10*POWER(1+C10,23) -> 3071.5238 | AC10: =SUM(E10:G10) -> 3152.5 | AD10: =SUM(H10:J10) -> 3649.4128 | AE10: =SUM(K10:M10) -> 4224.6515 | AF10: =SUM(N10:P10) -> 4890.5622 | AG10: =SUM(AC10:AF10) -> 15917.127 | AH10: =SUM(Q10:S10) -> 5661.4371 | AI10: =SUM(T10:V10) -> 6553.8211 | AJ10: =SUM(W10:Y10) -> 7586.8671 | AK10: =SUM(Z10:AB10) -> 8782.7471 | AL10: =SUM(AH10:AK10) -> 28584.872 | AM10: =AG10+AL10 -> 44501.999
A11: IT & Communications | C11: 0.03 | D11: Internet, phones, collaboration software | E11: =B11*POWER(1+C11,0) -> 0 | F11: =B11*POWER(1+C11,1) -> 0 | G11: =B11*POWER(1+C11,2) -> 0 | H11: =B11*POWER(1+C11,3) -> 0 | I11: =B11*POWER(1+C11,4) -> 0 | J11: =B11*POWER(1+C11,5) -> 0 | K11: =B11*POWER(1+C11,6) -> 0 | L11: =B11*POWER(1+C11,7) -> 0 | M11: =B11*POWER(1+C11,8) -> 0 | N11: =B11*POWER(1+C11,9) -> 0 | O11: =B11*POWER(1+C11,10) -> 0 | P11: =B11*POWER(1+C11,11) -> 0 | Q11: =B11*POWER(1+C11,12) -> 0 | R11: =B11*POWER(1+C11,13) -> 0 | S11: =B11*POWER(1+C11,14) -> 0 | T11: =B11*POWER(1+C11,15) -> 0 | U11: =B11*POWER(1+C11,16) -> 0 | V11: =B11*POWER(1+C11,17) -> 0 | W11: =B11*POWER(1+C11,18) -> 0 | X11: =B11*POWER(1+C11,19) -> 0 | Y11: =B11*POWER(1+C11,20) -> 0 | Z11: =B11*POWER(1+C11,21) -> 0 | AA11: =B11*POWER(1+C11,22) -> 0 | AB11: =B11*POWER(1+C11,23) -> 0 | AC11: =SUM(E11:G11) -> 0 | AD11: =SUM(H11:J11) -> 0 | AE11: =SUM(K11:M11) -> 0 | AF11: =SUM(N11:P11) -> 0 | AG11: =SUM(AC11:AF11) -> 0 | AH11: =SUM(Q11:S11) -> 0 | AI11: =SUM(T11:V11) -> 0 | AJ11: =SUM(W11:Y11) -> 0 | AK11: =SUM(Z11:AB11) -> 0 | AL11: =SUM(AH11:AK11) -> 0 | AM11: =AG11+AL11 -> 0
A12: Insurance & Legal | C12: 0.02 | D12: D&O insurance, general liability, legal retainer | E12: =B12*POWER(1+C12,0) -> 0 | F12: =B12*POWER(1+C12,1) -> 0 | G12: =B12*POWER(1+C12,2) -> 0 | H12: =B12*POWER(1+C12,3) -> 0 | I12: =B12*POWER(1+C12,4) -> 0 | J12: =B12*POWER(1+C12,5) -> 0 | K12: =B12*POWER(1+C12,6) -> 0 | L12: =B12*POWER(1+C12,7) -> 0 | M12: =B12*POWER(1+C12,8) -> 0 | N12: =B12*POWER(1+C12,9) -> 0 | O12: =B12*POWER(1+C12,10) -> 0 | P12: =B12*POWER(1+C12,11) -> 0 | Q12: =B12*POWER(1+C12,12) -> 0 | R12: =B12*POWER(1+C12,13) -> 0 | S12: =B12*POWER(1+C12,14) -> 0 | T12: =B12*POWER(1+C12,15) -> 0 | U12: =B12*POWER(1+C12,16) -> 0 | V12: =B12*POWER(1+C12,17) -> 0 | W12: =B12*POWER(1+C12,18) -> 0 | X12: =B12*POWER(1+C12,19) -> 0 | Y12: =B12*POWER(1+C12,20) -> 0 | Z12: =B12*POWER(1+C12,21) -> 0 | AA12: =B12*POWER(1+C12,22) -> 0 | AB12: =B12*POWER(1+C12,23) -> 0 | AC12: =SUM(E12:G12) -> 0 | AD12: =SUM(H12:J12) -> 0 | AE12: =SUM(K12:M12) -> 0 | AF12: =SUM(N12:P12) -> 0 | AG12: =SUM(AC12:AF12) -> 0 | AH12: =SUM(Q12:S12) -> 0 | AI12: =SUM(T12:V12) -> 0 | AJ12: =SUM(W12:Y12) -> 0 | AK12: =SUM(Z12:AB12) -> 0 | AL12: =SUM(AH12:AK12) -> 0 | AM12: =AG12+AL12 -> 0
A13: Accounting & Finance | C13: 0.02 | D13: Bookkeeping, tax prep, financial systems | E13: =B13*POWER(1+C13,0) -> 0 | F13: =B13*POWER(1+C13,1) -> 0 | G13: =B13*POWER(1+C13,2) -> 0 | H13: =B13*POWER(1+C13,3) -> 0 | I13: =B13*POWER(1+C13,4) -> 0 | J13: =B13*POWER(1+C13,5) -> 0 | K13: =B13*POWER(1+C13,6) -> 0 | L13: =B13*POWER(1+C13,7) -> 0 | M13: =B13*POWER(1+C13,8) -> 0 | N13: =B13*POWER(1+C13,9) -> 0 | O13: =B13*POWER(1+C13,10) -> 0 | P13: =B13*POWER(1+C13,11) -> 0 | Q13: =B13*POWER(1+C13,12) -> 0 | R13: =B13*POWER(1+C13,13) -> 0 | S13: =B13*POWER(1+C13,14) -> 0 | T13: =B13*POWER(1+C13,15) -> 0 | U13: =B13*POWER(1+C13,16) -> 0 | V13: =B13*POWER(1+C13,17) -> 0 | W13: =B13*POWER(1+C13,18) -> 0 | X13: =B13*POWER(1+C13,19) -> 0 | Y13: =B13*POWER(1+C13,20) -> 0 | Z13: =B13*POWER(1+C13,21) -> 0 | AA13: =B13*POWER(1+C13,22) -> 0 | AB13: =B13*POWER(1+C13,23) -> 0 | AC13: =SUM(E13:G13) -> 0 | AD13: =SUM(H13:J13) -> 0 | AE13: =SUM(K13:M13) -> 0 | AF13: =SUM(N13:P13) -> 0 | AG13: =SUM(AC13:AF13) -> 0 | AH13: =SUM(Q13:S13) -> 0 | AI13: =SUM(T13:V13) -> 0 | AJ13: =SUM(W13:Y13) -> 0 | AK13: =SUM(Z13:AB13) -> 0 | AL13: =SUM(AH13:AK13) -> 0 | AM13: =AG13+AL13 -> 0
A14: TOTAL INFRASTRUCTURE & OPERATING | E14: =SUM(E4:E13) -> 8500 | F14: =SUM(F4:F13) -> 9125 | G14: =SUM(G4:G13) -> 9804.75 | H14: =SUM(H4:H13) -> 10544.443 | I14: =SUM(I4:I13) -> 11349.778 | J14: =SUM(J4:J13) -> 12227.017 | K14: =SUM(K4:K13) -> 13183.031 | L14: =SUM(L4:L13) -> 14225.371 | ... AM14: =SUM(AM4:AM13) -> 573054.81
A15: Cumulative Infrastructure & Operating | E15: =E14 -> 8500 | F15: =E15+F14 -> 17625 | G15: =F15+G14 -> 27429.75 | H15: =G15+H14 -> 37974.193 | I15: =H15+I14 -> 49323.971 | J15: =I15+J14 -> 61550.988 | K15: =J15+K14 -> 74734.019 | L15: =K15+L14 -> 88959.389 | M15: =L15+M14 -> 104321.71 | ... AB15: =AA15+AB14 -> 573054.81 | AC15: =G15 -> 27429.75 | AD15: =J15 -> 61550.988 | AE15: =M15 -> 104321.71 | AF15: =P15 -> 158318.62 | AG15: =AF15 -> 158318.62 | AH15: =S15 -> 226938.26 | AI15: =V15 -> 314664.34 | AJ15: =Y15 -> 427422.96 | AK15: =AB15 -> 573054.81 | AL15: =AK15 -> 573054.81 | AM15: =AB15 -> 573054.81

Sheet Go-to-Market Detail
A1: Go-to-Market
A3: Line Item | B3: Base Monthly | C3: Growth Rate | D3: Notes / Assumptions | E3: Jan-26 | F3: Feb-26 | G3: Mar-26 | H3: Apr-26 | I3: May-26 | J3: Jun-26 | K3: Jul-26 | L3: Aug-26 | M3: Sep-26 | N3: Oct-26 | O3: Nov-26 | P3: Dec-26 | Q3: Jan-27 | R3: Feb-27 | S3: Mar-27 | T3: Apr-27 | U3: May-27 | V3: Jun-27 | W3: Jul-27 | X3: Aug-27 | Y3: Sep-27 | Z3: Oct-27 | AA3: Nov-27 | AB3: Dec-27 | AC3: Q1 2026 | AD3: Q2 2026 | AE3: Q3 2026 | AF3: Q4 2026 | AG3: 2026 Total | AH3: Q1 2027 | AI3: Q2 2027 | AJ3: Q3 2027 | AK3: Q4 2027 | AL3: 2027 Total | AM3: Grand Total
A4: Content Marketing & SEO | B4: 5000 | C4: 0.03 | D4: Blog, SEO tools, content creation | E4: =B4*POWER(1+C4,0) -> 5000 | F4: =B4*POWER(1+C4,1) -> 5150 | G4: =B4*POWER(1+C4,2) -> 5304.5 | H4: =B4*POWER(1+C4,3) -> 5463.635 | I4: =B4*POWER(1+C4,4) -> 5627.544 | J4: =B4*POWER(1+C4,5) -> 5796.3704 | K4: =B4*POWER(1+C4,6) -> 5970.2615 | L4: =B4*POWER(1+C4,7) -> 6149.3693 | M4: =B4*POWER(1+C4,8) -> 6333.8504 | N4: =B4*POWER(1+C4,9) -> 6523.8659 | O4: =B4*POWER(1+C4,10) -> 6719.5819 | P4: =B4*POWER(1+C4,11) -> 6921.1694 | Q4: =B4*POWER(1+C4,12) -> 7128.8044 | R4: =B4*POWER(1+C4,13) -> 7342.6686 | S4: =B4*POWER(1+C4,14) -> 7562.9486 | T4: =B4*POWER(1+C4,15) -> 7789.8371 | U4: =B4*POWER(1+C4,16) -> 8023.5322 | V4: =B4*POWER(1+C4,17) -> 8264.2382 | W4: =B4*POWER(1+C4,18) -> 8512.1653 | X4: =B4*POWER(1+C4,19) -> 8767.5303 | Y4: =B4*POWER(1+C4,20) -> 9030.5562 | Z4: =B4*POWER(1+C4,21) -> 9301.4729 | AA4: =B4*POWER(1+C4,22) -> 9580.517 | AB4: =B4*POWER(1+C4,23) -> 9867.9326 | AC4: =SUM(E4:G4) -> 15454.5 | AD4: =SUM(H4:J4) -> 16887.549 | AE4: =SUM(K4:M4) -> 18453.481 | AF4: =SUM(N4:P4) -> 20164.617 | AG4: =SUM(AC4:AF4) -> 70960.148 | AH4: =SUM(Q4:S4) -> 22034.422 | AI4: =SUM(T4:V4) -> 24077.607 | AJ4: =SUM(W4:Y4) -> 26310.252 | AK4: =SUM(Z4:AB4) -> 28749.922 | AL4: =SUM(AH4:AK4) -> 101172.2 | AM4: =AG4+AL4 -> 172132.35
