Workbook
Name _: #REF!
Name __: #REF!
Name ___: {"'1-TheatreBkgs'!$A$1:$L$102"}
Name ______________________________j4: {"Inc_standard",#N/A,TRUE,"Inc"}
Name ______________________________j5: {"'A'!$A$1:$AH$71","'TOC'!$J$29"}
Name ______________________________j6: {"'A'!$A$1:$AH$71","'TOC'!$J$29"}
Name ______________________________j8: {#N/A,"SCENARIO2",FALSE,"DirRpts_Sum";#N/A,"SCENARIO2",FALSE,"Exp_Adjmts";#N/A,#N/A,FALSE,"Advtg_Sum"}
Name ______________________________t9: {#N/A,"SCENARIO2",FALSE,"DirRpts_Sum";#N/A,"SCENARIO2",FALSE,"Exp_Adjmts";#N/A,#N/A,FALSE,"Advtg_Sum"}
Name _____________________________DCF1: #REF!
Name ____________________________j4: {"Inc_standard",#N/A,TRUE,"Inc"}
Name ____________________________j5: {"'A'!$A$1:$AH$71","'TOC'!$J$29"}
Name ____________________________j6: {"'A'!$A$1:$AH$71","'TOC'!$J$29"}
Name ____________________________j8: {#N/A,"SCENARIO2",FALSE,"DirRpts_Sum";#N/A,"SCENARIO2",FALSE,"Exp_Adjmts";#N/A,#N/A,FALSE,"Advtg_Sum"}
Name ____________________________t9: {#N/A,"SCENARIO2",FALSE,"DirRpts_Sum";#N/A,"SCENARIO2",FALSE,"Exp_Adjmts";#N/A,#N/A,FALSE,"Advtg_Sum"}
Name ____________________________ww2: {#N/A,#N/A,FALSE,"Admin";#N/A,#N/A,FALSE,"Other"}
Name ___________________________DCF1: #REF!
Name __________________________DCF1: #REF!
Name __________________________j4: {"Inc_standard",#N/A,TRUE,"Inc"}
Name __________________________j5: {"'A'!$A$1:$AH$71","'TOC'!$J$29"}
Name __________________________j6: {"'A'!$A$1:$AH$71","'TOC'!$J$29"}
Name __________________________j8: {#N/A,"SCENARIO2",FALSE,"DirRpts_Sum";#N/A,"SCENARIO2",FALSE,"Exp_Adjmts";#N/A,#N/A,FALSE,"Advtg_Sum"}
Name __________________________t9: {#N/A,"SCENARIO2",FALSE,"DirRpts_Sum";#N/A,"SCENARIO2",FALSE,"Exp_Adjmts";#N/A,#N/A,FALSE,"Advtg_Sum"}
Name _________________________DCF1: #REF!
Name _________________________j4: {"Inc_standard",#N/A,TRUE,"Inc"}
Name _________________________j5: {"'A'!$A$1:$AH$71","'TOC'!$J$29"}
Name _________________________j6: {"'A'!$A$1:$AH$71","'TOC'!$J$29"}
Name _________________________j8: {#N/A,"SCENARIO2",FALSE,"DirRpts_Sum";#N/A,"SCENARIO2",FALSE,"Exp_Adjmts";#N/A,#N/A,FALSE,"Advtg_Sum"}
Name _________________________t9: {#N/A,"SCENARIO2",FALSE,"DirRpts_Sum";#N/A,"SCENARIO2",FALSE,"Exp_Adjmts";#N/A,#N/A,FALSE,"Advtg_Sum"}
Name ________________________DCF1: #REF!
Name _______________________DCF1: #REF!
Name _______________________j4: {"Inc_standard",#N/A,TRUE,"Inc"}
Name _______________________j5: {"'A'!$A$1:$AH$71","'TOC'!$J$29"}
Name _______________________j6: {"'A'!$A$1:$AH$71","'TOC'!$J$29"}
Name _______________________j8: {#N/A,"SCENARIO2",FALSE,"DirRpts_Sum";#N/A,"SCENARIO2",FALSE,"Exp_Adjmts";#N/A,#N/A,FALSE,"Advtg_Sum"}
Name _______________________t9: {#N/A,"SCENARIO2",FALSE,"DirRpts_Sum";#N/A,"SCENARIO2",FALSE,"Exp_Adjmts";#N/A,#N/A,FALSE,"Advtg_Sum"}
Name ______________________DCF1: #REF!
Name ______________________j4: {"Inc_standard",#N/A,TRUE,"Inc"}
Name ______________________j5: {"'A'!$A$1:$AH$71","'TOC'!$J$29"}
Name ______________________j6: {"'A'!$A$1:$AH$71","'TOC'!$J$29"}
Name ______________________j8: {#N/A,"SCENARIO2",FALSE,"DirRpts_Sum";#N/A,"SCENARIO2",FALSE,"Exp_Adjmts";#N/A,#N/A,FALSE,"Advtg_Sum"}
Name ______________________t9: {#N/A,"SCENARIO2",FALSE,"DirRpts_Sum";#N/A,"SCENARIO2",FALSE,"Exp_Adjmts";#N/A,#N/A,FALSE,"Advtg_Sum"}
Name _____________________DCF1: #REF!
Name _____________________PRN2: {"adj95mult",#N/A,FALSE,"COMPCO";"adj95est",#N/A,FALSE,"COMPCO"}
Name _____________________T123456: {"COUNT",#N/A,FALSE,"AB"}
Name _____________________T12347: {"COUNT",#N/A,FALSE,"AB"}
Name ____________________DCF1: #REF!
Name ____________________j4: {"Inc_standard",#N/A,TRUE,"Inc"}
Name ____________________j5: {"'A'!$A$1:$AH$71","'TOC'!$J$29"}
Name ____________________j6: {"'A'!$A$1:$AH$71","'TOC'!$J$29"}
Name ____________________j8: {#N/A,"SCENARIO2",FALSE,"DirRpts_Sum";#N/A,"SCENARIO2",FALSE,"Exp_Adjmts";#N/A,#N/A,FALSE,"Advtg_Sum"}
Name ____________________PRN2: {"adj95mult",#N/A,FALSE,"COMPCO";"adj95est",#N/A,FALSE,"COMPCO"}
Name ____________________t9: {#N/A,"SCENARIO2",FALSE,"DirRpts_Sum";#N/A,"SCENARIO2",FALSE,"Exp_Adjmts";#N/A,#N/A,FALSE,"Advtg_Sum"}
Name ___________________DCF1: #REF!
Name ___________________PRN2: {"adj95mult",#N/A,FALSE,"COMPCO";"adj95est",#N/A,FALSE,"COMPCO"}
Name __________________DCF1: #REF!
Name __________________PRN2: {"adj95mult",#N/A,FALSE,"COMPCO";"adj95est",#N/A,FALSE,"COMPCO"}
Name __________________T123456: {"COUNT",#N/A,FALSE,"AB"}
Name __________________T12347: {"COUNT",#N/A,FALSE,"AB"}
Name _________________DCF1: #REF!
Name _________________j4: {"Inc_standard",#N/A,TRUE,"Inc"}

Sheet Inputs
B2: Current Month: | C2: 46022

Sheet Cover Page
C17: =TEXT(Inputs!C2,"Mmmm yyyy")&" - Monthly Reporting Pack" -> December 2025 - Monthly Reporting Pack
F19: Confidential

Sheet Narrative
B2: Dispatch | Monthly Operating Narrative
B3: =TEXT(Inputs!C2,"Mmmm yyyy") -> December 2025

Sheet Exec Summary
C2: Dispatch Business Unit | M2: Youreka Business Unit | W2: Consolidated Company
C3: =Inputs!$C$2 -> 46022 | E3: Actual vs Plan | I3: Year over Year | M3: =Inputs!$C$2 -> 46022 | O3: Actual vs Plan | S3: Year over Year | W3: =Inputs!$C$2 -> 46022 | Y3: Actual vs Plan | AC3: Year over Year
C4: Actual | E4: =YEAR(Inputs!$C$2)&" Plan" -> 2025 Plan | F4: Diff($) | G4: Diff (%) | I4: =YEAR(EOMONTH(Inputs!$C$2,-12))&" Actual" -> 2024 Actual | J4: Diff($) | K4: Diff (%) | M4: Actual | O4: =YEAR(Inputs!$C$2)&" Plan" -> 2025 Plan | P4: Diff($) | Q4: Diff (%) | S4: =YEAR(EOMONTH(Inputs!$C$2,-12))&" Actual" -> 2024 Actual | T4: Diff($) | U4: Diff (%) | W4: Actual | Y4: =YEAR(Inputs!$C$2)&" Plan" -> 2025 Plan | Z4: Diff($) | AA4: Diff (%) | AC4: =YEAR(EOMONTH(Inputs!$C$2,-12))&" Actual" -> 2024 Actual | AD4: Diff($) | AE4: Diff (%)
B5: Revenue
B6: Recurring | C6: ='1a. Dispatch Functional P&L'!E11 -> 1121015.8 | E6: ='1a. Dispatch Functional P&L'!F11 -> 1200544.9 | F6: =IFERROR(C6-E6,"N/A") -> -79529.093 | G6: =IFERROR(C6/E6-1,"N/A") -> -0.066244161 | I6: ='1a. Dispatch Functional P&L'!P11 -> 1070609 | J6: =IFERROR(C6-I6,"N/A") -> 50406.84 | K6: =IFERROR(C6/I6-1,"N/A") -> 0.047082398 | M6: ='1b. Youreka Functional P&L'!E11 -> 993864.86 | O6: ='1b. Youreka Functional P&L'!F11 -> 1080660.7 | P6: =IFERROR(M6-O6,"N/A") -> -86795.881 | Q6: =IFERROR(M6/O6-1,"N/A") -> -0.080317418 | S6: ='1b. Youreka Functional P&L'!P11 -> 865103.75 | T6: =IFERROR(M6-S6,"N/A") -> 128761.11 | U6: =IFERROR(M6/S6-1,"N/A") -> 0.14883892 | W6: =C6+M6 -> 2114880.7 | Y6: =IFERROR(E6+O6,"N/A") -> 2281205.7 | Z6: =IFERROR(W6-Y6,"N/A") -> -166324.97 | AA6: =IFERROR(W6/Y6-1,"N/A") -> -0.072910994 | AC6: =I6+S6 -> 1935712.8 | AD6: =IFERROR(W6-AC6,"N/A") -> 179167.95 | AE6: =IFERROR(W6/AC6-1,"N/A") -> 0.092559162
B7: Non-recurring | C7: ='1a. Dispatch Functional P&L'!E15 -> 26500 | E7: ='1a. Dispatch Functional P&L'!F15 -> 28666.667 | F7: =IFERROR(C7-E7,"N/A") -> -2166.6667 | G7: =IFERROR(C7/E7-1,"N/A") -> -0.075581395 | I7: ='1a. Dispatch Functional P&L'!P15 -> 31999 | J7: =IFERROR(C7-I7,"N/A") -> -5499 | K7: =IFERROR(C7/I7-1,"N/A") -> -0.17184912 | M7: ='1b. Youreka Functional P&L'!E15 -> 22500 | O7: ='1b. Youreka Functional P&L'!F15 -> 10583.333 | P7: =IFERROR(M7-O7,"N/A") -> 11916.667 | Q7: =IFERROR(M7/O7-1,"N/A") -> 1.1259843 | S7: ='1b. Youreka Functional P&L'!P15 -> 37019.05 | T7: =IFERROR(M7-S7,"N/A") -> -14519.05 | U7: =IFERROR(M7/S7-1,"N/A") -> -0.39220482 | W7: =C7+M7 -> 49000 | Y7: =IFERROR(E7+O7,"N/A") -> 39250 | Z7: =IFERROR(W7-Y7,"N/A") -> 9750 | AA7: =IFERROR(W7/Y7-1,"N/A") -> 0.24840764 | AC7: =I7+S7 -> 69018.05 | AD7: =IFERROR(W7-AC7,"N/A") -> -20018.05 | AE7: =IFERROR(W7/AC7-1,"N/A") -> -0.29004079
B8: Total | C8: =SUM(C6:C7) -> 1147515.8 | E8: ='1a. Dispatch Functional P&L'!F16 -> 1229211.6 | F8: =IFERROR(C8-E8,"N/A") -> -81695.759 | G8: =IFERROR(C8/E8-1,"N/A") -> -0.066461917 | I8: =SUM(I6:I7) -> 1102608 | J8: =IFERROR(C8-I8,"N/A") -> 44907.84 | K8: =IFERROR(C8/I8-1,"N/A") -> 0.040728745 | M8: =SUM(M6:M7) -> 1016364.9 | O8: ='1b. Youreka Functional P&L'!F16 -> 1091244.1 | P8: =IFERROR(M8-O8,"N/A") -> -74879.214 | Q8: =IFERROR(M8/O8-1,"N/A") -> -0.068618209 | S8: =SUM(S6:S7) -> 902122.8 | T8: =IFERROR(M8-S8,"N/A") -> 114242.06 | U8: =IFERROR(M8/S8-1,"N/A") -> 0.12663693 | W8: =SUM(W6:W7) -> 2163880.7 | Y8: =IFERROR(E8+O8,"N/A") -> 2320455.7 | Z8: =IFERROR(W8-Y8,"N/A") -> -156574.97 | AA8: =IFERROR(W8/Y8-1,"N/A") -> -0.067475959 | AC8: =SUM(AC6:AC7) -> 2004730.8 | AD8: =IFERROR(W8-AC8,"N/A") -> 159149.9 | AE8: =IFERROR(W8/AC8-1,"N/A") -> 0.079387167
B9: % Reccurring Revenue | C9: =C6/C8 -> 0.97690664 | E9: =IFERROR(E6/E8,"N/A") -> 0.97667882 | I9: =I6/I8 -> 0.97097881 | M9: =M6/M8 -> 0.97786228 | O9: =IFERROR(O6/O8,"N/A") -> 0.99030159 | S9: =S6/S8 -> 0.95896451 | W9: =W6/W8 -> 0.9773555 | Y9: =IFERROR(Y6/Y8,"N/A") -> 0.98308522 | AC9: =AC6/AC8 -> 0.96557241
B11: Gross Profit ($) | C11: ='1a. Dispatch Functional P&L'!E32 -> 936897.54 | E11: ='1a. Dispatch Functional P&L'!F32 -> 1034875.5 | F11: =IFERROR(C11-E11,"N/A") -> -97977.98 | G11: =IFERROR(C11/E11-1,"N/A") -> -0.094676102 | I11: ='1a. Dispatch Functional P&L'!P32 -> 911795.62 | J11: =IFERROR(C11-I11,"N/A") -> 25101.92 | K11: =IFERROR(C11/I11-1,"N/A") -> 0.027530205 | M11: ='1b. Youreka Functional P&L'!E32 -> 763128.94 | O11: ='1b. Youreka Functional P&L'!F32 -> 834901.58 | P11: =IFERROR(M11-O11,"N/A") -> -71772.644 | Q11: =IFERROR(M11/O11-1,"N/A") -> -0.085965394 | S11: ='1b. Youreka Functional P&L'!P32 -> 669606.17 | T11: =IFERROR(M11-S11,"N/A") -> 93522.77 | U11: =IFERROR(M11/S11-1,"N/A") -> 0.13966832 | W11: =C11+M11 -> 1700026.5 | Y11: =IFERROR(E11+O11,"N/A") -> 1869777.1 | Z11: =IFERROR(W11-Y11,"N/A") -> -169750.62 | AA11: =IFERROR(W11/Y11-1,"N/A") -> -0.090786556 | AC11: =I11+S11 -> 1581401.8 | AD11: =IFERROR(W11-AC11,"N/A") -> 118624.69 | AE11: =IFERROR(W11/AC11-1,"N/A") -> 0.075012366
B12: Gross Profit (%) | C12: =C11/C8 -> 0.81645717 | E12: =IFERROR(E11/E8,"N/A") -> 0.84190184 | G12: =C12-E12 -> -0.025444677 | I12: =I11/I8 -> 0.82694449 | K12: =C12-I12 -> -0.010487324 | M12: =M11/M8 -> 0.75084152 | O12: =IFERROR(O11/O8,"N/A") -> 0.76509152 | Q12: =M12-O12 -> -0.014249993 | S12: =S11/S8 -> 0.74225612 | U12: =M12-S12 -> 0.0085854028 | W12: =W11/W8 -> 0.7856378 | Y12: =Y11/Y8 -> 0.80578014 | AA12: =W12-Y12 -> -0.02014234 | AC12: =AC11/AC8 -> 0.78883498 | AE12: =W12-AC12 -> -0.003197181
B14: EBITDA ($) | C14: ='1a. Dispatch Functional P&L'!E84 -> 246778.48 | E14: ='1a. Dispatch Functional P&L'!F84 -> 98053.145 | F14: =IFERROR(C14-E14,"N/A") -> 148725.34 | G14: =IFERROR(C14/E14-1,"N/A") -> 1.5167829 | I14: ='1a. Dispatch Functional P&L'!P84 -> 11013.611 | J14: =IFERROR(C14-I14,"N/A") -> 235764.87 | K14: =IFERROR(C14/I14-1,"N/A") -> 21.406682 | M14: ='1b. Youreka Functional P&L'!E84 -> 355001.73 | O14: ='1b. Youreka Functional P&L'!F84 -> 266928.82 | P14: =IFERROR(M14-O14,"N/A") -> 88072.914 | Q14: =IFERROR(M14/O14-1,"N/A") -> 0.32994907 | S14: ='1b. Youreka Functional P&L'!P84 -> 133318.06 | T14: =IFERROR(M14-S14,"N/A") -> 221683.67 | U14: =IFERROR(M14/S14-1,"N/A") -> 1.662818 | W14: =C14+M14 -> 601780.21 | Y14: =IFERROR(E14+O14,"N/A") -> 364981.96 | Z14: =IFERROR(W14-Y14,"N/A") -> 236798.25 | AA14: =IFERROR(W14/Y14-1,"N/A") -> 0.64879439 | AC14: =I14+S14 -> 144331.67 | AD14: =IFERROR(W14-AC14,"N/A") -> 457448.54 | AE14: =IFERROR(W14/AC14-1,"N/A") -> 3.1694259
B15: EBITDA (%) | C15: =C14/C8 -> 0.21505453 | E15: =IFERROR(E14/E8,"N/A") -> 0.079769134 | I15: =I14/I8 -> 0.0099886912 | M15: =M14/M8 -> 0.34928572 | O15: =IFERROR(O14/O8,"N/A") -> 0.24460964 | S15: =S14/S8 -> 0.14778261 | W15: =W14/W8 -> 0.2781023 | Y15: =Y14/Y8 -> 0.15728892 | AC15: =AC14/AC8 -> 0.071995537
B17: Cash Balance | C17: ='Dispatch BS-Monthly'!Q8 -> 47713.25 | E17: =INDEX('Dispatch CF-Monthly'!$AI$66:$AU$66,MATCH($C$3,'Dispatch CF-Monthly'!$AI$5:$AU$5,0)) -> -3532586.7 | F17: =IFERROR(C17-E17,"N/A") -> 3580299.9 | G17: =IFERROR(C17/E17-1,"N/A") -> -1.0135066 | I17: ='3. Balance Sheet'!I9 -> 489889.18 | J17: =IFERROR(C17-I17,"N/A") -> -442175.93 | K17: =IFERROR(C17/I17-1,"N/A") -> -0.90260399 | M17: ='Youreka BS-Monthly'!Q8 -> 46955.58 | O17: =INDEX('Youreka CF-Monthly'!$AI$66:$AU$66,MATCH($C$3,'Youreka CF-Monthly'!$AI$5:$AU$5,0)) -> 4059401.8 | P17: =IFERROR(M17-O17,"N/A") -> -4012446.2 | Q17: =IFERROR(M17/O17-1,"N/A") -> -0.98843288 | S17: ='3. Balance Sheet'!I9 -> 489889.18 | T17: =IFERROR(M17-S17,"N/A") -> -442933.6 | U17: =IFERROR(M17/S17-1,"N/A") -> -0.90415061 | W17: =C17+M17 -> 94668.83 | Y17: =IFERROR(E17+O17,"N/A") -> 526815.12 | Z17: =IFERROR(W17-Y17,"N/A") -> -432146.29 | AA17: =IFERROR(W17/Y17-1,"N/A") -> -0.82029971 | AC17: =I17+S17 -> 979778.36 | AD17: =IFERROR(W17-AC17,"N/A") -> -885109.53 | AE17: =IFERROR(W17/AC17-1,"N/A") -> -0.9033773
B18: Debt Balance | C18: ='Dispatch BS-Monthly'!Q49 -> 53483000 | E18: =INDEX('Dispatch BS-Monthly'!$AI$49:$AU$49,MATCH(C3,'Dispatch BS-Monthly'!$AI$5:$AU$5,0)) -> 48325271 | F18: =IFERROR(C18-E18,"N/A") -> 5157729 | G18: =IFERROR(C18/E18-1,"N/A") -> 0.10672944 | I18: ='3. Balance Sheet'!I50 -> 52158000 | J18: =IFERROR(C18-I18,"N/A") -> 1325000 | K18: =IFERROR(C18/I18-1,"N/A") -> 0.025403581 | W18: =C18+M18 -> 53483000 | Y18: =IFERROR(E18+O18,"N/A") -> 48325271 | Z18: =IFERROR(W18-Y18,"N/A") -> 5157729 | AA18: =IFERROR(W18/Y18-1,"N/A") -> 0.10672944 | AC18: =I18+S18 -> 52158000 | AD18: =IFERROR(W18-AC18,"N/A") -> 1325000 | AE18: =IFERROR(W18/AC18-1,"N/A") -> 0.025403581
B20: Enterprise collections | C20: ='Dispatch Payments'!F16 -> 215777.79 | E20: List | M20: ='Youreka Payments'!E19 -> 761145 | O20: List | W20: =M20+C20 -> 976922.79
B22: Live ARR3 | C22: =INDEX('6. Snowball'!$L$51:$W$51,MATCH(C$3,'6. Snowball'!$L$8:$W$8,0)) -> 13452190 | E22: =INDEX('6. Snowball'!$AH$51:$AS$51,MATCH(C$3,'6. Snowball'!$AH$8:$AS$8,0)) -> 14406539 | F22: =IFERROR(C22-E22,"N/A") -> -954349.4 | G22: =IFERROR(C22/E22-1,"N/A") -> -0.066244181 | I22: =I6*12 -> 12847308 | J22: =IFERROR(C22-I22,"N/A") -> 604881.79 | K22: =IFERROR(C22/I22-1,"N/A") -> 0.047082376 | M22: {=INDEX('6. Snowball'!$L$81:$W$81,MATCH(M$3,'6. Snowball'!$L$8:$W$8,0))} -> 11797002 | O22: =INDEX('6. Snowball'!$AH$81:$AS$81,MATCH(M$3,'6. Snowball'!$AH$8:$AS$8,0)) -> 12967929 | P22: =IFERROR(M22-O22,"N/A") -> -1170927 | Q22: =IFERROR(M22/O22-1,"N/A") -> -0.090294061 | S22: =S6*12 -> 10381245 | T22: =IFERROR(M22-S22,"N/A") -> 1415756.9 | U22: =IFERROR(M22/S22-1,"N/A") -> 0.13637641 | W22: =M22+C22 -> 25249192 | Y22: =IFERROR(E22+O22,"N/A") -> 27374468 | Z22: =IFERROR(W22-Y22,"N/A") -> -2125276.4 | AA22: =IFERROR(W22/Y22-1,"N/A") -> -0.077637174 | AC22: =I22+S22 -> 23228553 | AD22: =IFERROR(W22-AC22,"N/A") -> 2020638.7 | AE22: =IFERROR(W22/AC22-1,"N/A") -> 0.086989435
B24: CARR 1 | C24: 13817790 | E24: 15076015 | F24: =IFERROR(C24-E24,"N/A") -> -1258225.2 | G24: =IFERROR(C24/E24-1,"N/A") -> -0.083458742 | I24: 13599013 | J24: =IFERROR(C24-I24,"N/A") -> 218776.54 | K24: =IFERROR(C24/I24-1,"N/A") -> 0.016087678 | M24: 11868188 | O24: 13943297 | P24: =IFERROR(M24-O24,"N/A") -> -2075108.6 | Q24: =IFERROR(M24/O24-1,"N/A") -> -0.14882481 | S24: 11974733 | T24: =IFERROR(M24-S24,"N/A") -> -106544.44 | U24: =IFERROR(M24/S24-1,"N/A") -> -0.0088974382 | W24: =M24+C24 -> 25685978 | Y24: =IFERROR(E24+O24,"N/A") -> 29019312 | Z24: =IFERROR(W24-Y24,"N/A") -> -3333333.8 | AA24: =IFERROR(W24/Y24-1,"N/A") -> -0.11486605 | AC24: =I24+S24 -> 25573746 | AD24: =IFERROR(W24-AC24,"N/A") -> 112232.1 | AE24: =IFERROR(W24/AC24-1,"N/A") -> 0.0043885669
B25: Max ARR 2 | C25: 13971474 | I25: 13812253 | J25: =IFERROR(C25-I25,"N/A") -> 159221.58 | K25: =IFERROR(C25/I25-1,"N/A") -> 0.011527561 | M25: TBD | S25: TBD | T25: =IFERROR(M25-S25,"N/A") -> N/A | U25: =IFERROR(M25/S25-1,"N/A") -> N/A | W25: =IFERROR(M25+C25,"N/A") -> N/A | AC25: =IFERROR(S25+I25,"N/A") -> N/A | AD25: =IFERROR(W25-AC25,"N/A") -> N/A | AE25: =IFERROR(W25/AC25-1,"N/A") -> N/A
B28: 1 Contracted ARR scheduled to go live in the next 12 months
B29: 2 Includes all contractual step ups, regardless of timing, and assumes 100% renewal rate

Sheet 1. Consolidated Functional P&L
C1: Dispatch | Monthly Profit & Loss (Functional View)
E4: Current Month | J4: Year-to-Date | O4: Year-over-Year
U5: Current Month | X5: YTD | AA5: YoY
C6: Revenue | E6: =Inputs!C2 -> 46022 | F6: Budget | G6: Difference | H6: % Difference | J6: =E6 -> 46022 | K6: Budget | L6: Difference | M6: % Difference | O6: =J6 -> 46022 | P6: =EOMONTH(E6,-12) -> 45657 | Q6: Difference | R6: % Difference | U6: Checks | X6: Checks | AA6: Checks
C7: Recurring Revenue
C8: Recurring Enterprise License Revenue | E8: ='1a. Dispatch Functional P&L'!E8+'1b. Youreka Functional P&L'!E8 -> 1886430.2 | F8: ='1a. Dispatch Functional P&L'!F8+'1b. Youreka Functional P&L'!F8 -> 2054472.9 | G8: =IFERROR(E8-F8,"N/A") -> -168042.7 | H8: =IFERROR((E8/F8-1),"N/A") -> -0.081793584 | J8: ='1a. Dispatch Functional P&L'!J8+'1b. Youreka Functional P&L'!J8 -> 22220506 | K8: ='1a. Dispatch Functional P&L'!K8+'1b. Youreka Functional P&L'!K8 -> 23068278 | L8: =IFERROR(J8-K8,"N/A") -> -847772.07 | M8: =IFERROR((J8/K8-1),"N/A") -> -0.036750557 | O8: ='1a. Dispatch Functional P&L'!O8+'1b. Youreka Functional P&L'!O8 -> 1886430.2 | P8: ='1a. Dispatch Functional P&L'!P8+'1b. Youreka Functional P&L'!P8 -> 1736049.1 | Q8: =O8-P8 -> 150381.11 | R8: =IFERROR((O8/P8-1),"N/A") -> 0.086622615
C9: Recurring Services Revenue | E9: ='1a. Dispatch Functional P&L'!E9+'1b. Youreka Functional P&L'!E9 -> 132806.87 | F9: ='1a. Dispatch Functional P&L'!F9+'1b. Youreka Functional P&L'!F9 -> 118739.5 | G9: =IFERROR(E9-F9,"N/A") -> 14067.368 | H9: =IFERROR((E9/F9-1),"N/A") -> 0.11847252 | J9: ='1a. Dispatch Functional P&L'!J9+'1b. Youreka Functional P&L'!J9 -> 1534400.6 | K9: ='1a. Dispatch Functional P&L'!K9+'1b. Youreka Functional P&L'!K9 -> 1423624 | L9: =IFERROR(J9-K9,"N/A") -> 110776.62 | M9: =IFERROR((J9/K9-1),"N/A") -> 0.077813115 | O9: ='1a. Dispatch Functional P&L'!O9+'1b. Youreka Functional P&L'!O9 -> 132806.87 | P9: ='1a. Dispatch Functional P&L'!P9+'1b. Youreka Functional P&L'!P9 -> 107855.4 | Q9: =O9-P9 -> 24951.47 | R9: =IFERROR((O9/P9-1),"N/A") -> 0.23134187
C10: Recurring Service Provider (SMB) Revenue | E10: ='1a. Dispatch Functional P&L'!E10+'1b. Youreka Functional P&L'!E10 -> 95643.67 | F10: ='1a. Dispatch Functional P&L'!F10+'1b. Youreka Functional P&L'!F10 -> 107993.31 | G10: =IFERROR(E10-F10,"N/A") -> -12349.642 | H10: =IFERROR((E10/F10-1),"N/A") -> -0.11435562 | J10: ='1a. Dispatch Functional P&L'!J10+'1b. Youreka Functional P&L'!J10 -> 1158666.8 | K10: ='1a. Dispatch Functional P&L'!K10+'1b. Youreka Functional P&L'!K10 -> 1217243.8 | L10: =IFERROR(J10-K10,"N/A") -> -58577.008 | M10: =IFERROR((J10/K10-1),"N/A") -> -0.048122658 | O10: ='1a. Dispatch Functional P&L'!O10+'1b. Youreka Functional P&L'!O10 -> 95643.67 | P10: ='1a. Dispatch Functional P&L'!P10+'1b. Youreka Functional P&L'!P10 -> 91808.3 | Q10: =O10-P10 -> 3835.37 | R10: =IFERROR((O10/P10-1),"N/A") -> 0.041775853
C11: Total Recurring Revenue | E11: ='1a. Dispatch Functional P&L'!E11+'1b. Youreka Functional P&L'!E11 -> 2114880.7 | F11: ='1a. Dispatch Functional P&L'!F11+'1b. Youreka Functional P&L'!F11 -> 2281205.7 | G11: =IFERROR(E11-F11,"N/A") -> -166324.97 | H11: =IFERROR((E11/F11-1),"N/A") -> -0.072910994 | J11: ='1a. Dispatch Functional P&L'!J11+'1b. Youreka Functional P&L'!J11 -> 24913573 | K11: ='1a. Dispatch Functional P&L'!K11+'1b. Youreka Functional P&L'!K11 -> 25709146 | L11: =IFERROR(J11-K11,"N/A") -> -795572.46 | M11: =IFERROR((J11/K11-1),"N/A") -> -0.030945115 | O11: ='1a. Dispatch Functional P&L'!O11+'1b. Youreka Functional P&L'!O11 -> 2114880.7 | P11: ='1a. Dispatch Functional P&L'!P11+'1b. Youreka Functional P&L'!P11 -> 1935712.8 | Q11: =O11-P11 -> 179167.95 | R11: =IFERROR((O11/P11-1),"N/A") -> 0.092559162 | U11: =SUM(E8:E10)-E11 -> 0 | V11: =SUM(F8:F10)-F11 -> 0 | X11: =SUM(J8:J10)-J11 -> 0 | Y11: =SUM(K8:K10)-K11 -> 0 | AA11: =SUM(O8:O10)-O11 -> 0 | AB11: =SUM(P8:P10)-P11 -> 0
C12: Non-Recurring Revenue
C13: Non-Recurring Professional Services Revenue | E13: ='1a. Dispatch Functional P&L'!E13+'1b. Youreka Functional P&L'!E13 -> 49000 | F13: ='1a. Dispatch Functional P&L'!F13+'1b. Youreka Functional P&L'!F13 -> 39250 | G13: =IFERROR(E13-F13,"N/A") -> 9750 | H13: =IFERROR((E13/F13-1),"N/A") -> 0.24840764 | J13: ='1a. Dispatch Functional P&L'!J13+'1b. Youreka Functional P&L'!J13 -> 772519.96 | K13: ='1a. Dispatch Functional P&L'!K13+'1b. Youreka Functional P&L'!K13 -> 506416.67 | L13: =IFERROR(J13-K13,"N/A") -> 266103.29 | M13: =IFERROR((J13/K13-1),"N/A") -> 0.52546314 | O13: ='1a. Dispatch Functional P&L'!O13+'1b. Youreka Functional P&L'!O13 -> 49000 | P13: ='1a. Dispatch Functional P&L'!P13+'1b. Youreka Functional P&L'!P13 -> 69018.05 | Q13: =O13-P13 -> -20018.05 | R13: =IFERROR((O13/P13-1),"N/A") -> -0.29004079
C14: Other Non-Recurring Revenue | E14: ='1a. Dispatch Functional P&L'!E14+'1b. Youreka Functional P&L'!E14 -> 0 | F14: ='1a. Dispatch Functional P&L'!F14+'1b. Youreka Functional P&L'!F14 -> 0 | G14: =IFERROR(E14-F14,"N/A") -> 0 | H14: =IFERROR((E14/F14-1),"N/A") -> N/A | J14: ='1a. Dispatch Functional P&L'!J14+'1b. Youreka Functional P&L'!J14 -> 0 | K14: ='1a. Dispatch Functional P&L'!K14+'1b. Youreka Functional P&L'!K14 -> 0 | L14: =IFERROR(J14-K14,"N/A") -> 0 | M14: =IFERROR((J14/K14-1),"N/A") -> N/A | O14: ='1a. Dispatch Functional P&L'!O14+'1b. Youreka Functional P&L'!O14 -> 0 | P14: ='1a. Dispatch Functional P&L'!P14+'1b. Youreka Functional P&L'!P14 -> 0 | Q14: =O14-P14 -> 0 | R14: =IFERROR((O14/P14-1),"N/A") -> N/A
C15: Total Non-Recurring Revenue | E15: ='1a. Dispatch Functional P&L'!E15+'1b. Youreka Functional P&L'!E15 -> 49000 | F15: ='1a. Dispatch Functional P&L'!F15+'1b. Youreka Functional P&L'!F15 -> 39250 | G15: =IFERROR(E15-F15,"N/A") -> 9750 | H15: =IFERROR((E15/F15-1),"N/A") -> 0.24840764 | J15: ='1a. Dispatch Functional P&L'!J15+'1b. Youreka Functional P&L'!J15 -> 772519.96 | K15: ='1a. Dispatch Functional P&L'!K15+'1b. Youreka Functional P&L'!K15 -> 506416.67 | L15: =IFERROR(J15-K15,"N/A") -> 266103.29 | M15: =IFERROR((J15/K15-1),"N/A") -> 0.52546314 | O15: ='1a. Dispatch Functional P&L'!O15+'1b. Youreka Functional P&L'!O15 -> 49000 | P15: ='1a. Dispatch Functional P&L'!P15+'1b. Youreka Functional P&L'!P15 -> 69018.05 | Q15: =O15-P15 -> -20018.05 | R15: =IFERROR((O15/P15-1),"N/A") -> -0.29004079 | U15: =SUM(E13:E14)-E15 -> 0 | V15: =SUM(F13:F14)-F15 -> 0 | X15: =SUM(J13:J14)-J15 -> 0 | Y15: =SUM(K13:K14)-K15 -> 0 | AA15: =SUM(O13:O14)-O15 -> 0 | AB15: =SUM(P13:P14)-P15 -> 0
C16: Total Revenue | E16: ='1a. Dispatch Functional P&L'!E16+'1b. Youreka Functional P&L'!E16 -> 2163880.7 | F16: ='1a. Dispatch Functional P&L'!F16+'1b. Youreka Functional P&L'!F16 -> 2320455.7 | G16: =IFERROR(E16-F16,"N/A") -> -156574.97 | H16: =IFERROR((E16/F16-1),"N/A") -> -0.067475959 | J16: ='1a. Dispatch Functional P&L'!J16+'1b. Youreka Functional P&L'!J16 -> 25686093 | K16: ='1a. Dispatch Functional P&L'!K16+'1b. Youreka Functional P&L'!K16 -> 26215562 | L16: =IFERROR(J16-K16,"N/A") -> -529469.17 | M16: =IFERROR((J16/K16-1),"N/A") -> -0.02019675 | O16: ='1a. Dispatch Functional P&L'!O16+'1b. Youreka Functional P&L'!O16 -> 2163880.7 | P16: ='1a. Dispatch Functional P&L'!P16+'1b. Youreka Functional P&L'!P16 -> 2004730.8 | Q16: =O16-P16 -> 159149.9 | R16: =IFERROR((O16/P16-1),"N/A") -> 0.079387167 | U16: =E11+E15-E16 -> 0 | V16: =F11+F15-F16 -> 0 | X16: =J11+J15-J16 -> 0 | Y16: =K11+K15-K16 -> 0 | AA16: =O11+O15-O16 -> 0 | AB16: =P11+P15-P16 -> 0
C17: % Reccurring Revenue | E17: =E11/E16 -> 0.9773555 | F17: =F11/F16 -> 0.98308522 | G17: =IFERROR(E17-F17,"N/A") -> -0.0057297204 | J17: =J11/J16 -> 0.96992458 | K17: =K11/K16 -> 0.98068259 | L17: =IFERROR(J17-K17,"N/A") -> -0.010758011 | O17: =O11/O16 -> 0.9773555 | P17: =P11/P16 -> 0.96557241 | Q17: =O17-P17 -> 0.011783088 | U17: =E11/E16-E17 -> 0 | V17: =F11/F16-F17 -> 0 | X17: =J11/J16-J17 -> 0 | Y17: =K11/K16-K17 -> 0 | AA17: =O11/O16-O17 -> 0 | AB17: =P11/P16-P17 -> 0
C19: Recurring Cost of Sales - Functional
C20: Cost of Sales (Functional) - Direct Compensation (R) | E20: ='1a. Dispatch Functional P&L'!E20+'1b. Youreka Functional P&L'!E20 -> 133217.39 | F20: ='1a. Dispatch Functional P&L'!F20+'1b. Youreka Functional P&L'!F20 -> 123599.11 | G20: =IFERROR(E20-F20,"N/A") -> 9618.2846 | H20: =IFERROR((E20/F20-1),"N/A") -> 0.0778184 | J20: ='1a. Dispatch Functional P&L'!J20+'1b. Youreka Functional P&L'!J20 -> 1575570.4 | K20: ='1a. Dispatch Functional P&L'!K20+'1b. Youreka Functional P&L'!K20 -> 1505275.3 | L20: =IFERROR(J20-K20,"N/A") -> 70295.077 | M20: =IFERROR((J20/K20-1),"N/A") -> 0.04669915 | O20: ='1a. Dispatch Functional P&L'!O20+'1b. Youreka Functional P&L'!O20 -> 133217.39 | P20: ='1a. Dispatch Functional P&L'!P20+'1b. Youreka Functional P&L'!P20 -> 131756.49 | Q20: =O20-P20 -> 1460.9 | R20: =IFERROR((O20/P20-1),"N/A") -> 0.011087879
C21: Cost of Sales (Functional) - Hosting & Infrastructure | E21: ='1a. Dispatch Functional P&L'!E21+'1b. Youreka Functional P&L'!E21 -> 159319.81 | F21: ='1a. Dispatch Functional P&L'!F21+'1b. Youreka Functional P&L'!F21 -> 169122.85 | G21: =IFERROR(E21-F21,"N/A") -> -9803.0355 | H21: =IFERROR((E21/F21-1),"N/A") -> -0.057963994 | J21: ='1a. Dispatch Functional P&L'!J21+'1b. Youreka Functional P&L'!J21 -> 1869794.5 | K21: ='1a. Dispatch Functional P&L'!K21+'1b. Youreka Functional P&L'!K21 -> 1958808.1 | L21: =IFERROR(J21-K21,"N/A") -> -89013.559 | M21: =IFERROR((J21/K21-1),"N/A") -> -0.045442716 | O21: ='1a. Dispatch Functional P&L'!O21+'1b. Youreka Functional P&L'!O21 -> 159319.81 | P21: ='1a. Dispatch Functional P&L'!P21+'1b. Youreka Functional P&L'!P21 -> 145877.6 | Q21: =O21-P21 -> 13442.21 | R21: =IFERROR((O21/P21-1),"N/A") -> 0.092147184
C22: Cost of Sales (Functional) - Software & Subscriptions | E22: ='1a. Dispatch Functional P&L'!E22+'1b. Youreka Functional P&L'!E22 -> 60407.04 | F22: ='1a. Dispatch Functional P&L'!F22+'1b. Youreka Functional P&L'!F22 -> 60127.688 | G22: =IFERROR(E22-F22,"N/A") -> 279.3525 | H22: =IFERROR((E22/F22-1),"N/A") -> 0.0046459878 | J22: ='1a. Dispatch Functional P&L'!J22+'1b. Youreka Functional P&L'!J22 -> 736470.03 | K22: ='1a. Dispatch Functional P&L'!K22+'1b. Youreka Functional P&L'!K22 -> 751768.25 | L22: =IFERROR(J22-K22,"N/A") -> -15298.22 | M22: =IFERROR((J22/K22-1),"N/A") -> -0.020349649 | O22: ='1a. Dispatch Functional P&L'!O22+'1b. Youreka Functional P&L'!O22 -> 60407.04 | P22: ='1a. Dispatch Functional P&L'!P22+'1b. Youreka Functional P&L'!P22 -> 58677.8 | Q22: =O22-P22 -> 1729.24 | R22: =IFERROR((O22/P22-1),"N/A") -> 0.029470089
C23: Total Recurring Cost of Sales - Functional | E23: ='1a. Dispatch Functional P&L'!E23+'1b. Youreka Functional P&L'!E23 -> 352944.24 | F23: ='1a. Dispatch Functional P&L'!F23+'1b. Youreka Functional P&L'!F23 -> 352849.64 | G23: =IFERROR(E23-F23,"N/A") -> 94.601564 | H23: =IFERROR((E23/F23-1),"N/A") -> 0.0002681073 | J23: ='1a. Dispatch Functional P&L'!J23+'1b. Youreka Functional P&L'!J23 -> 4181834.9 | K23: ='1a. Dispatch Functional P&L'!K23+'1b. Youreka Functional P&L'!K23 -> 4215851.6 | L23: =IFERROR(J23-K23,"N/A") -> -34016.702 | M23: =IFERROR((J23/K23-1),"N/A") -> -0.0080687618 | O23: ='1a. Dispatch Functional P&L'!O23+'1b. Youreka Functional P&L'!O23 -> 352944.24 | P23: ='1a. Dispatch Functional P&L'!P23+'1b. Youreka Functional P&L'!P23 -> 336311.89 | Q23: =O23-P23 -> 16632.35 | R23: =IFERROR((O23/P23-1),"N/A") -> 0.049455135 | U23: =SUM(E20:E22)-E23 -> 0 | V23: =SUM(F20:F22)-F23 -> 0 | X23: =SUM(J20:J22)-J23 -> 0 | Y23: =SUM(K20:K22)-K23 -> 0 | AA23: =SUM(O20:O22)-O23 -> 0 | AB23: =SUM(P20:P22)-P23 -> 0
C24: Non-recurring Cost of Sales - Functional
C25: Cost of Sales (Functional) - Consultants & Contractors | E25: ='1a. Dispatch Functional P&L'!E25+'1b. Youreka Functional P&L'!E25 -> 10632.75 | F25: ='1a. Dispatch Functional P&L'!F25+'1b. Youreka Functional P&L'!F25 -> 0 | G25: =IFERROR(E25-F25,"N/A") -> 10632.75 | H25: =IFERROR((E25/F25-1),"N/A") -> N/A | J25: ='1a. Dispatch Functional P&L'!J25+'1b. Youreka Functional P&L'!J25 -> 51263.75 | K25: ='1a. Dispatch Functional P&L'!K25+'1b. Youreka Functional P&L'!K25 -> 0 | L25: =IFERROR(J25-K25,"N/A") -> 51263.75 | M25: =IFERROR((J25/K25-1),"N/A") -> N/A | O25: ='1a. Dispatch Functional P&L'!O25+'1b. Youreka Functional P&L'!O25 -> 10632.75 | P25: ='1a. Dispatch Functional P&L'!P25+'1b. Youreka Functional P&L'!P25 -> 0 | Q25: =O25-P25 -> 10632.75 | R25: =IFERROR((O25/P25-1),"N/A") -> N/A
C26: Cost of Sales (Functional) - Direct Compensation (NR) | E26: ='1a. Dispatch Functional P&L'!E26+'1b. Youreka Functional P&L'!E26 -> 100277.24 | F26: ='1a. Dispatch Functional P&L'!F26+'1b. Youreka Functional P&L'!F26 -> 97828.941 | G26: =IFERROR(E26-F26,"N/A") -> 2448.2991 | H26: =IFERROR((E26/F26-1),"N/A") -> 0.025026327 | J26: ='1a. Dispatch Functional P&L'!J26+'1b. Youreka Functional P&L'!J26 -> 1192046.8 | K26: ='1a. Dispatch Functional P&L'!K26+'1b. Youreka Functional P&L'!K26 -> 1162277.6 | L26: =IFERROR(J26-K26,"N/A") -> 29769.212 | M26: =IFERROR((J26/K26-1),"N/A") -> 0.025612825 | O26: ='1a. Dispatch Functional P&L'!O26+'1b. Youreka Functional P&L'!O26 -> 100277.24 | P26: ='1a. Dispatch Functional P&L'!P26+'1b. Youreka Functional P&L'!P26 -> 87017.13 | Q26: =O26-P26 -> 13260.11 | R26: =IFERROR((O26/P26-1),"N/A") -> 0.15238505
C27: Total Non-recurring Cost of Sales - Functional | E27: ='1a. Dispatch Functional P&L'!E27+'1b. Youreka Functional P&L'!E27 -> 110909.99 | F27: ='1a. Dispatch Functional P&L'!F27+'1b. Youreka Functional P&L'!F27 -> 97828.941 | G27: =IFERROR(E27-F27,"N/A") -> 13081.049 | H27: =IFERROR((E27/F27-1),"N/A") -> 0.13371349 | J27: ='1a. Dispatch Functional P&L'!J27+'1b. Youreka Functional P&L'!J27 -> 1243310.6 | K27: ='1a. Dispatch Functional P&L'!K27+'1b. Youreka Functional P&L'!K27 -> 1162277.6 | L27: =IFERROR(J27-K27,"N/A") -> 81032.962 | M27: =IFERROR((J27/K27-1),"N/A") -> 0.069719112 | O27: ='1a. Dispatch Functional P&L'!O27+'1b. Youreka Functional P&L'!O27 -> 110909.99 | P27: ='1a. Dispatch Functional P&L'!P27+'1b. Youreka Functional P&L'!P27 -> 87017.13 | Q27: =O27-P27 -> 23892.86 | R27: =IFERROR((O27/P27-1),"N/A") -> 0.27457651 | U27: =E27-E26-E25 -> 0 | V27: =F27-F26 -> 0 | X27: =J27-J26-J25 -> 0 | Y27: =K27-K26 -> 0 | AA27: =O27-O26-O25 -> 0 | AB27: =P27-P26 -> 0
C28: Total Cost of Sales - Functional | E28: ='1a. Dispatch Functional P&L'!E28+'1b. Youreka Functional P&L'!E28 -> 463854.23 | F28: ='1a. Dispatch Functional P&L'!F28+'1b. Youreka Functional P&L'!F28 -> 450678.58 | G28: =IFERROR(E28-F28,"N/A") -> 13175.651 | H28: =IFERROR((E28/F28-1),"N/A") -> 0.029235138 | J28: ='1a. Dispatch Functional P&L'!J28+'1b. Youreka Functional P&L'!J28 -> 5425145.5 | K28: ='1a. Dispatch Functional P&L'!K28+'1b. Youreka Functional P&L'!K28 -> 5378129.2 | L28: =IFERROR(J28-K28,"N/A") -> 47016.26 | M28: =IFERROR((J28/K28-1),"N/A") -> 0.0087421217 | O28: ='1a. Dispatch Functional P&L'!O28+'1b. Youreka Functional P&L'!O28 -> 463854.23 | P28: ='1a. Dispatch Functional P&L'!P28+'1b. Youreka Functional P&L'!P28 -> 423329.02 | Q28: =O28-P28 -> 40525.21 | R28: =IFERROR((O28/P28-1),"N/A") -> 0.095729818 | U28: =E28-E27-E23 -> 0 | V28: =F28-F27-F23 -> 0 | X28: =J28-J27-J23 -> 0 | Y28: =K28-K27-K23 -> 0 | AA28: =O28-O27-O23 -> 0 | AB28: =P28-P27-P23 -> 0
C29: Gross Profit - Functional
C30: Recurring Gross Profit - Functional | E30: ='1a. Dispatch Functional P&L'!E30+'1b. Youreka Functional P&L'!E30 -> 1761936.5 | F30: ='1a. Dispatch Functional P&L'!F30+'1b. Youreka Functional P&L'!F30 -> 1928356 | G30: =IFERROR(E30-F30,"N/A") -> -166419.58 | H30: =IFERROR((E30/F30-1),"N/A") -> -0.08630127 | J30: ='1a. Dispatch Functional P&L'!J30+'1b. Youreka Functional P&L'!J30 -> 20731738 | K30: ='1a. Dispatch Functional P&L'!K30+'1b. Youreka Functional P&L'!K30 -> 21493294 | L30: =IFERROR(J30-K30,"N/A") -> -761555.76 | M30: =IFERROR((J30/K30-1),"N/A") -> -0.035432249 | O30: ='1a. Dispatch Functional P&L'!O30+'1b. Youreka Functional P&L'!O30 -> 1761936.5 | P30: ='1a. Dispatch Functional P&L'!P30+'1b. Youreka Functional P&L'!P30 -> 1599400.9 | Q30: =O30-P30 -> 162535.6 | R30: =IFERROR((O30/P30-1),"N/A") -> 0.1016228
C31: Non-recurring Gross Profit - Functional | E31: ='1a. Dispatch Functional P&L'!E31+'1b. Youreka Functional P&L'!E31 -> -61909.99 | F31: ='1a. Dispatch Functional P&L'!F31+'1b. Youreka Functional P&L'!F31 -> -58578.941 | G31: =IFERROR(E31-F31,"N/A") -> -3331.0491 | H31: =IFERROR((E31/F31-1),"N/A") -> 0.056864276 | J31: ='1a. Dispatch Functional P&L'!J31+'1b. Youreka Functional P&L'!J31 -> -470790.61 | K31: ='1a. Dispatch Functional P&L'!K31+'1b. Youreka Functional P&L'!K31 -> -655860.94 | L31: =IFERROR(J31-K31,"N/A") -> 185070.33 | M31: =IFERROR((J31/K31-1),"N/A") -> -0.28217922 | O31: ='1a. Dispatch Functional P&L'!O31+'1b. Youreka Functional P&L'!O31 -> -61909.99 | P31: ='1a. Dispatch Functional P&L'!P31+'1b. Youreka Functional P&L'!P31 -> -17999.08 | Q31: =O31-P31 -> -43910.91 | R31: =IFERROR((O31/P31-1),"N/A") -> 2.4396197
C32: Total Gross Profit - Functional | E32: ='1a. Dispatch Functional P&L'!E32+'1b. Youreka Functional P&L'!E32 -> 1700026.5 | F32: ='1a. Dispatch Functional P&L'!F32+'1b. Youreka Functional P&L'!F32 -> 1869777.1 | G32: =IFERROR(E32-F32,"N/A") -> -169750.62 | H32: =IFERROR((E32/F32-1),"N/A") -> -0.090786556 | J32: ='1a. Dispatch Functional P&L'!J32+'1b. Youreka Functional P&L'!J32 -> 20260948 | K32: ='1a. Dispatch Functional P&L'!K32+'1b. Youreka Functional P&L'!K32 -> 20837433 | L32: =IFERROR(J32-K32,"N/A") -> -576485.43 | M32: =IFERROR((J32/K32-1),"N/A") -> -0.027665856 | O32: ='1a. Dispatch Functional P&L'!O32+'1b. Youreka Functional P&L'!O32 -> 1700026.5 | P32: ='1a. Dispatch Functional P&L'!P32+'1b. Youreka Functional P&L'!P32 -> 1581401.8 | Q32: =O32-P32 -> 118624.69 | R32: =IFERROR((O32/P32-1),"N/A") -> 0.075012366 | U32: =E16-E28-E32 -> 0 | V32: =F16-F28-F32 -> 0 | X32: =J16-J28-J32 -> 0 | Y32: =K16-K28-K32 -> 0 | AA32: =O16-O28-O32 -> 0 | AB32: =P16-P28-P32 -> 0
C33: Recurring Gross Profit Margin % - Functional | E33: =E30/E11 -> 0.83311388 | F33: =F30/F11 -> 0.84532318 | G33: =IFERROR(E33-F33,"N/A") -> -0.012209303 | J33: =J30/J11 -> 0.83214632 | K33: =K30/K11 -> 0.83601744 | L33: =IFERROR(J33-K33,"N/A") -> -0.003871115 | O33: =O30/O11 -> 0.83311388 | P33: =P30/P11 -> 0.8262594 | Q33: =O33-P33 -> 0.0068544748
C34: Non-recurring Gross Profit Margin % - Functional | E34: =E31/E15 -> -1.2634692 | F34: =F31/F15 -> -1.4924571 | G34: =IFERROR(E34-F34,"N/A") -> 0.22898791 | J34: =J31/J15 -> -0.60942194 | K34: =K31/K15 -> -1.2951014 | L34: =IFERROR(J34-K34,"N/A") -> 0.68567948 | O34: =O31/O15 -> -1.2634692 | P34: =P31/P15 -> -0.26078801 | Q34: =O34-P34 -> -1.0026812
C35: Total Gross Profit Margin % - Functional | E35: =E32/E16 -> 0.7856378 | F35: =F32/F16 -> 0.80578014 | G35: =IFERROR(E35-F35,"N/A") -> -0.02014234 | J35: =J32/J16 -> 0.78879056 | K35: =K32/K16 -> 0.79484975 | L35: =IFERROR(J35-K35,"N/A") -> -0.0060591929 | O35: =O32/O16 -> 0.7856378 | P35: =P32/P16 -> 0.78883498 | Q35: =O35-P35 -> -0.003197181 | U35: =E32/E16-E35 -> 0 | V35: =F32/F16-F35 -> 0 | X35: =J32/J16-J35 -> 0 | Y35: =K32/K16-K35 -> 0 | AA35: =O32/O16-O35 -> 0 | AB35: =P32/P16-P35 -> 0
C37: Functional Operating Expenses
C38: Product & Engineering Expense - Functional | E38: ='1a. Dispatch Functional P&L'!E38+'1b. Youreka Functional P&L'!E38 -> 442397.33 | F38: ='1a. Dispatch Functional P&L'!F38+'1b. Youreka Functional P&L'!F38 -> 584826.18 | G38: =IFERROR(E38-F38,"N/A") -> -142428.85 | H38: =IFERROR((E38/F38-1),"N/A") -> -0.24354048 | J38: ='1a. Dispatch Functional P&L'!J38+'1b. Youreka Functional P&L'!J38 -> 6306078.5 | K38: ='1a. Dispatch Functional P&L'!K38+'1b. Youreka Functional P&L'!K38 -> 7248588.7 | L38: =IFERROR(J38-K38,"N/A") -> -942510.15 | M38: =IFERROR((J38/K38-1),"N/A") -> -0.13002671 | O38: ='1a. Dispatch Functional P&L'!O38+'1b. Youreka Functional P&L'!O38 -> 442397.33 | P38: ='1a. Dispatch Functional P&L'!P38+'1b. Youreka Functional P&L'!P38 -> 599255.53 | Q38: =O38-P38 -> -156858.2 | R38: =IFERROR((O38/P38-1),"N/A") -> -0.26175511
C39: General & Administrative Expense - Functional | E39: ='1a. Dispatch Functional P&L'!E39+'1b. Youreka Functional P&L'!E39 -> 242107.56 | F39: ='1a. Dispatch Functional P&L'!F39+'1b. Youreka Functional P&L'!F39 -> 373135.83 | G39: =IFERROR(E39-F39,"N/A") -> -131028.27 | H39: =IFERROR((E39/F39-1),"N/A") -> -0.35115434 | J39: ='1a. Dispatch Functional P&L'!J39+'1b. Youreka Functional P&L'!J39 -> 4183787.8 | K39: ='1a. Dispatch Functional P&L'!K39+'1b. Youreka Functional P&L'!K39 -> 4608003 | L39: =IFERROR(J39-K39,"N/A") -> -424215.24 | M39: =IFERROR((J39/K39-1),"N/A") -> -0.092060538 | O39: ='1a. Dispatch Functional P&L'!O39+'1b. Youreka Functional P&L'!O39 -> 242107.56 | P39: ='1a. Dispatch Functional P&L'!P39+'1b. Youreka Functional P&L'!P39 -> 317762.27 | Q39: =O39-P39 -> -75654.71 | R39: =IFERROR((O39/P39-1),"N/A") -> -0.23808588
C40: Human Resources - Functional | E40: ='1a. Dispatch Functional P&L'!E40+'1b. Youreka Functional P&L'!E40 -> 6591.59 | F40: ='1a. Dispatch Functional P&L'!F40+'1b. Youreka Functional P&L'!F40 -> 11424.583 | G40: =IFERROR(E40-F40,"N/A") -> -4832.9933 | H40: =IFERROR((E40/F40-1),"N/A") -> -0.42303454 | J40: ='1a. Dispatch Functional P&L'!J40+'1b. Youreka Functional P&L'!J40 -> 82432.71 | K40: ='1a. Dispatch Functional P&L'!K40+'1b. Youreka Functional P&L'!K40 -> 116671 | L40: =IFERROR(J40-K40,"N/A") -> -34238.29 | M40: =IFERROR((J40/K40-1),"N/A") -> -0.29346016 | O40: ='1a. Dispatch Functional P&L'!O40+'1b. Youreka Functional P&L'!O40 -> 6591.59 | P40: ='1a. Dispatch Functional P&L'!P40+'1b. Youreka Functional P&L'!P40 -> 7263.65 | Q40: =O40-P40 -> -672.06 | R40: =IFERROR((O40/P40-1),"N/A") -> -0.092523731
C41: Sales Expense - Functional | E41: ='1a. Dispatch Functional P&L'!E41+'1b. Youreka Functional P&L'!E41 -> 346036.59 | F41: ='1a. Dispatch Functional P&L'!F41+'1b. Youreka Functional P&L'!F41 -> 446168.36 | G41: =IFERROR(E41-F41,"N/A") -> -100131.77 | H41: =IFERROR((E41/F41-1),"N/A") -> -0.22442598 | J41: ='1a. Dispatch Functional P&L'!J41+'1b. Youreka Functional P&L'!J41 -> 4626641.5 | K41: ='1a. Dispatch Functional P&L'!K41+'1b. Youreka Functional P&L'!K41 -> 5479382.1 | L41: =IFERROR(J41-K41,"N/A") -> -852740.65 | M41: =IFERROR((J41/K41-1),"N/A") -> -0.15562715 | O41: ='1a. Dispatch Functional P&L'!O41+'1b. Youreka Functional P&L'!O41 -> 346036.59 | P41: ='1a. Dispatch Functional P&L'!P41+'1b. Youreka Functional P&L'!P41 -> 429493.92 | Q41: =O41-P41 -> -83457.33 | R41: =IFERROR((O41/P41-1),"N/A") -> -0.19431551
C42: Marketing Expense - Functional | E42: ='1a. Dispatch Functional P&L'!E42+'1b. Youreka Functional P&L'!E42 -> 61113.21 | F42: ='1a. Dispatch Functional P&L'!F42+'1b. Youreka Functional P&L'!F42 -> 89240.191 | G42: =IFERROR(E42-F42,"N/A") -> -28126.981 | H42: =IFERROR((E42/F42-1),"N/A") -> -0.31518289 | J42: ='1a. Dispatch Functional P&L'!J42+'1b. Youreka Functional P&L'!J42 -> 1041226 | K42: ='1a. Dispatch Functional P&L'!K42+'1b. Youreka Functional P&L'!K42 -> 1245318.9 | L42: =IFERROR(J42-K42,"N/A") -> -204092.84 | M42: =IFERROR((J42/K42-1),"N/A") -> -0.16388802 | O42: ='1a. Dispatch Functional P&L'!O42+'1b. Youreka Functional P&L'!O42 -> 61113.21 | P42: ='1a. Dispatch Functional P&L'!P42+'1b. Youreka Functional P&L'!P42 -> 83294.76 | Q42: =O42-P42 -> -22181.55 | R42: =IFERROR((O42/P42-1),"N/A") -> -0.26630187
C43: Other Functional Operating Expense (incl. D&A) | E43: ='1a. Dispatch Functional P&L'!E43+'1b. Youreka Functional P&L'!E43 -> 1251110.2 | F43: ='1a. Dispatch Functional P&L'!F43+'1b. Youreka Functional P&L'!F43 -> 1241003.5 | G43: =IFERROR(E43-F43,"N/A") -> 10106.684 | H43: =IFERROR((E43/F43-1),"N/A") -> 0.0081439607 | J43: ='1a. Dispatch Functional P&L'!J43+'1b. Youreka Functional P&L'!J43 -> 14975224 | K43: ='1a. Dispatch Functional P&L'!K43+'1b. Youreka Functional P&L'!K43 -> 15092042 | L43: =IFERROR(J43-K43,"N/A") -> -116817.92 | M43: =IFERROR((J43/K43-1),"N/A") -> -0.0077403657 | O43: ='1a. Dispatch Functional P&L'!O43+'1b. Youreka Functional P&L'!O43 -> 1251110.2 | P43: ='1a. Dispatch Functional P&L'!P43+'1b. Youreka Functional P&L'!P43 -> 1304209.1 | Q43: =O43-P43 -> -53098.95 | R43: =IFERROR((O43/P43-1),"N/A") -> -0.040713524
C44: Total - Functional Operating Expenses | E44: ='1a. Dispatch Functional P&L'!E44+'1b. Youreka Functional P&L'!E44 -> 2349356.5 | F44: ='1a. Dispatch Functional P&L'!F44+'1b. Youreka Functional P&L'!F44 -> 2745798.7 | G44: =IFERROR(E44-F44,"N/A") -> -396442.18 | H44: =IFERROR((E44/F44-1),"N/A") -> -0.14438137 | J44: ='1a. Dispatch Functional P&L'!J44+'1b. Youreka Functional P&L'!J44 -> 31215391 | K44: ='1a. Dispatch Functional P&L'!K44+'1b. Youreka Functional P&L'!K44 -> 33790006 | L44: =IFERROR(J44-K44,"N/A") -> -2574615.1 | M44: =IFERROR((J44/K44-1),"N/A") -> -0.076194574 | O44: ='1a. Dispatch Functional P&L'!O44+'1b. Youreka Functional P&L'!O44 -> 2349356.5 | P44: ='1a. Dispatch Functional P&L'!P44+'1b. Youreka Functional P&L'!P44 -> 2741279.3 | Q44: =O44-P44 -> -391922.8 | R44: =IFERROR((O44/P44-1),"N/A") -> -0.14297077 | U44: =SUM(E38:E43)-E44 -> 0 | V44: =SUM(F38:F43)-F44 -> 0 | X44: =SUM(J38:J43)-J44 -> 0 | Y44: =SUM(K38:K43)-K44 -> 0 | AA44: =SUM(O38:O43)-O44 -> 0 | AB44: =SUM(P38:P43)-P44 -> 0
...

Sheet 1a. Dispatch Functional P&L
C1: Dispatch | Monthly Profit & Loss (Functional View)
E4: Current Month | J4: Year-to-Date | O4: Year-over-Year
U5: Current Month | X5: YTD | AA5: YoY
C6: Revenue | E6: =Inputs!C2 -> 46022 | F6: Budget | G6: Difference | H6: % Difference | J6: =E6 -> 46022 | K6: Budget | L6: Difference | M6: % Difference | O6: =J6 -> 46022 | P6: =EOMONTH(E6,-12) -> 45657 | Q6: Difference | R6: % Difference | U6: Checks | X6: Checks | AA6: Checks
C7: Recurring Revenue
C8: Recurring Enterprise License Revenue | E8: ='Dispatch Monthly Func P&L'!Q7 -> 1025372.2 | F8: =INDEX('Dispatch Monthly Func P&L'!$AI7:$AT7,MATCH(EOMONTH(Inputs!$C$2,0),'Dispatch Monthly Func P&L'!$AI$5:$AT$5,0)) -> 1092551.6 | G8: =IFERROR(E8-F8,"N/A") -> -67179.451 | H8: =IFERROR((E8/F8-1),"N/A") -> -0.061488582 | J8: ='Dispatch Monthly Func P&L'!X7 -> 12038585 | K8: ='Dispatch Monthly Func P&L'!AV7 -> 12122794 | L8: =IFERROR(J8-K8,"N/A") -> -84208.692 | M8: =IFERROR((J8/K8-1),"N/A") -> -0.0069463105 | O8: =E8 -> 1025372.2 | P8: ='Dispatch Monthly Func P&L'!$BM7 -> 978384.06 | Q8: =O8-P8 -> 46988.12 | R8: =IFERROR((O8/P8-1),"N/A") -> 0.048026253
C9: Recurring Services Revenue | E9: ='Dispatch Monthly Func P&L'!Q8 -> 0 | F9: =INDEX('Dispatch Monthly Func P&L'!$AI8:$AT8,MATCH(EOMONTH(Inputs!$C$2,0),'Dispatch Monthly Func P&L'!$AI$5:$AT$5,0)) -> 0 | G9: =IFERROR(E9-F9,"N/A") -> 0 | H9: =IFERROR((E9/F9-1),"N/A") -> N/A | J9: ='Dispatch Monthly Func P&L'!X8 -> 0 | K9: ='Dispatch Monthly Func P&L'!AV8 -> 0 | L9: =IFERROR(J9-K9,"N/A") -> 0 | M9: =IFERROR((J9/K9-1),"N/A") -> N/A | O9: =E9 -> 0 | P9: ='Dispatch Monthly Func P&L'!$BM8 -> 416.65 | Q9: =O9-P9 -> -416.65 | R9: =IFERROR((O9/P9-1),"N/A") -> -1
C10: Recurring Service Provider (SMB) Revenue | E10: ='Dispatch Monthly Func P&L'!Q9 -> 95643.67 | F10: =INDEX('Dispatch Monthly Func P&L'!$AI9:$AT9,MATCH(EOMONTH(Inputs!$C$2,0),'Dispatch Monthly Func P&L'!$AI$5:$AT$5,0)) -> 107993.31 | G10: =IFERROR(E10-F10,"N/A") -> -12349.642 | H10: =IFERROR((E10/F10-1),"N/A") -> -0.11435562 | J10: ='Dispatch Monthly Func P&L'!X9 -> 1158666.8 | K10: ='Dispatch Monthly Func P&L'!AV9 -> 1217243.8 | L10: =IFERROR(J10-K10,"N/A") -> -58577.008 | M10: =IFERROR((J10/K10-1),"N/A") -> -0.048122658 | O10: =E10 -> 95643.67 | P10: ='Dispatch Monthly Func P&L'!$BM9 -> 91808.3 | Q10: =O10-P10 -> 3835.37 | R10: =IFERROR((O10/P10-1),"N/A") -> 0.041775853
C11: Total Recurring Revenue | E11: ='Dispatch Monthly Func P&L'!Q10 -> 1121015.8 | F11: =INDEX('Dispatch Monthly Func P&L'!$AI10:$AT10,MATCH(EOMONTH(Inputs!$C$2,0),'Dispatch Monthly Func P&L'!$AI$5:$AT$5,0)) -> 1200544.9 | G11: =IFERROR(E11-F11,"N/A") -> -79529.093 | H11: =IFERROR((E11/F11-1),"N/A") -> -0.066244161 | J11: ='Dispatch Monthly Func P&L'!X10 -> 13197252 | K11: ='Dispatch Monthly Func P&L'!AV10 -> 13340038 | L11: =IFERROR(J11-K11,"N/A") -> -142785.7 | M11: =IFERROR((J11/K11-1),"N/A") -> -0.010703545 | O11: =E11 -> 1121015.8 | P11: ='Dispatch Monthly Func P&L'!$BM10 -> 1070609 | Q11: =O11-P11 -> 50406.84 | R11: =IFERROR((O11/P11-1),"N/A") -> 0.047082398 | U11: =SUM(E8:E10)-E11 -> 0 | V11: =SUM(F8:F10)-F11 -> 0 | X11: =SUM(J8:J10)-J11 -> 0 | Y11: =SUM(K8:K10)-K11 -> 0 | AA11: =SUM(O8:O10)-O11 -> 0 | AB11: =SUM(P8:P10)-P11 -> 0
C12: Non-Recurring Revenue
C13: Non-Recurring Professional Services Revenue | E13: ='Dispatch Monthly Func P&L'!Q12 -> 26500 | F13: =INDEX('Dispatch Monthly Func P&L'!$AI12:$AT12,MATCH(EOMONTH(Inputs!$C$2,0),'Dispatch Monthly Func P&L'!$AI$5:$AT$5,0)) -> 28666.667 | G13: =IFERROR(E13-F13,"N/A") -> -2166.6667 | H13: =IFERROR((E13/F13-1),"N/A") -> -0.075581395 | J13: ='Dispatch Monthly Func P&L'!X12 -> 480250 | K13: ='Dispatch Monthly Func P&L'!AV12 -> 250041.67 | L13: =IFERROR(J13-K13,"N/A") -> 230208.33 | M13: =IFERROR((J13/K13-1),"N/A") -> 0.92067989 | O13: =E13 -> 26500 | P13: ='Dispatch Monthly Func P&L'!$BM12 -> 31999 | Q13: =O13-P13 -> -5499 | R13: =IFERROR((O13/P13-1),"N/A") -> -0.17184912
C14: Other Non-Recurring Revenue | E14: ='Dispatch Monthly Func P&L'!Q13 -> 0 | F14: =INDEX('Dispatch Monthly Func P&L'!$AI13:$AT13,MATCH(EOMONTH(Inputs!$C$2,0),'Dispatch Monthly Func P&L'!$AI$5:$AT$5,0)) -> 0 | G14: =IFERROR(E14-F14,"N/A") -> 0 | H14: =IFERROR((E14/F14-1),"N/A") -> N/A | J14: ='Dispatch Monthly Func P&L'!X13 -> 0 | K14: ='Dispatch Monthly Func P&L'!AV13 -> 0 | L14: =IFERROR(J14-K14,"N/A") -> 0 | M14: =IFERROR((J14/K14-1),"N/A") -> N/A | O14: =E14 -> 0 | P14: ='Dispatch Monthly Func P&L'!$BM13 -> 0 | Q14: =O14-P14 -> 0 | R14: =IFERROR((O14/P14-1),"N/A") -> N/A
C15: Total Non-Recurring Revenue | E15: ='Dispatch Monthly Func P&L'!Q14 -> 26500 | F15: =INDEX('Dispatch Monthly Func P&L'!$AI14:$AT14,MATCH(EOMONTH(Inputs!$C$2,0),'Dispatch Monthly Func P&L'!$AI$5:$AT$5,0)) -> 28666.667 | G15: =IFERROR(E15-F15,"N/A") -> -2166.6667 | H15: =IFERROR((E15/F15-1),"N/A") -> -0.075581395 | J15: ='Dispatch Monthly Func P&L'!X14 -> 480250 | K15: ='Dispatch Monthly Func P&L'!AV14 -> 250041.67 | L15: =IFERROR(J15-K15,"N/A") -> 230208.33 | M15: =IFERROR((J15/K15-1),"N/A") -> 0.92067989 | O15: =E15 -> 26500 | P15: ='Dispatch Monthly Func P&L'!$BM14 -> 31999 | Q15: =O15-P15 -> -5499 | R15: =IFERROR((O15/P15-1),"N/A") -> -0.17184912 | U15: =SUM(E13:E14)-E15 -> 0 | V15: =SUM(F13:F14)-F15 -> 0 | X15: =SUM(J13:J14)-J15 -> 0 | Y15: =SUM(K13:K14)-K15 -> 0 | AA15: =SUM(O13:O14)-O15 -> 0 | AB15: =SUM(P13:P14)-P15 -> 0
C16: Total Revenue | E16: ='Dispatch Monthly Func P&L'!Q15 -> 1147515.8 | F16: =INDEX('Dispatch Monthly Func P&L'!$AI15:$AT15,MATCH(EOMONTH(Inputs!$C$2,0),'Dispatch Monthly Func P&L'!$AI$5:$AT$5,0)) -> 1229211.6 | G16: =IFERROR(E16-F16,"N/A") -> -81695.759 | H16: =IFERROR((E16/F16-1),"N/A") -> -0.066461917 | J16: ='Dispatch Monthly Func P&L'!X15 -> 13677502 | K16: ='Dispatch Monthly Func P&L'!AV15 -> 13590080 | L16: =IFERROR(J16-K16,"N/A") -> 87422.634 | M16: =IFERROR((J16/K16-1),"N/A") -> 0.0064328272 | O16: =E16 -> 1147515.8 | P16: ='Dispatch Monthly Func P&L'!$BM15 -> 1102608 | Q16: =O16-P16 -> 44907.84 | R16: =IFERROR((O16/P16-1),"N/A") -> 0.040728745 | U16: =E11+E15-E16 -> 0 | V16: =F11+F15-F16 -> 0 | X16: =J11+J15-J16 -> 0 | Y16: =K11+K15-K16 -> 0 | AA16: =O11+O15-O16 -> 0 | AB16: =P11+P15-P16 -> 0
C17: % Reccurring Revenue | E17: ='Dispatch Monthly Func P&L'!Q16 -> 0.97690664 | F17: =INDEX('Dispatch Monthly Func P&L'!$AI16:$AT16,MATCH(EOMONTH(Inputs!$C$2,0),'Dispatch Monthly Func P&L'!$AI$5:$AT$5,0)) -> 0.97667882 | G17: =IFERROR(E17-F17,"N/A") -> 0.00022781825 | J17: ='Dispatch Monthly Func P&L'!X16 -> 0.96488759 | K17: ='Dispatch Monthly Func P&L'!AV16 -> 0.98160116 | L17: =IFERROR(J17-K17,"N/A") -> -0.016713568 | O17: =E17 -> 0.97690664 | P17: ='Dispatch Monthly Func P&L'!$BM16 -> 0.97097881 | Q17: =O17-P17 -> 0.0059278302 | U17: =E11/E16-E17 -> 0 | V17: =F11/F16-F17 -> 0 | X17: =J11/J16-J17 -> 0 | Y17: =K11/K16-K17 -> 0 | AA17: =O11/O16-O17 -> 0 | AB17: =P11/P16-P17 -> 0
C19: Recurring Cost of Sales - Functional
C20: Cost of Sales (Functional) - Direct Compensation (R) | E20: ='Dispatch Monthly Func P&L'!Q19 -> 71518.56 | F20: =INDEX('Dispatch Monthly Func P&L'!$AI19:$AT19,MATCH(EOMONTH(Inputs!$C$2,0),'Dispatch Monthly Func P&L'!$AI$5:$AT$5,0)) -> 60391.046 | G20: =IFERROR(E20-F20,"N/A") -> 11127.514 | H20: =IFERROR((E20/F20-1),"N/A") -> 0.18425769 | J20: ='Dispatch Monthly Func P&L'!X19 -> 818939.73 | K20: ='Dispatch Monthly Func P&L'!AV19 -> 749729.86 | L20: =IFERROR(J20-K20,"N/A") -> 69209.87 | M20: =IFERROR((J20/K20-1),"N/A") -> 0.092313077 | O20: =E20 -> 71518.56 | P20: ='Dispatch Monthly Func P&L'!$BM19 -> 71244.07 | Q20: =O20-P20 -> 274.49 | R20: =IFERROR((O20/P20-1),"N/A") -> 0.0038528119
C21: Cost of Sales (Functional) - Hosting & Infrastructure | E21: ='Dispatch Monthly Func P&L'!Q20 -> 30965.26 | F21: =INDEX('Dispatch Monthly Func P&L'!$AI20:$AT20,MATCH(EOMONTH(Inputs!$C$2,0),'Dispatch Monthly Func P&L'!$AI$5:$AT$5,0)) -> 30367 | G21: =IFERROR(E21-F21,"N/A") -> 598.26 | H21: =IFERROR((E21/F21-1),"N/A") -> 0.019700991 | J21: ='Dispatch Monthly Func P&L'!X20 -> 384144.89 | K21: ='Dispatch Monthly Func P&L'!AV20 -> 383084 | L21: =IFERROR(J21-K21,"N/A") -> 1060.89 | M21: =IFERROR((J21/K21-1),"N/A") -> 0.0027693404 | O21: =E21 -> 30965.26 | P21: ='Dispatch Monthly Func P&L'!$BM20 -> 26023.77 | Q21: =O21-P21 -> 4941.49 | R21: =IFERROR((O21/P21-1),"N/A") -> 0.18988371
C22: Cost of Sales (Functional) - Software & Subscriptions | E22: ='Dispatch Monthly Func P&L'!Q21 -> 48760.04 | F22: =INDEX('Dispatch Monthly Func P&L'!$AI21:$AT21,MATCH(EOMONTH(Inputs!$C$2,0),'Dispatch Monthly Func P&L'!$AI$5:$AT$5,0)) -> 46922.188 | G22: =IFERROR(E22-F22,"N/A") -> 1837.8525 | H22: =IFERROR((E22/F22-1),"N/A") -> 0.039168091 | J22: ='Dispatch Monthly Func P&L'!X21 -> 584922.5 | K22: ='Dispatch Monthly Func P&L'!AV21 -> 593302.25 | L22: =IFERROR(J22-K22,"N/A") -> -8379.75 | M22: =IFERROR((J22/K22-1),"N/A") -> -0.014123914 | O22: =E22 -> 48760.04 | P22: ='Dispatch Monthly Func P&L'!$BM21 -> 45472.75 | Q22: =O22-P22 -> 3287.29 | R22: =IFERROR((O22/P22-1),"N/A") -> 0.072291427
C23: Total Recurring Cost of Sales - Functional | E23: ='Dispatch Monthly Func P&L'!Q22 -> 151243.86 | F23: =INDEX('Dispatch Monthly Func P&L'!$AI22:$AT22,MATCH(EOMONTH(Inputs!$C$2,0),'Dispatch Monthly Func P&L'!$AI$5:$AT$5,0)) -> 137680.23 | G23: =IFERROR(E23-F23,"N/A") -> 13563.627 | H23: =IFERROR((E23/F23-1),"N/A") -> 0.098515427 | J23: ='Dispatch Monthly Func P&L'!X22 -> 1788007.1 | K23: ='Dispatch Monthly Func P&L'!AV22 -> 1726116.1 | L23: =IFERROR(J23-K23,"N/A") -> 61891.01 | M23: =IFERROR((J23/K23-1),"N/A") -> 0.035855647 | O23: =E23 -> 151243.86 | P23: ='Dispatch Monthly Func P&L'!$BM22 -> 142740.59 | Q23: =O23-P23 -> 8503.27 | R23: =IFERROR((O23/P23-1),"N/A") -> 0.059571493 | U23: =SUM(E20:E22)-E23 -> 0 | V23: =SUM(F20:F22)-F23 -> 0 | X23: =SUM(J20:J22)-J23 -> 0 | Y23: =SUM(K20:K22)-K23 -> 0 | AA23: =SUM(O20:O22)-O23 -> 0 | AB23: =SUM(P20:P22)-P23 -> 0
C24: Non-recurring Cost of Sales - Functional
C25: Cost of Sales (Functional) - Consultants & Contractors | E25: ='Dispatch Monthly Func P&L'!Q24 -> 0 | F25: =INDEX('Dispatch Monthly Func P&L'!$AI24:$AT24,MATCH(EOMONTH(Inputs!$C$2,0),'Dispatch Monthly Func P&L'!$AI$5:$AT$5,0)) -> 0 | G25: =IFERROR(E25-F25,"N/A") -> 0 | H25: =IFERROR((E25/F25-1),"N/A") -> N/A | J25: ='Dispatch Monthly Func P&L'!X24 -> 0 | K25: ='Dispatch Monthly Func P&L'!AV24 -> 0 | L25: =IFERROR(J25-K25,"N/A") -> 0 | M25: =IFERROR((J25/K25-1),"N/A") -> N/A | O25: =E25 -> 0 | P25: ='Dispatch Monthly Func P&L'!$BM24 -> 0 | Q25: =O25-P25 -> 0 | R25: =IFERROR((O25/P25-1),"N/A") -> N/A
C26: Cost of Sales (Functional) - Direct Compensation (NR) | E26: ='Dispatch Monthly Func P&L'!Q25 -> 59374.45 | F26: =INDEX('Dispatch Monthly Func P&L'!$AI25:$AT25,MATCH(EOMONTH(Inputs!$C$2,0),'Dispatch Monthly Func P&L'!$AI$5:$AT$5,0)) -> 56655.856 | G26: =IFERROR(E26-F26,"N/A") -> 2718.594 | H26: =IFERROR((E26/F26-1),"N/A") -> 0.047984342 | J26: ='Dispatch Monthly Func P&L'!X25 -> 694660.55 | K26: ='Dispatch Monthly Func P&L'!AV25 -> 673118.5 | L26: =IFERROR(J26-K26,"N/A") -> 21542.046 | M26: =IFERROR((J26/K26-1),"N/A") -> 0.032003349 | O26: =E26 -> 59374.45 | P26: ='Dispatch Monthly Func P&L'!$BM25 -> 48071.8 | Q26: =O26-P26 -> 11302.65 | R26: =IFERROR((O26/P26-1),"N/A") -> 0.23512017
C27: Total Non-recurring Cost of Sales - Functional | E27: ='Dispatch Monthly Func P&L'!Q26 -> 59374.45 | F27: =INDEX('Dispatch Monthly Func P&L'!$AI26:$AT26,MATCH(EOMONTH(Inputs!$C$2,0),'Dispatch Monthly Func P&L'!$AI$5:$AT$5,0)) -> 56655.856 | G27: =IFERROR(E27-F27,"N/A") -> 2718.594 | H27: =IFERROR((E27/F27-1),"N/A") -> 0.047984342 | J27: ='Dispatch Monthly Func P&L'!X26 -> 694660.55 | K27: ='Dispatch Monthly Func P&L'!AV26 -> 673118.5 | L27: =IFERROR(J27-K27,"N/A") -> 21542.046 | M27: =IFERROR((J27/K27-1),"N/A") -> 0.032003349 | O27: =E27 -> 59374.45 | P27: ='Dispatch Monthly Func P&L'!$BM26 -> 48071.8 | Q27: =O27-P27 -> 11302.65 | R27: =IFERROR((O27/P27-1),"N/A") -> 0.23512017 | U27: =E27-E26 -> 0 | V27: =F27-F26 -> 0 | X27: =J27-J26 -> 0 | Y27: =K27-K26 -> 0 | AA27: =O27-O26 -> 0 | AB27: =P27-P26 -> 0
C28: Total Cost of Sales - Functional | E28: ='Dispatch Monthly Func P&L'!Q27 -> 210618.31 | F28: =INDEX('Dispatch Monthly Func P&L'!$AI27:$AT27,MATCH(EOMONTH(Inputs!$C$2,0),'Dispatch Monthly Func P&L'!$AI$5:$AT$5,0)) -> 194336.09 | G28: =IFERROR(E28-F28,"N/A") -> 16282.221 | H28: =IFERROR((E28/F28-1),"N/A") -> 0.083783825 | J28: ='Dispatch Monthly Func P&L'!X27 -> 2482667.7 | K28: ='Dispatch Monthly Func P&L'!AV27 -> 2399234.6 | L28: =IFERROR(J28-K28,"N/A") -> 83433.057 | M28: =IFERROR((J28/K28-1),"N/A") -> 0.034774864 | O28: =E28 -> 210618.31 | P28: ='Dispatch Monthly Func P&L'!$BM27 -> 190812.39 | Q28: =O28-P28 -> 19805.92 | R28: =IFERROR((O28/P28-1),"N/A") -> 0.10379787 | U28: =E28-E27-E23 -> 0 | V28: =F28-F27-F23 -> 0 | X28: =J28-J27-J23 -> 0 | Y28: =K28-K27-K23 -> 0 | AA28: =O28-O27-O23 -> 0 | AB28: =P28-P27-P23 -> 0
C29: Gross Profit - Functional
C30: Recurring Gross Profit - Functional | E30: ='Dispatch Monthly Func P&L'!Q29 -> 969771.99 | F30: =INDEX('Dispatch Monthly Func P&L'!$AI29:$AT29,MATCH(EOMONTH(Inputs!$C$2,0),'Dispatch Monthly Func P&L'!$AI$5:$AT$5,0)) -> 1062864.7 | G30: =IFERROR(E30-F30,"N/A") -> -93092.72 | H30: =IFERROR((E30/F30-1),"N/A") -> -0.087586613 | J30: ='Dispatch Monthly Func P&L'!X29 -> 11409245 | K30: ='Dispatch Monthly Func P&L'!AV29 -> 11613922 | L30: =IFERROR(J30-K30,"N/A") -> -204676.71 | M30: =IFERROR((J30/K30-1),"N/A") -> -0.017623393 | O30: =E30 -> 969771.99 | P30: ='Dispatch Monthly Func P&L'!$BM29 -> 927868.42 | Q30: =O30-P30 -> 41903.57 | R30: =IFERROR((O30/P30-1),"N/A") -> 0.045161112
C31: Non-recurring Gross Profit - Functional | E31: ='Dispatch Monthly Func P&L'!Q30 -> -32874.45 | F31: =INDEX('Dispatch Monthly Func P&L'!$AI30:$AT30,MATCH(EOMONTH(Inputs!$C$2,0),'Dispatch Monthly Func P&L'!$AI$5:$AT$5,0)) -> -27989.189 | G31: =IFERROR(E31-F31,"N/A") -> -4885.2606 | H31: =IFERROR((E31/F31-1),"N/A") -> 0.17454098 | J31: ='Dispatch Monthly Func P&L'!X30 -> -214410.55 | K31: ='Dispatch Monthly Func P&L'!AV30 -> -423076.84 | L31: =IFERROR(J31-K31,"N/A") -> 208666.29 | M31: =IFERROR((J31/K31-1),"N/A") -> -0.49321132 | O31: =E31 -> -32874.45 | P31: ='Dispatch Monthly Func P&L'!$BM30 -> -16072.8 | Q31: =O31-P31 -> -16801.65 | R31: =IFERROR((O31/P31-1),"N/A") -> 1.0453468
C32: Total Gross Profit - Functional | E32: ='Dispatch Monthly Func P&L'!Q31 -> 936897.54 | F32: =INDEX('Dispatch Monthly Func P&L'!$AI31:$AT31,MATCH(EOMONTH(Inputs!$C$2,0),'Dispatch Monthly Func P&L'!$AI$5:$AT$5,0)) -> 1034875.5 | G32: =IFERROR(E32-F32,"N/A") -> -97977.98 | H32: =IFERROR((E32/F32-1),"N/A") -> -0.094676102 | J32: ='Dispatch Monthly Func P&L'!X31 -> 11194835 | K32: ='Dispatch Monthly Func P&L'!AV31 -> 11190845 | L32: =IFERROR(J32-K32,"N/A") -> 3989.5771 | M32: =IFERROR((J32/K32-1),"N/A") -> 0.00035650365 | O32: =E32 -> 936897.54 | P32: ='Dispatch Monthly Func P&L'!$BM31 -> 911795.62 | Q32: =O32-P32 -> 25101.92 | R32: =IFERROR((O32/P32-1),"N/A") -> 0.027530205 | U32: =E16-E28-E32 -> 0 | V32: =F16-F28-F32 -> 0 | X32: =J16-J28-J32 -> 0 | Y32: =K16-K28-K32 -> 0 | AA32: =O16-O28-O32 -> 0 | AB32: =P16-P28-P32 -> 0
C33: Recurring Gross Profit Margin % - Functional | E33: ='Dispatch Monthly Func P&L'!Q32 -> 0.86508321 | F33: =INDEX('Dispatch Monthly Func P&L'!$AI32:$AT32,MATCH(EOMONTH(Inputs!$C$2,0),'Dispatch Monthly Func P&L'!$AI$5:$AT$5,0)) -> 0.88531855 | G33: =IFERROR(E33-F33,"N/A") -> -0.020235341 | J33: ='Dispatch Monthly Func P&L'!X32 -> 0.86451671 | K33: ='Dispatch Monthly Func P&L'!AV32 -> 0.87060636 | L33: =IFERROR(J33-K33,"N/A") -> -0.0060896443 | O33: =E33 -> 0.86508321 | P33: ='Dispatch Monthly Func P&L'!$BM32 -> 0.86667346 | Q33: =O33-P33 -> -0.0015902546
C34: Non-recurring Gross Profit Margin % - Functional | E34: ='Dispatch Monthly Func P&L'!Q33 -> -1.2405453 | F34: =INDEX('Dispatch Monthly Func P&L'!$AI33:$AT33,MATCH(EOMONTH(Inputs!$C$2,0),'Dispatch Monthly Func P&L'!$AI$5:$AT$5,0)) -> -0.97636707 | G34: =IFERROR(E34-F34,"N/A") -> -0.26417821 | J34: ='Dispatch Monthly Func P&L'!X33 -> -0.44645612 | K34: ='Dispatch Monthly Func P&L'!AV33 -> -1.6920253 | L34: =IFERROR(J34-K34,"N/A") -> 1.2455692 | O34: =E34 -> -1.2405453 | P34: ='Dispatch Monthly Func P&L'!$BM33 -> -0.5022907 | Q34: =O34-P34 -> -0.73825459
C35: Total Gross Profit Margin % - Functional | E35: ='Dispatch Monthly Func P&L'!Q34 -> 0.81645717 | F35: =INDEX('Dispatch Monthly Func P&L'!$AI34:$AT34,MATCH(EOMONTH(Inputs!$C$2,0),'Dispatch Monthly Func P&L'!$AI$5:$AT$5,0)) -> 0.84190184 | G35: =IFERROR(E35-F35,"N/A") -> -0.025444677 | J35: ='Dispatch Monthly Func P&L'!X34 -> 0.8184853 | K35: ='Dispatch Monthly Func P&L'!AV34 -> 0.82345691 | L35: =IFERROR(J35-K35,"N/A") -> -0.0049716091 | O35: =E35 -> 0.81645717 | P35: ='Dispatch Monthly Func P&L'!$BM34 -> 0.82694449 | Q35: =O35-P35 -> -0.010487324 | U35: =E32/E16-E35 -> 0 | V35: =F32/F16-F35 -> 0 | X35: =J32/J16-J35 -> 0 | Y35: =K32/K16-K35 -> 0 | AA35: =O32/O16-O35 -> 0 | AB35: =P32/P16-P35 -> 0
C37: Functional Operating Expenses
C38: Product & Engineering Expense - Functional | E38: ='Dispatch Monthly Func P&L'!Q37 -> 295887.01 | F38: =INDEX('Dispatch Monthly Func P&L'!$AI37:$AT37,MATCH(EOMONTH(Inputs!$C$2,0),'Dispatch Monthly Func P&L'!$AI$5:$AT$5,0)) -> 373734.97 | G38: =IFERROR(E38-F38,"N/A") -> -77847.964 | H38: =IFERROR((E38/F38-1),"N/A") -> -0.20829724 | J38: ='Dispatch Monthly Func P&L'!X37 -> 4142020.4 | K38: ='Dispatch Monthly Func P&L'!AV37 -> 4680914.8 | L38: =IFERROR(J38-K38,"N/A") -> -538894.45 | M38: =IFERROR((J38/K38-1),"N/A") -> -0.11512588 | O38: =E38 -> 295887.01 | P38: ='Dispatch Monthly Func P&L'!$BM37 -> 389441.73 | Q38: =O38-P38 -> -93554.72 | R38: =IFERROR((O38/P38-1),"N/A") -> -0.24022777
C39: General & Administrative Expense - Functional | E39: ='Dispatch Monthly Func P&L'!Q38 -> 183958.68 | F39: =INDEX('Dispatch Monthly Func P&L'!$AI38:$AT38,MATCH(EOMONTH(Inputs!$C$2,0),'Dispatch Monthly Func P&L'!$AI$5:$AT$5,0)) -> 274754.18 | G39: =IFERROR(E39-F39,"N/A") -> -90795.498 | H39: =IFERROR((E39/F39-1),"N/A") -> -0.33046084 | J39: ='Dispatch Monthly Func P&L'!X38 -> 3235849.6 | K39: ='Dispatch Monthly Func P&L'!AV38 -> 3437916.3 | L39: =IFERROR(J39-K39,"N/A") -> -202066.69 | M39: =IFERROR((J39/K39-1),"N/A") -> -0.058775919 | O39: =E39 -> 183958.68 | P39: ='Dispatch Monthly Func P&L'!$BM38 -> 242492.84 | Q39: =O39-P39 -> -58534.16 | R39: =IFERROR((O39/P39-1),"N/A") -> -0.24138511
